Workbook
Name URK_2020_1989: USSR!$E$94

Sheet NOTES
A1: Ретропрогноз динамики демографического перехода для населения территории РСФСР-1991 (без Тувы),
A2: и территорий Новороссии, Малороссии, Белоруссии и СССР
A4: Страницы RSFSR, NR, MR, BR проводят исчисление для территорий РСФСР-1991 (без Тувы), Новороссии, Малороссии и Белоруссии.
B6: Листы NR, MR и BR структурно повторяют расчёт для территории РСФСР-1991.
B7: Их отличие состоит только в величине исходного населения на январь 1917 года,
B8: в базовых значениях рождаемости и смертности,
B9: а также в положении той точки модельных кривых RB/RD, которая принимается за опорную для соответствующей территории.
B10: Тем самым сохраняется единый принцип расчёта,
B11: а территориальные различия учитываются не через изменение самой модели,
B12: а через изменение её начальных условий и фазового сдвига по траектории демографического перехода.
A14: Страница USSR сводит их итоги в исчисление для территории СССР в текущих границах на даты переписей населения.
B16: Главная таблица на странице USSR представляет собой сводный расчёт ожидаемой численности населения территории СССР по датам переписей и для нескольких последующих контрольных дат.
B17: В отличие от погодовых таблиц для РСФСР-1991, Новороссии, Малороссии и Белоруссии, она не производит самостоятельного год за годом исчисления
B18: демографической динамики, а сводит в единую систему уже полученные для этих четырёх территорий ретропрогнозные величины. Для каждой даты переписи в
B19: таблицу вносятся ожидаемые величины населения РСФСР-1991, Новороссии, Малороссии и Белоруссии, полученные по отдельным расчётам, после чего к ним
B20: добавляется фактическая численность тех частей СССР, для которых контрфактическое моделирование в настоящей работе не производится. Тем самым образуется
B21: составная ожидаемая численность населения СССР, но лишь после специальной территориальной корректировки: для переписей 1926-1939 гг. из суммы вычитается
B22: население тех частей Новороссии, Малороссии и Белоруссии, которые на соответствующий момент ещё не входили в состав СССР. Эта операция приводит
B23: расчётные таксоны к реальным границам СССР на дату данной переписи и делает итоговое сопоставление территориально корректным.
B25: Иными словами, ожидаемая численность населения СССР в таблице определяется как сумма контрфактических величин для четырёх моделируемых восточнославянских
B26: территорий и фактической численности прочих республик и областей, входивших в состав СССР на соответствующую дату, за вычетом тех частей моделируемых
B27: территорий, которые тогда ещё находились вне его государственных границ. Для переписей 1959-1989 гг. к этой сумме уже добавляется фактическое население
B28: бывших подавстрийских земель, включённых в СССР в 1939-1945 гг., а также Тувы. Полученная итоговая величина сопоставляется с фактической численностью
... B37: сопоставить её с фактической переписной численностью, исчислив абсолютные и относительные размеры демографического дефицита.
A39: Страница USSR-Simplifed даёт сокращённый вариант итогов со страницы USSR.
B41: Страница USSR-Simplified даёт компактное представление тех же итогов, что и страница USSR, но без промежуточных сводных колонок. Она служит сокращённой
B42: таблицей результатов, в которой для каждой даты непосредственно сопоставляются ожидаемая и фактическая численность населения СССР в соответствующих
B43: границах, а также исчисленные на этой основе абсолютные и относительные размеры демографического дефицита.
A45: Фактическая рождаемость и смертность в РСФСР (источники):
B46: 1927-1958 (кроме 1941-1945) по АДХ
B47: 1941-1945 по нашему расчёту в РТСС = RTSS/ww2-losses/cdbr-194x.html
B48: 1959-2023 по Росстату
A51: !!! Белоруссия без Смоленской
A54: !!! Также Вайнштейн стр. 455

Sheet RSFSR
A1: Ретропрогноз динамики демографического перехода для населения территории РСФСР-1991 (без Тувы)
B3: относительная рождаемость и смертность | D3: ожидаемые
D4: промилле | F4: тыс. чел. | M4: на начало года | Q4: фактическая рождаемость и смертность | S4: фактическая vs ожидаемая
A5: год | B5: RB | C5: RD | D5: рождаемость | E5: смертность | F5: население в начале года | G5: число рождений | H5: число смертей | I5: военная поправка | J5: темп прироста, % | L5: примечание | M5: фактическое население РСФСР (1927-1959 по АДХ, далее по Росстату), с 1946 года с Тувой | N5: % потерь | O5: величина потерь | Q5: р | R5: с | S5: р | T5: с
A6: 1910-1914 | D6: 49.5 | E6: 32.1 | F6: 89243 | L6: население на начало 1914 года
A7: 1917 | B7: 0.51 | C7: 1 | D7: =B7*$D$6 -> 25.245 | E7: =C7*$E$6 -> 32.1 | F7: 91000 | G7: =F7*D7/1000 -> 2297.295 | H7: =E7*F7/1000 -> 2921.1 | I7: -54 | J7: =100 *(F8-F7) / F7 -> -0.74484066
A8: =A7+1 -> 1918 | B8: 0.6 | C8: 1 | D8: =B8*$D$6 -> 29.7 | E8: =C8*$E$6 -> 32.1 | F8: =F7+G7-H7+I7 -> 90322.195 | G8: =F8*D8/1000 -> 2682.5692 | H8: =E8*F8/1000 -> 2899.3425 | I8: -145 | J8: =100 *(F9-F8) / F8 -> -0.4005364
A9: =A8+1 -> 1919 | B9: 1 | C9: 1 | D9: =B9*$D$6 -> 49.5 | E9: =C9*$E$6 -> 32.1 | F9: =F8+G8-H8+I8 -> 89960.422 | G9: =F9*D9/1000 -> 4453.0409 | H9: =E9*F9/1000 -> 2887.7295 | I9: 1450 | J9: =100 *(F10-F9) / F9 -> 3.3518199
A10: =A9+1 -> 1920 | B10: 1 | C10: 1 | D10: =B10*$D$6 -> 49.5 | E10: =C10*$E$6 -> 32.1 | F10: =F9+G9-H9+I9 -> 92975.733 | G10: =F10*D10/1000 -> 4602.2988 | H10: =E10*F10/1000 -> 2984.521 | I10: 870 | J10: =100 *(F11-F10) / F10 -> 2.675728
A11: =A10+1 -> 1921 | B11: 1 | C11: 1 | D11: =B11*$D$6 -> 49.5 | E11: =C11*$E$6 -> 32.1 | F11: =F10+G10-H10+I10 -> 95463.511 | G11: =F11*D11/1000 -> 4725.4438 | H11: =E11*F11/1000 -> 3064.3787 | I11: 580 | J11: =100 *(F12-F11) / F11 -> 2.347562
A12: =A11+1 -> 1922 | B12: 0.999 | C12: 0.992 | D12: =B12*$D$6 -> 49.4505 | E12: =C12*$E$6 -> 31.8432 | F12: =F11+G11-H11+I11 -> 97704.576 | G12: =F12*D12/1000 -> 4831.5401 | H12: =E12*F12/1000 -> 3111.2264 | J12: =100 *(F13-F12) / F12 -> 1.76073
A13: =A12+1 -> 1923 | B13: 0.997 | C13: 0.981 | D13: =B13*$D$6 -> 49.3515 | E13: =C13*$E$6 -> 31.4901 | F13: =F12+G12-H12+I12 -> 99424.89 | G13: =F13*D13/1000 -> 4906.7674 | H13: =E13*F13/1000 -> 3130.8997 | J13: =100 *(F14-F13) / F13 -> 1.78614
A14: =A13+1 -> 1924 | B14: 0.995 | C14: 0.967 | D14: =B14*$D$6 -> 49.2525 | E14: =C14*$E$6 -> 31.0407 | F14: =F13+G13-H13+I13 -> 101200.76 | G14: =F14*D14/1000 -> 4984.3903 | H14: =E14*F14/1000 -> 3141.3424 | J14: =100 *(F15-F14) / F14 -> 1.82118
A15: =A14+1 -> 1925 | B15: 0.992 | C15: 0.953 | D15: =B15*$D$6 -> 49.104 | E15: =C15*$E$6 -> 30.5913 | F15: =F14+G14-H14+I14 -> 103043.81 | G15: =F15*D15/1000 -> 5059.863 | H15: =E15*F15/1000 -> 3152.244 | J15: =100 *(F16-F15) / F15 -> 1.85127
A16: =A15+1 -> 1926 | B16: 0.99 | C16: 0.94 | D16: =B16*$D$6 -> 49.005 | E16: =C16*$E$6 -> 30.174 | F16: =F15+G15-H15+I15 -> 104951.42 | G16: =F16*D16/1000 -> 5143.1446 | H16: =E16*F16/1000 -> 3166.8043 | J16: =100 *(F17-F16) / F16 -> 1.8831
A17: =A16+1 -> 1927 | B17: 0.987 | C17: 0.927 | D17: =B17*$D$6 -> 48.8565 | E17: =C17*$E$6 -> 29.7567 | F17: =F16+G16-H16+I16 -> 106927.76 | G17: =F17*D17/1000 -> 5224.1163 | H17: =E17*F17/1000 -> 3181.8174 | J17: =100 *(F18-F17) / F17 -> 1.90998 | M17: 93604 | N17: =100*O17/F17 -> 12.460529 | O17: =F17-M17 -> 13323.765 | Q17: 49.6 | R17: 28.6 | S17: =Q17/D17 -> 1.015218 | T17: =R17/E17 -> 0.96112808
A18: =A17+1 -> 1928 | B18: 0.985 | C18: 0.914 | D18: =B18*$D$6 -> 48.7575 | E18: =C18*$E$6 -> 29.3394 | F18: =F17+G17-H17+I17 -> 108970.06 | G18: =F18*D18/1000 -> 5313.1079 | H18: =E18*F18/1000 -> 3197.1163 | J18: =100 *(F19-F18) / F18 -> 1.94181 | M18: 95587 | N18: =100*O18/F18 -> 12.281413 | O18: =F18-M18 -> 13383.064 | Q18: 48.9 | R18: 26.8 | S18: =Q18/D18 -> 1.0029226 | T18: =R18/E18 -> 0.91344745
A19: =A18+1 -> 1929 | B19: 0.982 | C19: 0.901 | D19: =B19*$D$6 -> 48.609 | E19: =C19*$E$6 -> 28.9221 | F19: =F18+G18-H18+I18 -> 111086.06 | G19: =F19*D19/1000 -> 5399.7821 | H19: =E19*F19/1000 -> 3212.842 | J19: =100 *(F20-F19) / F19 -> 1.96869 | M19: 97721 | N19: =100*O19/F19 -> 12.031263 | O19: =F19-M19 -> 13365.055 | Q19: 47 | R19: 28.6 | S19: =Q19/D19 -> 0.96689913 | T19: =R19/E19 -> 0.98886319
A20: =A19+1 -> 1930 | B20: 0.98 | C20: 0.887 | D20: =B20*$D$6 -> 48.51 | E20: =C20*$E$6 -> 28.4727 | F20: =F19+G19-H19+I19 -> 113273 | G20: =F20*D20/1000 -> 5494.873 | H20: =E20*F20/1000 -> 3225.188 | J20: =100 *(F21-F20) / F20 -> 2.00373 | M20: 99566 | N20: =100*O20/F20 -> 12.10085 | O20: =F20-M20 -> 13706.995 | Q20: 43.9 | R20: 27.3 | S20: =Q20/D20 -> 0.90496805 | T20: =R20/E20 -> 0.95881318
A21: =A20+1 -> 1931 | B21: 0.98 | C21: 0.874 | D21: =B21*$D$6 -> 48.51 | E21: =C21*$E$6 -> 28.0554 | F21: =F20+G20-H20+I20 -> 115542.68 | G21: =F21*D21/1000 -> 5604.9754 | H21: =E21*F21/1000 -> 3241.5961 | J21: =100 *(F22-F21) / F21 -> 2.04546 | M21: 101272 | N21: =100*O21/F21 -> 12.351003 | O21: =F21-M21 -> 14270.68 | Q21: 43.3 | R21: 30.3 | S21: =Q21/D21 -> 0.89259946 | T21: =R21/E21 -> 1.080006
A22: =A21+1 -> 1932 | B22: 0.978 | C22: 0.863 | D22: =B22*$D$6 -> 48.411 | E22: =C22*$E$6 -> 27.7023 | F22: =F21+G21-H21+I21 -> 117906.06 | G22: =F22*D22/1000 -> 5707.9502 | H22: =E22*F22/1000 -> 3266.269 | J22: =100 *(F23-F22) / F22 -> 2.07087 | M22: 102625 | N22: =100*O22/F22 -> 12.960368 | O22: =F22-M22 -> 15281.06 | Q22: 39.3 | R22: 29.8 | S22: =Q22/D22 -> 0.81179897 | T22: =R22/E22 -> 1.075723
A23: =A22+1 -> 1933 | B23: 0.975 | C23: 0.859 | D23: =B23*$D$6 -> 48.2625 | E23: =C23*$E$6 -> 27.5739 | F23: =F22+G22-H22+I22 -> 120347.74 | G23: =F23*D23/1000 -> 5808.2828 | H23: =E23*F23/1000 -> 3318.4566 | J23: =100 *(F24-F23) / F23 -> 2.06886 | M23: 103648 | N23: =100*O23/F23 -> 13.87624 | O23: =F23-M23 -> 16699.741 | Q23: 32.3 | R23: 51 | S23: =Q23/D23 -> 0.66925667 | T23: =R23/E23 -> 1.8495751
A24: =A23+1 -> 1934 | B24: 0.972 | C24: 0.851 | D24: =B24*$D$6 -> 48.114 | E24: =C24*$E$6 -> 27.3171 | F24: =F23+G23-H23+I23 -> 122837.57 | G24: =F24*D24/1000 -> 5910.2067 | H24: =E24*F24/1000 -> 3355.5661 | J24: =100 *(F25-F24) / F24 -> 2.07969 | M24: 101763 | N24: =100*O24/F24 -> 17.156451 | O24: =F24-M24 -> 21074.567 | Q24: 28.7 | R24: 26.1 | S24: =Q24/D24 -> 0.59649998 | T24: =R24/E24 -> 0.95544549
A25: =A24+1 -> 1935 | B25: 0.968 | C25: 0.841 | D25: =B25*$D$6 -> 47.916 | E25: =C25*$E$6 -> 26.9961 | F25: =F24+G24-H24+I24 -> 125392.21 | G25: =F25*D25/1000 -> 6008.293 | H25: =E25*F25/1000 -> 3385.1006 | J25: =100 *(F26-F25) / F25 -> 2.09199 | M25: 102080 | N25: =100*O25/F25 -> 18.591433 | O25: =F25-M25 -> 23312.208 | Q25: 34.8 | R25: 23.6 | S25: =Q25/D25 -> 0.72627097 | T25: =R25/E25 -> 0.87420035
A26: =A25+1 -> 1936 | B26: 0.956 | C26: 0.829 | D26: =B26*$D$6 -> 47.322 | E26: =C26*$E$6 -> 26.6109 | F26: =F25+G25-H25+I25 -> 128015.4 | G26: =F26*D26/1000 -> 6057.9448 | H26: =E26*F26/1000 -> 3406.605 | J26: =100 *(F27-F26) / F26 -> 2.07111 | M26: 103288 | N26: =100*O26/F26 -> 19.315957 | O26: =F26-M26 -> 24727.4 | Q26: 37.5 | R26: 26.2 | S26: =Q26/D26 -> 0.79244326 | T26: =R26/E26 -> 0.98455896
A27: =A26+1 -> 1937 | B27: 0.961 | C27: 0.818 | D27: =B27*$D$6 -> 47.5695 | E27: =C27*$E$6 -> 26.2578 | F27: =F26+G26-H26+I26 -> 130666.74 | G27: =F27*D27/1000 -> 6215.7515 | H27: =E27*F27/1000 -> 3431.0211 | J27: =100 *(F28-F27) / F27 -> 2.13117 | M27: 104520 | N27: =100*O27/F27 -> 20.010249 | O27: =F27-M27 -> 26146.74 | Q27: 41.5 | R27: 26.2 | S27: =Q27/D27 -> 0.87240774 | T27: =R27/E27 -> 0.99779875
A28: =A27+1 -> 1938 | B28: 0.966 | C28: 0.806 | D28: =B28*$D$6 -> 47.817 | E28: =C28*$E$6 -> 25.8726 | F28: =F27+G27-H27+I27 -> 133451.47 | G28: =F28*D28/1000 -> 6381.249 | H28: =E28*F28/1000 -> 3452.7365 | J28: =100 *(F29-F28) / F28 -> 2.19444 | M28: 106195 | N28: =100*O28/F28 -> 20.424256 | O28: =F28-M28 -> 27256.47 | Q28: 40.9 | R28: 25.6 | S28: =Q28/D28 -> 0.85534433 | T28: =R28/E28 -> 0.98946376
... A31: =A30+1 -> 1941 | B31: 0.965 | C31: 0.796 | D31: =B31*$D$6 -> 47.7675 | E31: =C31*$E$6 -> 25.5516 | F31: =F30+G30-H30+I30 -> 142530.03 | G31: =F31*D31/1000 -> 6808.3032 | H31: =E31*F31/1000 -> 3641.8703 | J31: =100 *(F32-F31) / F31 -> 2.22159 | M31: 110988 | N31: =100*O31/F31 -> 22.130094 | O31: =F31-M31 -> 31542.03 | Q31: 32.8 | R31: 51.7 | S31: =Q31/D31 -> 0.68665934 | T31: =R31/E31 -> 2.0233567
A32: =A31+1 -> 1942 | B32: 0.962 | C32: 0.795 | D32: =B32*$D$6 -> 47.619 | E32: =C32*$E$6 -> 25.5195 | F32: =F31+G31-H31+I31 -> 145696.46 | G32: =F32*D32/1000 -> 6937.9198 | H32: =E32*F32/1000 -> 3718.1009 | I32: -90 | J32: =100 *(F33-F32) / F32 -> 2.1481777 | Q32: 21.3 | R32: 67.9 | S32: =Q32/D32 -> 0.44730045 | T32: =R32/E32 -> 2.6607104
A33: =A32+1 -> 1943 | B33: 0.956 | C33: 0.788 | D33: =B33*$D$6 -> 47.322 | E33: =C33*$E$6 -> 25.2948 | F33: =F32+G32-H32+I32 -> 148826.28 | G33: =F33*D33/1000 -> 7042.7573 | H33: =E33*F33/1000 -> 3764.531 | I33: -90 | J33: =100 *(F34-F33) / F33 -> 2.1422468 | Q33: 12.9 | R33: 51.5 | S33: =Q33/D33 -> 0.27260048 | T33: =R33/E33 -> 2.0359916 | V33: среднее факт/ожид за 1929-1939
A34: =A33+1 -> 1944 | B34: 0.95 | C34: 0.768 | D34: =B34*$D$6 -> 47.025 | E34: =C34*$E$6 -> 24.6528 | F34: =F33+G33-H33+I33 -> 152014.51 | G34: =F34*D34/1000 -> 7148.4822 | H34: =E34*F34/1000 -> 3747.5833 | I34: -90 | J34: =100 *(F35-F34) / F34 -> 2.1780151 | Q34: 13.7 | R34: 40.9 | S34: =Q34/D34 -> 0.2913344 | T34: =R34/E34 -> 1.6590408 | V34: 0.80354946 | W34: 1.0497126
A35: =A34+1 -> 1945 | B35: 0.941 | C35: 0.742 | D35: =B35*$D$6 -> 46.5795 | E35: =C35*$E$6 -> 23.8182 | F35: =F34+G34-H34+I34 -> 155325.41 | G35: =F35*D35/1000 -> 7234.9798 | H35: =E35*F35/1000 -> 3699.5716 | J35: =100 *(F36-F35) / F35 -> 2.27613 | Q35: 15.1 | R35: 25 | S35: =Q35/D35 -> 0.32417694 | T35: =R35/E35 -> 1.0496175
A36: =A35+1 -> 1946 | B36: 0.934 | C36: 0.727 | D36: =B36*$D$6 -> 46.233 | E36: =C36*$E$6 -> 23.3367 | F36: =F35+G35-H35+I35 -> 158860.81 | G36: =F36*D36/1000 -> 7344.6121 | H36: =E36*F36/1000 -> 3707.2872 | J36: =100 *(F37-F36) / F36 -> 2.28963 | M36: 97548 | N36: =100*O36/F36 -> 38.595304 | O36: =F36-M36 -> 61312.815 | Q36: 26 | R36: 12.3 | S36: =Q36/D36 -> 0.56236887 | T36: =R36/E36 -> 0.52706681
A37: =A36+1 -> 1947 | B37: 0.929 | C37: 0.712 | D37: =B37*$D$6 -> 45.9855 | E37: =C37*$E$6 -> 22.8552 | F37: =F36+G36-H36+I36 -> 162498.14 | G37: =F37*D37/1000 -> 7472.5582 | H37: =E37*F37/1000 -> 3713.9275 | J37: =100 *(F38-F37) / F37 -> 2.31303 | M37: 98509 | N37: =100*O37/F37 -> 39.378383 | O37: =F37-M37 -> 63989.14 | Q37: 27.5 | R37: 17 | S37: =Q37/D37 -> 0.59801459 | T37: =R37/E37 -> 0.74381322
A38: =A37+1 -> 1948 | B38: 0.921 | C38: 0.698 | D38: =B38*$D$6 -> 45.5895 | E38: =C38*$E$6 -> 22.4058 | F38: =F37+G37-H37+I37 -> 166256.77 | G38: =F38*D38/1000 -> 7579.563 | H38: =E38*F38/1000 -> 3725.1159 | J38: =100 *(F39-F38) / F38 -> 2.31837 | M38: 99159 | N38: =100*O38/F38 -> 40.357918 | O38: =F38-M38 -> 67097.77 | Q38: 25.2 | R38: 13.1 | S38: =Q38/D38 -> 0.55275886 | T38: =R38/E38 -> 0.58467004
A39: =A38+1 -> 1949 | B39: 0.933 | C39: 0.696 | D39: =B39*$D$6 -> 46.1835 | E39: =C39*$E$6 -> 22.3416 | F39: =F38+G38-H38+I38 -> 170111.22 | G39: =F39*D39/1000 -> 7856.3314 | H39: =E39*F39/1000 -> 3800.5568 | J39: =100 *(F40-F39) / F39 -> 2.38419 | M39: 100252 | N39: =100*O39/F39 -> 41.066791 | O39: =F39-M39 -> 69859.218 | Q39: 30.5 | R39: 11.7 | S39: =Q39/D39 -> 0.66040902 | T39: =R39/E39 -> 0.52368675
A40: =A39+1 -> 1950 | B40: 0.942 | C40: 0.697 | D40: =B40*$D$6 -> 46.629 | E40: =C40*$E$6 -> 22.3737 | F40: =F39+G39-H39+I39 -> 174166.99 | G40: =F40*D40/1000 -> 8121.2327 | H40: =E40*F40/1000 -> 3896.76 | J40: =100 *(F41-F40) / F40 -> 2.42553 | M40: 102067 | N40: =100*O40/F40 -> 41.397047 | O40: =F40-M40 -> 72099.992 | Q40: 27.8 | R40: 11.5 | S40: =Q40/D40 -> 0.5961955 | T40: =R40/E40 -> 0.51399634
A41: =A40+1 -> 1951 | B41: 0.948 | C41: 0.694 | D41: =B41*$D$6 -> 46.926 | E41: =C41*$E$6 -> 22.2774 | F41: =F40+G40-H40+I40 -> 178391.46 | G41: =F41*D41/1000 -> 8371.1979 | H41: =E41*F41/1000 -> 3974.098 | J41: =100 *(F42-F41) / F41 -> 2.46486 | M41: 103599 | N41: =100*O41/F41 -> 41.926033 | O41: =F41-M41 -> 74792.465 | Q41: 28.1 | R41: 11.6 | S41: =Q41/D41 -> 0.59881516 | T41: =R41/E41 -> 0.52070708
A42: =A41+1 -> 1952 | B42: 0.953 | C42: 0.688 | D42: =B42*$D$6 -> 47.1735 | E42: =C42*$E$6 -> 22.0848 | F42: =F41+G41-H41+I41 -> 182788.56 | G42: =F42*D42/1000 -> 8622.7764 | H42: =E42*F42/1000 -> 4036.8489 | J42: =100 *(F43-F42) / F42 -> 2.50887 | M42: 105278 | N42: =100*O42/F42 -> 42.404493 | O42: =F42-M42 -> 77510.565 | Q42: 27.6 | R42: 10.7 | S42: =Q42/D42 -> 0.58507425 | T42: =R42/E42 -> 0.48449612
A43: =A42+1 -> 1953 | B43: 0.957 | C43: 0.679 | D43: =B43*$D$6 -> 47.3715 | E43: =C43*$E$6 -> 21.7959 | F43: =F42+G42-H42+I42 -> 187374.49 | G43: =F43*D43/1000 -> 8876.2108 | H43: =E43*F43/1000 -> 4083.9957 | J43: =100 *(F44-F43) / F43 -> 2.55756 | M43: 107049 | N43: =100*O43/F43 -> 42.868958 | O43: =F43-M43 -> 80325.492 | Q43: 26.2 | R43: 10.4 | S43: =Q43/D43 -> 0.55307516 | T43: =R43/E43 -> 0.47715396
...

Sheet NR
A1: Ретропрогноз динамики демографического перехода для населения территории Новороссии
D4: промилле | F4: тыс. чел.
A5: год | B5: RB | C5: RD | D5: рождаемость | E5: смертность | F5: население в начале года | G5: число рождений | H5: число смертей | I5: военная поправка | J5: темп прироста, % | L5: примечание
A6: 1909-1913 | D6: 47.88 | E6: 28.52 | F6: 14754 | L6: население на начало 1914 года
A7: 1917 | B7: 0.51 | C7: 1 | D7: =B7*$D$6 -> 24.4188 | E7: =C7*$E$6 -> 28.52 | F7: =F6 * RSFSR!F7 / RSFSR!F6 -> 15044.474 | G7: =F7*D7/1000 -> 367.368 | H7: =E7*F7/1000 -> 429.0684 | I7: =NR!F6 / RSFSR!F6 * INDIRECT("'RSFSR'!" & ADDRESS(ROW(), COLUMN())) -> -8.9274901 | J7: =100 *(F8-F7) / F7 -> -0.46946066
A8: =A7+1 -> 1918 | B8: 0.6 | C8: 1 | D8: =B8*$D$6 -> 28.728 | E8: =C8*$E$6 -> 28.52 | F8: =F7+G7-H7+I7 -> 14973.846 | G8: =F8*D8/1000 -> 430.16865 | H8: =E8*F8/1000 -> 427.05409 | I8: =NR!F6 / RSFSR!F6 * INDIRECT("'RSFSR'!" & ADDRESS(ROW(), COLUMN())) -> -23.971964 | J8: =100 *(F9-F8) / F8 -> -0.13929223
A9: =A8+1 -> 1919 | B9: 1 | C9: 1 | D9: =B9*$D$6 -> 47.88 | E9: =C9*$E$6 -> 28.52 | F9: =F8+G8-H8+I8 -> 14952.989 | G9: =F9*D9/1000 -> 715.9491 | H9: =E9*F9/1000 -> 426.45924 | I9: =NR!F6 / RSFSR!F6 * INDIRECT("'RSFSR'!" & ADDRESS(ROW(), COLUMN())) -> 239.71964 | J9: =100 *(F10-F9) / F9 -> 3.5391554
A10: =A9+1 -> 1920 | B10: 1 | C10: 1 | D10: =B10*$D$6 -> 47.88 | E10: =C10*$E$6 -> 28.52 | F10: =F9+G9-H9+I9 -> 15482.198 | G10: =F10*D10/1000 -> 741.28765 | H10: =E10*F10/1000 -> 441.5523 | I10: =NR!F6 / RSFSR!F6 * INDIRECT("'RSFSR'!" & ADDRESS(ROW(), COLUMN())) -> 143.83179 | J10: =100 *(F11-F10) / F10 -> 2.865014
A11: =A10+1 -> 1921 | B11: 0.999 | C11: 0.992 | D11: =B11*$D$6 -> 47.83212 | E11: =C11*$E$6 -> 28.29184 | F11: =F10+G10-H10+I10 -> 15925.765 | G11: =F11*D11/1000 -> 761.76312 | H11: =E11*F11/1000 -> 450.56921 | I11: =NR!F6 / RSFSR!F6 * INDIRECT("'RSFSR'!" & ADDRESS(ROW(), COLUMN())) -> 95.887857 | J11: =100 *(F12-F11) / F11 -> 2.5561206
A12: =A11+1 -> 1922 | B12: 0.997 | C12: 0.981 | D12: =B12*$D$6 -> 47.73636 | E12: =C12*$E$6 -> 27.97812 | F12: =F11+G11-H11+I11 -> 16332.847 | G12: =F12*D12/1000 -> 779.67067 | H12: =E12*F12/1000 -> 456.96236 | J12: =100 *(F13-F12) / F12 -> 1.975824
A13: =A12+1 -> 1923 | B13: 0.995 | C13: 0.967 | D13: =B13*$D$6 -> 47.6406 | E13: =C13*$E$6 -> 27.57884 | F13: =F12+G12-H12+I12 -> 16655.556 | G13: =F13*D13/1000 -> 793.48066 | H13: =E13*F13/1000 -> 459.3409 | J13: =100 *(F14-F13) / F13 -> 2.006176
A14: =A13+1 -> 1924 | B14: 0.992 | C14: 0.953 | D14: =B14*$D$6 -> 47.49696 | E14: =C14*$E$6 -> 27.17956 | F14: =F13+G13-H13+I13 -> 16989.695 | G14: =F14*D14/1000 -> 806.95888 | H14: =E14*F14/1000 -> 461.77244 | J14: =100 *(F15-F14) / F14 -> 2.03174
A15: =A14+1 -> 1925 | B15: 0.99 | C15: 0.94 | D15: =B15*$D$6 -> 47.4012 | E15: =C15*$E$6 -> 26.8088 | F15: =F14+G14-H14+I14 -> 17334.882 | G15: =F15*D15/1000 -> 821.6942 | H15: =E15*F15/1000 -> 464.72738 | J15: =100 *(F16-F15) / F15 -> 2.05924
A16: =A15+1 -> 1926 | B16: 0.987 | C16: 0.927 | D16: =B16*$D$6 -> 47.25756 | E16: =C16*$E$6 -> 26.43804 | F16: =F15+G15-H15+I15 -> 17691.849 | G16: =F16*D16/1000 -> 836.07359 | H16: =E16*F16/1000 -> 467.7378 | J16: =100 *(F17-F16) / F16 -> 2.081952
A17: =A16+1 -> 1927 | B17: 0.985 | C17: 0.914 | D17: =B17*$D$6 -> 47.1618 | E17: =C17*$E$6 -> 26.06728 | F17: =F16+G16-H16+I16 -> 18060.184 | G17: =F17*D17/1000 -> 851.7508 | H17: =E17*F17/1000 -> 470.77988 | J17: =100 *(F18-F17) / F17 -> 2.109452
A18: =A17+1 -> 1928 | B18: 0.982 | C18: 0.901 | D18: =B18*$D$6 -> 47.01816 | E18: =C18*$E$6 -> 25.69652 | F18: =F17+G17-H17+I17 -> 18441.155 | G18: =F18*D18/1000 -> 867.06919 | H18: =E18*F18/1000 -> 473.87351 | J18: =100 *(F19-F18) / F18 -> 2.132164
A19: =A18+1 -> 1929 | B19: 0.98 | C19: 0.887 | D19: =B19*$D$6 -> 46.9224 | E19: =C19*$E$6 -> 25.29724 | F19: =F18+G18-H18+I18 -> 18834.351 | G19: =F19*D19/1000 -> 883.75295 | H19: =E19*F19/1000 -> 476.4571 | J19: =100 *(F20-F19) / F19 -> 2.162516
A20: =A19+1 -> 1930 | B20: 0.98 | C20: 0.874 | D20: =B20*$D$6 -> 46.9224 | E20: =C20*$E$6 -> 24.92648 | F20: =F19+G19-H19+I19 -> 19241.647 | G20: =F20*D20/1000 -> 902.86425 | H20: =E20*F20/1000 -> 479.62652 | J20: =100 *(F21-F20) / F20 -> 2.199592
A21: =A20+1 -> 1931 | B21: 0.978 | C21: 0.863 | D21: =B21*$D$6 -> 46.82664 | E21: =C21*$E$6 -> 24.61276 | F21: =F20+G20-H20+I20 -> 19664.884 | G21: =F21*D21/1000 -> 920.84047 | H21: =E21*F21/1000 -> 484.00708 | J21: =100 *(F22-F21) / F21 -> 2.221388
A22: =A21+1 -> 1932 | B22: 0.975 | C22: 0.859 | D22: =B22*$D$6 -> 46.683 | E22: =C22*$E$6 -> 24.49868 | F22: =F21+G21-H21+I21 -> 20101.718 | G22: =F22*D22/1000 -> 938.4085 | H22: =E22*F22/1000 -> 492.46555 | J22: =100 *(F23-F22) / F22 -> 2.218432
A23: =A22+1 -> 1933 | B23: 0.972 | C23: 0.851 | D23: =B23*$D$6 -> 46.53936 | E23: =C23*$E$6 -> 24.27052 | F23: =F22+G22-H22+I22 -> 20547.661 | G23: =F23*D23/1000 -> 956.27498 | H23: =E23*F23/1000 -> 498.70241 | J23: =100 *(F24-F23) / F23 -> 2.226884
... A31: =A30+1 -> 1941 | B31: 0.962 | C31: 0.795 | D31: =B31*$D$6 -> 46.06056 | E31: =C31*$E$6 -> 22.6734 | F31: =F30+G30-H30+I30 -> 24632.219 | G31: =F31*D31/1000 -> 1134.5738 | H31: =E31*F31/1000 -> 558.49615 | J31: =100 *(F32-F31) / F31 -> 2.338716
A32: =A31+1 -> 1942 | B32: 0.956 | C32: 0.788 | D32: =B32*$D$6 -> 45.77328 | E32: =C32*$E$6 -> 22.47376 | F32: =F31+G31-H31+I31 -> 25208.296 | G32: =F32*D32/1000 -> 1153.8664 | H32: =E32*F32/1000 -> 566.5252 | I32: =NR!F6 / RSFSR!F6 * INDIRECT("'RSFSR'!" & ADDRESS(ROW(), COLUMN())) -> -14.87915 | J32: =100 *(F33-F32) / F32 -> 2.2709272
A33: =A32+1 -> 1943 | B33: 0.95 | C33: 0.768 | D33: =B33*$D$6 -> 45.486 | E33: =C33*$E$6 -> 21.90336 | F33: =F32+G32-H32+I32 -> 25780.758 | G33: =F33*D33/1000 -> 1172.6636 | H33: =E33*F33/1000 -> 564.68523 | I33: =NR!F6 / RSFSR!F6 * INDIRECT("'RSFSR'!" & ADDRESS(ROW(), COLUMN())) -> -14.87915 | J33: =100 *(F34-F33) / F33 -> 2.3005498
A34: =A33+1 -> 1944 | B34: 0.941 | C34: 0.742 | D34: =B34*$D$6 -> 45.05508 | E34: =C34*$E$6 -> 21.16184 | F34: =F33+G33-H33+I33 -> 26373.858 | G34: =F34*D34/1000 -> 1188.2763 | H34: =E34*F34/1000 -> 558.11935 | I34: =NR!F6 / RSFSR!F6 * INDIRECT("'RSFSR'!" & ADDRESS(ROW(), COLUMN())) -> -14.87915 | J34: =100 *(F35-F34) / F34 -> 2.3329077
A35: =A34+1 -> 1945 | B35: 0.934 | C35: 0.727 | D35: =B35*$D$6 -> 44.71992 | E35: =C35*$E$6 -> 20.73404 | F35: =F34+G34-H34+I34 -> 26989.135 | G35: =F35*D35/1000 -> 1206.952 | H35: =E35*F35/1000 -> 559.59381 | J35: =100 *(F36-F35) / F35 -> 2.398588
A36: =A35+1 -> 1946 | B36: 0.929 | C36: 0.712 | D36: =B36*$D$6 -> 44.48052 | E36: =C36*$E$6 -> 20.30624 | F36: =F35+G35-H35+I35 -> 27636.493 | G36: =F36*D36/1000 -> 1229.2856 | H36: =E36*F36/1000 -> 561.19327 | J36: =100 *(F37-F36) / F36 -> 2.417428
A37: =A36+1 -> 1947 | B37: 0.921 | C37: 0.698 | D37: =B37*$D$6 -> 44.09748 | E37: =C37*$E$6 -> 19.90696 | F37: =F36+G36-H36+I36 -> 28304.586 | G37: =F37*D37/1000 -> 1248.1609 | H37: =E37*F37/1000 -> 563.45826 | J37: =100 *(F38-F37) / F37 -> 2.419052
A38: =A37+1 -> 1948 | B38: 0.933 | C38: 0.696 | D38: =B38*$D$6 -> 44.67204 | E38: =C38*$E$6 -> 19.84992 | F38: =F37+G37-H37+I37 -> 28989.288 | G38: =F38*D38/1000 -> 1295.0107 | H38: =E38*F38/1000 -> 575.43506 | J38: =100 *(F39-F38) / F38 -> 2.482212
A39: =A38+1 -> 1949 | B39: 0.942 | C39: 0.697 | D39: =B39*$D$6 -> 45.10296 | E39: =C39*$E$6 -> 19.87844 | F39: =F38+G38-H38+I38 -> 29708.864 | G39: =F39*D39/1000 -> 1339.9577 | H39: =E39*F39/1000 -> 590.56587 | J39: =100 *(F40-F39) / F39 -> 2.522452
A40: =A39+1 -> 1950 | B40: 0.948 | C40: 0.694 | D40: =B40*$D$6 -> 45.39024 | E40: =C40*$E$6 -> 19.79288 | F40: =F39+G39-H39+I39 -> 30458.256 | G40: =F40*D40/1000 -> 1382.5075 | H40: =E40*F40/1000 -> 602.8566 | J40: =100 *(F41-F40) / F40 -> 2.559736
A41: =A40+1 -> 1951 | B41: 0.953 | C41: 0.688 | D41: =B41*$D$6 -> 45.62964 | E41: =C41*$E$6 -> 19.62176 | F41: =F40+G40-H40+I40 -> 31237.907 | G41: =F41*D41/1000 -> 1425.3744 | H41: =E41*F41/1000 -> 612.94271 | J41: =100 *(F42-F41) / F41 -> 2.600788
A42: =A41+1 -> 1952 | B42: 0.957 | C42: 0.679 | D42: =B42*$D$6 -> 45.82116 | E42: =C42*$E$6 -> 19.36508 | F42: =F41+G41-H41+I41 -> 32050.339 | G42: =F42*D42/1000 -> 1468.5837 | H42: =E42*F42/1000 -> 620.65737 | J42: =100 *(F43-F42) / F42 -> 2.645608
A43: =A42+1 -> 1953 | B43: 0.959 | C43: 0.669 | D43: =B43*$D$6 -> 45.91692 | E43: =C43*$E$6 -> 19.07988 | F43: =F42+G42-H42+I42 -> 32898.265 | G43: =F43*D43/1000 -> 1510.587 | H43: =E43*F43/1000 -> 627.69495 | J43: =100 *(F44-F43) / F43 -> 2.683704
A44: =A43+1 -> 1954 | B44: 0.96 | C44: 0.654 | D44: =B44*$D$6 -> 45.9648 | E44: =C44*$E$6 -> 18.65208 | F44: =F43+G43-H43+I43 -> 33781.157 | G44: =F44*D44/1000 -> 1552.7441 | H44: =E44*F44/1000 -> 630.08884 | J44: =100 *(F45-F44) / F44 -> 2.731272
A45: =A44+1 -> 1955 | B45: 0.963 | C45: 0.625 | D45: =B45*$D$6 -> 46.10844 | E45: =C45*$E$6 -> 17.825 | F45: =F44+G44-H44+I44 -> 34703.812 | G45: =F45*D45/1000 -> 1600.1386 | H45: =E45*F45/1000 -> 618.59545 | J45: =100 *(F46-F45) / F45 -> 2.828344
A46: =A45+1 -> 1956 | B46: 0.965 | C46: 0.589 | D46: =B46*$D$6 -> 46.2042 | E46: =C46*$E$6 -> 16.79828 | F46: =F45+G45-H45+I45 -> 35685.355 | G46: =F46*D46/1000 -> 1648.8133 | H46: =E46*F46/1000 -> 599.45259 | J46: =100 *(F47-F46) / F46 -> 2.940592
... A129: =A128+1 -> 2039 | B129: 0.304 | C129: 0.192 | D129: =B129*$D$6 -> 14.55552 | E129: =C129*$E$6 -> 5.47584 | F129: =F128+G128-H128+I128 -> 305829.47 | G129: =F129*D129/1000 -> 4451.5069 | H129: =E129*F129/1000 -> 1674.6732 | J129: =100 *(F130-F129) / F129 -> 0.907968
A130: =A129+1 -> 2040 | F130: =F129+G129-H129+I129 -> 308606.3
A132: Значения в полях с голубым фоном экстраполированы
...

Sheet MR
A1: Ретропрогноз динамики демографического перехода для населения территории Малороссии
D4: промилле | F4: тыс. чел.
A5: год | B5: RB | C5: RD | D5: рождаемость | E5: смертность | F5: население в начале года | G5: число рождений | H5: число смертей | I5: военная поправка | J5: темп прироста, % | L5: примечание
A6: 1909-1913 | D6: 40.76 | E6: 24.18 | F6: 18578 | L6: население на начало 1914 года
A7: 1917 | B7: 0.50231156 | C7: 0.91726991 | D7: =B7*$D$6 -> 20.474219 | E7: =C7*$E$6 -> 22.179586 | F7: =F6 * RSFSR!F7 / RSFSR!F6 -> 18943.76 | G7: =F7*D7/1000 -> 387.8587 | H7: =E7*F7/1000 -> 420.16477 | I7: =MR!F6 / RSFSR!F6 * INDIRECT("'RSFSR'!" & ADDRESS(ROW(), COLUMN())) -> -11.241352 | J7: =100 *(F8-F7) / F7 -> -0.22987738
A8: =A7+1 -> 1918 | B8: 0.59095477 | C8: 0.90382627 | D8: =B8*$D$6 -> 24.087317 | E8: =C8*$E$6 -> 21.854519 | F8: =F7+G7-H7+I7 -> 18900.213 | G8: =F8*D8/1000 -> 455.25541 | H8: =E8*F8/1000 -> 413.05506 | I8: =MR!F6 / RSFSR!F6 * INDIRECT("'RSFSR'!" & ADDRESS(ROW(), COLUMN())) -> -30.185113 | J8: =100 *(F9-F8) / F8 -> 0.063571954
A9: =A8+1 -> 1919 | B9: 0.98291457 | C9: 0.89245088 | D9: =B9*$D$6 -> 40.063598 | E9: =C9*$E$6 -> 21.579462 | F9: =F8+G8-H8+I8 -> 18912.228 | G9: =F9*D9/1000 -> 757.6919 | H9: =E9*F9/1000 -> 408.11571 | I9: =MR!F6 / RSFSR!F6 * INDIRECT("'RSFSR'!" & ADDRESS(ROW(), COLUMN())) -> 301.85113 | J9: =100 *(F10-F9) / F9 -> 3.4444768
A10: =A9+1 -> 1920 | B10: 0.9798995 | C10: 0.88831437 | D10: =B10*$D$6 -> 39.940704 | E10: =C10*$E$6 -> 21.479442 | F10: =F9+G9-H9+I9 -> 19563.655 | G10: =F10*D10/1000 -> 781.38616 | H10: =E10*F10/1000 -> 420.21639 | I10: =MR!F6 / RSFSR!F6 * INDIRECT("'RSFSR'!" & ADDRESS(ROW(), COLUMN())) -> 181.11068 | J10: =100 *(F11-F10) / F10 -> 2.7718769
A11: =A10+1 -> 1921 | B11: 0.97688442 | C11: 0.88004137 | D11: =B11*$D$6 -> 39.817809 | E11: =C11*$E$6 -> 21.2794 | F11: =F10+G10-H10+I10 -> 20105.936 | G11: =F11*D11/1000 -> 800.57432 | H11: =E11*F11/1000 -> 427.84226 | I11: =MR!F6 / RSFSR!F6 * INDIRECT("'RSFSR'!" & ADDRESS(ROW(), COLUMN())) -> 120.74045 | J11: =100 *(F12-F11) / F11 -> 2.4543623
A12: =A11+1 -> 1922 | B12: 0.97286432 | C12: 0.8697001 | D12: =B12*$D$6 -> 39.65395 | E12: =C12*$E$6 -> 21.029349 | F12: =F11+G11-H11+I11 -> 20599.408 | G12: =F12*D12/1000 -> 816.8479 | H12: =E12*F12/1000 -> 433.19214 | J12: =100 *(F13-F12) / F12 -> 1.8624601
A13: =A12+1 -> 1923 | B13: 0.96080402 | C13: 0.85729059 | D13: =B13*$D$6 -> 39.162372 | E13: =C13*$E$6 -> 20.729286 | F13: =F12+G12-H12+I12 -> 20983.064 | G13: =F13*D13/1000 -> 821.74656 | H13: =E13*F13/1000 -> 434.96395 | J13: =100 *(F14-F13) / F13 -> 1.8433085
A14: =A13+1 -> 1924 | B14: 0.96582915 | C14: 0.8459152 | D14: =B14*$D$6 -> 39.367196 | E14: =C14*$E$6 -> 20.45423 | F14: =F13+G13-H13+I13 -> 21369.847 | G14: =F14*D14/1000 -> 841.27095 | H14: =E14*F14/1000 -> 437.10375 | J14: =100 *(F15-F14) / F14 -> 1.8912966
A15: =A14+1 -> 1925 | B15: 0.97085427 | C15: 0.83350569 | D15: =B15*$D$6 -> 39.57202 | E15: =C15*$E$6 -> 20.154168 | F15: =F14+G14-H14+I14 -> 21774.014 | G15: =F15*D15/1000 -> 861.64172 | H15: =E15*F15/1000 -> 438.83712 | J15: =100 *(F16-F15) / F15 -> 1.9417853
A16: =A15+1 -> 1926 | B16: 0.97386935 | C16: 0.8262668 | D16: =B16*$D$6 -> 39.694915 | E16: =C16*$E$6 -> 19.979131 | F16: =F15+G15-H15+I15 -> 22196.819 | G16: =F16*D16/1000 -> 881.10082 | H16: =E16*F16/1000 -> 443.47315 | J16: =100 *(F17-F16) / F16 -> 1.9715783
A17: =A16+1 -> 1927 | B17: 0.96984925 | C17: 0.82109617 | D17: =B17*$D$6 -> 39.531055 | E17: =C17*$E$6 -> 19.854105 | F17: =F16+G16-H16+I16 -> 22634.446 | G17: =F17*D17/1000 -> 894.76354 | H17: =E17*F17/1000 -> 449.38668 | J17: =100 *(F18-F17) / F17 -> 1.967695
A18: =A17+1 -> 1928 | B18: 0.96984925 | C18: 0.82316443 | D18: =B18*$D$6 -> 39.531055 | E18: =C18*$E$6 -> 19.904116 | F18: =F17+G17-H17+I17 -> 23079.823 | G18: =F18*D18/1000 -> 912.36976 | H18: =E18*F18/1000 -> 459.38347 | J18: =100 *(F19-F18) / F18 -> 1.9626939
A19: =A18+1 -> 1929 | B19: 0.96683417 | C19: 0.8221303 | D19: =B19*$D$6 -> 39.408161 | E19: =C19*$E$6 -> 19.879111 | F19: =F18+G18-H18+I18 -> 23532.809 | G19: =F19*D19/1000 -> 927.38474 | H19: =E19*F19/1000 -> 467.81132 | J19: =100 *(F20-F19) / F19 -> 1.952905
A20: =A19+1 -> 1930 | B20: 0.96080402 | C20: 0.81489142 | D20: =B20*$D$6 -> 39.162372 | E20: =C20*$E$6 -> 19.704074 | F20: =F19+G19-H19+I19 -> 23992.383 | G20: =F20*D20/1000 -> 939.59862 | H20: =E20*F20/1000 -> 472.7477 | J20: =100 *(F21-F20) / F20 -> 1.9458297
A21: =A20+1 -> 1931 | B21: 0.95477387 | C21: 0.79420889 | D21: =B21*$D$6 -> 38.916583 | E21: =C21*$E$6 -> 19.203971 | F21: =F20+G20-H20+I20 -> 24459.234 | G21: =F21*D21/1000 -> 951.8698 | H21: =E21*F21/1000 -> 469.71442 | J21: =100 *(F22-F21) / F21 -> 1.9712612
A22: =A21+1 -> 1932 | B22: 0.94572864 | C22: 0.76732161 | D22: =B22*$D$6 -> 38.547899 | E22: =C22*$E$6 -> 18.553837 | F22: =F21+G21-H21+I21 -> 24941.389 | G22: =F22*D22/1000 -> 961.43816 | H22: =E22*F22/1000 -> 462.75846 | J22: =100 *(F23-F22) / F22 -> 1.9994063
A23: =A22+1 -> 1933 | B23: 0.93869347 | C23: 0.75180972 | D23: =B23*$D$6 -> 38.261146 | E23: =C23*$E$6 -> 18.178759 | F23: =F22+G22-H22+I22 -> 25440.069 | G23: =F23*D23/1000 -> 973.36618 | H23: =E23*F23/1000 -> 462.46888 | J23: =100 *(F24-F23) / F23 -> 2.0082387
... A31: =A30+1 -> 1941 | B31: 0.9638191 | C31: 0.6918304 | D31: =B31*$D$6 -> 39.285266 | E31: =C31*$E$6 -> 16.728459 | F31: =F30+G30-H30+I30 -> 30045.403 | G31: =F31*D31/1000 -> 1180.3417 | H31: =E31*F31/1000 -> 502.61329 | J31: =100 *(F32-F31) / F31 -> 2.2556807
A32: =A31+1 -> 1942 | B32: 0.96482412 | C32: 0.67631851 | D32: =B32*$D$6 -> 39.326231 | E32: =C32*$E$6 -> 16.353382 | F32: =F31+G31-H31+I31 -> 30723.131 | G32: =F32*D32/1000 -> 1208.225 | H32: =E32*F32/1000 -> 502.42709 | I32: =MR!F6 / RSFSR!F6 * INDIRECT("'RSFSR'!" & ADDRESS(ROW(), COLUMN())) -> -18.735587 | J32: =100 *(F33-F32) / F32 -> 2.2363029
A33: =A32+1 -> 1943 | B33: 0.9678392 | C33: 0.64632885 | D33: =B33*$D$6 -> 39.449126 | E33: =C33*$E$6 -> 15.628232 | F33: =F32+G32-H32+I32 -> 31410.193 | G33: =F33*D33/1000 -> 1239.1047 | H33: =E33*F33/1000 -> 490.88578 | I33: =MR!F6 / RSFSR!F6 * INDIRECT("'RSFSR'!" & ADDRESS(ROW(), COLUMN())) -> -18.735587 | J33: =100 *(F34-F33) / F33 -> 2.3224413
A34: =A33+1 -> 1944 | B34: 0.96984925 | C34: 0.60910031 | D34: =B34*$D$6 -> 39.531055 | E34: =C34*$E$6 -> 14.728046 | F34: =F33+G33-H33+I33 -> 32139.677 | G34: =F34*D34/1000 -> 1270.5153 | H34: =E34*F34/1000 -> 473.35462 | I34: =MR!F6 / RSFSR!F6 * INDIRECT("'RSFSR'!" & ADDRESS(ROW(), COLUMN())) -> -18.735587 | J34: =100 *(F35-F34) / F34 -> 2.4220067
A35: =A34+1 -> 1945 | B35: 0.97487437 | C35: 0.57600827 | D35: =B35*$D$6 -> 39.735879 | E35: =C35*$E$6 -> 13.92788 | F35: =F34+G34-H34+I34 -> 32918.102 | G35: =F35*D35/1000 -> 1308.0297 | H35: =E35*F35/1000 -> 458.47937 | J35: =100 *(F36-F35) / F35 -> 2.5807999
A36: =A35+1 -> 1946 | B36: 0.97386935 | C36: 0.54601861 | D36: =B36*$D$6 -> 39.694915 | E36: =C36*$E$6 -> 13.20273 | F36: =F35+G35-H35+I35 -> 33767.652 | G36: =F36*D36/1000 -> 1340.4041 | H36: =E36*F36/1000 -> 445.8252 | J36: =100 *(F37-F36) / F36 -> 2.6492184
A37: =A36+1 -> 1947 | B37: 0.9678392 | C37: 0.5377456 | D37: =B37*$D$6 -> 39.449126 | E37: =C37*$E$6 -> 13.002689 | F37: =F36+G36-H36+I36 -> 34662.231 | G37: =F37*D37/1000 -> 1367.3947 | H37: =E37*F37/1000 -> 450.7022 | J37: =100 *(F38-F37) / F37 -> 2.6446437
A38: =A37+1 -> 1948 | B38: 0.9678392 | C38: 0.52326784 | D38: =B38*$D$6 -> 39.449126 | E38: =C38*$E$6 -> 12.652616 | F38: =F37+G37-H37+I37 -> 35578.924 | G38: =F38*D38/1000 -> 1403.5574 | H38: =E38*F38/1000 -> 450.16647 | J38: =100 *(F39-F38) / F38 -> 2.6796509
A39: =A38+1 -> 1949 | B39: 0.97085427 | C39: 0.51913133 | D39: =B39*$D$6 -> 39.57202 | E39: =C39*$E$6 -> 12.552596 | F39: =F38+G38-H38+I38 -> 36532.315 | G39: =F39*D39/1000 -> 1445.6575 | H39: =E39*F39/1000 -> 458.57537 | J39: =100 *(F40-F39) / F39 -> 2.7019424
A40: =A39+1 -> 1950 | B40: 0.9718593 | C40: 0.5098242 | D40: =B40*$D$6 -> 39.612985 | E40: =C40*$E$6 -> 12.327549 | F40: =F39+G39-H39+I39 -> 37519.397 | G40: =F40*D40/1000 -> 1486.2553 | H40: =E40*F40/1000 -> 462.52221 | J40: =100 *(F41-F40) / F40 -> 2.7285436
A41: =A40+1 -> 1951 | B41: 0.98090452 | C41: 0.48914168 | D41: =B41*$D$6 -> 39.981668 | E41: =C41*$E$6 -> 11.827446 | F41: =F40+G40-H40+I40 -> 38543.13 | G41: =F41*D41/1000 -> 1541.0186 | H41: =E41*F41/1000 -> 455.86678 | J41: =100 *(F42-F41) / F41 -> 2.8154223
A42: =A41+1 -> 1952 | B42: 0.97788945 | C42: 0.45604964 | D42: =B42*$D$6 -> 39.858774 | E42: =C42*$E$6 -> 11.02728 | F42: =F41+G41-H41+I41 -> 39628.282 | G42: =F42*D42/1000 -> 1579.5347 | H42: =E42*F42/1000 -> 436.99217 | J42: =100 *(F43-F42) / F42 -> 2.8831494
A43: =A42+1 -> 1953 | B43: 0.98693467 | C43: 0.43536711 | D43: =B43*$D$6 -> 40.227457 | E43: =C43*$E$6 -> 10.527177 | F43: =F42+G42-H42+I42 -> 40770.824 | G43: =F43*D43/1000 -> 1640.1066 | H43: =E43*F43/1000 -> 429.20168 | J43: =100 *(F44-F43) / F43 -> 2.970028
A44: =A43+1 -> 1954 | B44: 0.99497487 | C44: 0.41158221 | D44: =B44*$D$6 -> 40.555176 | E44: =C44*$E$6 -> 9.9520579 | F44: =F43+G43-H43+I43 -> 41981.729 | G44: =F44*D44/1000 -> 1702.5764 | H44: =E44*F44/1000 -> 417.8046 | J44: =100 *(F45-F44) / F44 -> 3.0603118
A45: =A44+1 -> 1955 | B45: 1 | C45: 0.40124095 | D45: =B45*$D$6 -> 40.76 | E45: =C45*$E$6 -> 9.7020062 | F45: =F44+G44-H44+I44 -> 43266.501 | G45: =F45*D45/1000 -> 1763.5426 | H45: =E45*F45/1000 -> 419.77186 | J45: =100 *(F46-F45) / F45 -> 3.1057994
A46: =A45+1 -> 1956 | B46: 1.0060302 | C46: 0.38676319 | D46: =B46*$D$6 -> 41.005789 | E46: =C46*$E$6 -> 9.3519338 | F46: =F45+G45-H45+I45 -> 44610.272 | G46: =F46*D46/1000 -> 1829.2794 | H46: =E46*F46/1000 -> 417.19231 | J46: =100 *(F47-F46) / F46 -> 3.1653855
... A129: =A128+1 -> 2039 | B129: 0.222 | C129: 0.217 | D129: =B129*$D$6 -> 9.04872 | E129: =C129*$E$6 -> 5.24706 | F129: =F128+G128-H128+I128 -> 214850.98 | G129: =F129*D129/1000 -> 1944.1264 | H129: =E129*F129/1000 -> 1127.336 | J129: =100 *(F130-F129) / F129 -> 0.380166
A130: =A129+1 -> 2040 | F130: =F129+G129-H129+I129 -> 215667.77
A132: Значения в полях с голубым фоном экстраполированы
...

Sheet BR
A1: Ретропрогноз динамики демографического перехода для населения территории Белоруссии
D4: промилле | F4: тыс. чел.
A5: год | B5: RB | C5: RD | D5: рождаемость | E5: смертность | F5: население в начале года | G5: число рождений | H5: число смертей | I5: военная поправка | J5: темп прироста, % | L5: примечание
A6: 1909-1913 | D6: 41.04 | E6: 22.92 | F6: 10686 | L6: население на начало 1914 года
A7: 1917 | B7: 0.5003003 | C7: 0.89415323 | D7: =B7*$D$6 -> 20.532324 | E7: =C7*$E$6 -> 20.493992 | F7: =F6 * RSFSR!F7 / RSFSR!F6 -> 10896.384 | G7: =F7*D7/1000 -> 223.72809 | H7: =E7*F7/1000 -> 223.31041 | I7: =BR!F6 / RSFSR!F6 * INDIRECT("'RSFSR'!" & ADDRESS(ROW(), COLUMN())) -> -6.4659861 | J7: =100 *(F8-F7) / F7 -> -0.05550742
A8: =A7+1 -> 1918 | B8: 0.58858859 | C8: 0.88104839 | D8: =B8*$D$6 -> 24.155676 | E8: =C8*$E$6 -> 20.193629 | F8: =F7+G7-H7+I7 -> 10890.336 | G8: =F8*D8/1000 -> 263.06342 | H8: =E8*F8/1000 -> 219.9154 | I8: =BR!F6 / RSFSR!F6 * INDIRECT("'RSFSR'!" & ADDRESS(ROW(), COLUMN())) -> -17.36237 | J8: =100 *(F9-F8) / F8 -> 0.23677551
A9: =A8+1 -> 1919 | B9: 0.97897898 | C9: 0.86995968 | D9: =B9*$D$6 -> 40.177297 | E9: =C9*$E$6 -> 19.939476 | F9: =F8+G8-H8+I8 -> 10916.121 | G9: =F9*D9/1000 -> 438.58025 | H9: =E9*F9/1000 -> 217.66174 | I9: =BR!F6 / RSFSR!F6 * INDIRECT("'RSFSR'!" & ADDRESS(ROW(), COLUMN())) -> 173.6237 | J9: =100 *(F10-F9) / F9 -> 3.6143077
A10: =A9+1 -> 1920 | B10: 0.97597598 | C10: 0.86592742 | D10: =B10*$D$6 -> 40.054054 | E10: =C10*$E$6 -> 19.847056 | F10: =F9+G9-H9+I9 -> 11310.664 | G10: =F10*D10/1000 -> 453.03793 | H10: =E10*F10/1000 -> 224.48338 | I10: =BR!F6 / RSFSR!F6 * INDIRECT("'RSFSR'!" & ADDRESS(ROW(), COLUMN())) -> 104.17422 | J10: =100 *(F11-F10) / F10 -> 2.9417264
A11: =A10+1 -> 1921 | B11: 0.97297297 | C11: 0.8578629 | D11: =B11*$D$6 -> 39.930811 | E11: =C11*$E$6 -> 19.662218 | F11: =F10+G10-H10+I10 -> 11643.392 | G11: =F11*D11/1000 -> 464.9301 | H11: =E11*F11/1000 -> 228.93492 | I11: =BR!F6 / RSFSR!F6 * INDIRECT("'RSFSR'!" & ADDRESS(ROW(), COLUMN())) -> 69.449481 | J11: =100 *(F12-F11) / F11 -> 2.6233305
A12: =A11+1 -> 1922 | B12: 0.96896897 | C12: 0.84778226 | D12: =B12*$D$6 -> 39.766486 | E12: =C12*$E$6 -> 19.431169 | F12: =F11+G11-H11+I11 -> 11948.837 | G12: =F12*D12/1000 -> 475.16327 | H12: =E12*F12/1000 -> 232.17988 | J12: =100 *(F13-F12) / F12 -> 2.0335317
A13: =A12+1 -> 1923 | B13: 0.95695696 | C13: 0.83568548 | D13: =B13*$D$6 -> 39.273514 | E13: =C13*$E$6 -> 19.153911 | F13: =F12+G12-H12+I12 -> 12191.82 | G13: =F13*D13/1000 -> 478.81562 | H13: =E13*F13/1000 -> 233.52105 | J13: =100 *(F14-F13) / F13 -> 2.0119602
A14: =A13+1 -> 1924 | B14: 0.96196196 | C14: 0.82459677 | D14: =B14*$D$6 -> 39.478919 | E14: =C14*$E$6 -> 18.899758 | F14: =F13+G13-H13+I13 -> 12437.115 | G14: =F14*D14/1000 -> 491.00385 | H14: =E14*F14/1000 -> 235.05846 | J14: =100 *(F15-F14) / F14 -> 2.0579161
A15: =A14+1 -> 1925 | B15: 0.96696697 | C15: 0.8125 | D15: =B15*$D$6 -> 39.684324 | E15: =C15*$E$6 -> 18.6225 | F15: =F14+G14-H14+I14 -> 12693.06 | G15: =F15*D15/1000 -> 503.71553 | H15: =E15*F15/1000 -> 236.37652 | J15: =100 *(F16-F15) / F15 -> 2.1061824
A16: =A15+1 -> 1926 | B16: 0.96996997 | C16: 0.80544355 | D16: =B16*$D$6 -> 39.807568 | E16: =C16*$E$6 -> 18.460766 | F16: =F15+G15-H15+I15 -> 12960.399 | G16: =F16*D16/1000 -> 515.92197 | H16: =E16*F16/1000 -> 239.2589 | J16: =100 *(F17-F16) / F16 -> 2.1346801
A17: =A16+1 -> 1927 | B17: 0.96596597 | C17: 0.80040323 | D17: =B17*$D$6 -> 39.643243 | E17: =C17*$E$6 -> 18.345242 | F17: =F16+G16-H16+I16 -> 13237.062 | G17: =F17*D17/1000 -> 524.76009 | H17: =E17*F17/1000 -> 242.83711 | J17: =100 *(F18-F17) / F17 -> 2.1298001
A18: =A17+1 -> 1928 | B18: 0.96596597 | C18: 0.80241935 | D18: =B18*$D$6 -> 39.643243 | E18: =C18*$E$6 -> 18.391452 | F18: =F17+G17-H17+I17 -> 13518.985 | G18: =F18*D18/1000 -> 535.93643 | H18: =E18*F18/1000 -> 248.63377 | J18: =100 *(F19-F18) / F18 -> 2.1251792
A19: =A18+1 -> 1929 | B19: 0.96296296 | C19: 0.80141129 | D19: =B19*$D$6 -> 39.52 | E19: =C19*$E$6 -> 18.368347 | F19: =F18+G18-H18+I18 -> 13806.288 | G19: =F19*D19/1000 -> 545.62451 | H19: =E19*F19/1000 -> 253.59869 | J19: =100 *(F20-F19) / F19 -> 2.1151653
A20: =A19+1 -> 1930 | B20: 0.95695696 | C20: 0.79435484 | D20: =B20*$D$6 -> 39.273514 | E20: =C20*$E$6 -> 18.206613 | F20: =F19+G19-H19+I19 -> 14098.314 | G20: =F20*D20/1000 -> 553.69032 | H20: =E20*F20/1000 -> 256.68254 | J20: =100 *(F21-F20) / F20 -> 2.1066901
A21: =A20+1 -> 1931 | B21: 0.95095095 | C21: 0.77419355 | D21: =B21*$D$6 -> 39.027027 | E21: =C21*$E$6 -> 17.744516 | F21: =F20+G20-H20+I20 -> 14395.322 | G21: =F21*D21/1000 -> 561.80661 | H21: =E21*F21/1000 -> 255.43802 | J21: =100 *(F22-F21) / F21 -> 2.1282511
A22: =A21+1 -> 1932 | B22: 0.94194194 | C22: 0.74798387 | D22: =B22*$D$6 -> 38.657297 | E22: =C22*$E$6 -> 17.14379 | F22: =F21+G21-H21+I21 -> 14701.69 | G22: =F22*D22/1000 -> 568.32761 | H22: =E22*F22/1000 -> 252.0427 | J22: =100 *(F23-F22) / F22 -> 2.1513507
A23: =A22+1 -> 1933 | B23: 0.93493493 | C23: 0.7328629 | D23: =B23*$D$6 -> 38.36973 | E23: =C23*$E$6 -> 16.797218 | F23: =F22+G22-H22+I22 -> 15017.975 | G23: =F23*D23/1000 -> 576.23565 | H23: =E23*F23/1000 -> 252.2602 | J23: =100 *(F24-F23) / F23 -> 2.1572512
... A31: =A30+1 -> 1941 | B31: 0.95995996 | C31: 0.67439516 | D31: =B31*$D$6 -> 39.396757 | E31: =C31*$E$6 -> 15.457137 | F31: =F30+G30-H30+I30 -> 17937.37 | G31: =F31*D31/1000 -> 706.6742 | H31: =E31*F31/1000 -> 277.26038 | J31: =100 *(F32-F31) / F31 -> 2.393962
A32: =A31+1 -> 1942 | B32: 0.96096096 | C32: 0.65927419 | D32: =B32*$D$6 -> 39.437838 | E32: =C32*$E$6 -> 15.110565 | F32: =F31+G31-H31+I31 -> 18366.784 | G32: =F32*D32/1000 -> 724.34623 | H32: =E32*F32/1000 -> 277.53247 | I32: =BR!F6 / RSFSR!F6 * INDIRECT("'RSFSR'!" & ADDRESS(ROW(), COLUMN())) -> -10.776644 | J32: =100 *(F33-F32) / F32 -> 2.3740527
A33: =A32+1 -> 1943 | B33: 0.96396396 | C33: 0.63004032 | D33: =B33*$D$6 -> 39.561081 | E33: =C33*$E$6 -> 14.440524 | F33: =F32+G32-H32+I32 -> 18802.821 | G33: =F33*D33/1000 -> 743.85992 | H33: =E33*F33/1000 -> 271.52259 | I33: =BR!F6 / RSFSR!F6 * INDIRECT("'RSFSR'!" & ADDRESS(ROW(), COLUMN())) -> -10.776644 | J33: =100 *(F34-F33) / F33 -> 2.4547417
A34: =A33+1 -> 1944 | B34: 0.96596597 | C34: 0.59375 | D34: =B34*$D$6 -> 39.643243 | E34: =C34*$E$6 -> 13.60875 | F34: =F33+G33-H33+I33 -> 19264.381 | G34: =F34*D34/1000 -> 763.70256 | H34: =E34*F34/1000 -> 262.16415 | I34: =BR!F6 / RSFSR!F6 * INDIRECT("'RSFSR'!" & ADDRESS(ROW(), COLUMN())) -> -10.776644 | J34: =100 *(F35-F34) / F34 -> 2.5475086
A35: =A34+1 -> 1945 | B35: 0.97097097 | C35: 0.56149194 | D35: =B35*$D$6 -> 39.848649 | E35: =C35*$E$6 -> 12.869395 | F35: =F34+G34-H34+I34 -> 19755.143 | G35: =F35*D35/1000 -> 787.21576 | H35: =E35*F35/1000 -> 254.23674 | J35: =100 *(F36-F35) / F35 -> 2.6979253
A36: =A35+1 -> 1946 | B36: 0.96996997 | C36: 0.53225806 | D36: =B36*$D$6 -> 39.807568 | E36: =C36*$E$6 -> 12.199355 | F36: =F35+G35-H35+I35 -> 20288.122 | G36: =F36*D36/1000 -> 807.6208 | H36: =E36*F36/1000 -> 247.502 | J36: =100 *(F37-F36) / F36 -> 2.7608213
A37: =A36+1 -> 1947 | B37: 0.96396396 | C37: 0.52419355 | D37: =B37*$D$6 -> 39.561081 | E37: =C37*$E$6 -> 12.014516 | F37: =F36+G36-H36+I36 -> 20848.241 | G37: =F37*D37/1000 -> 824.77895 | H37: =E37*F37/1000 -> 250.48153 | J37: =100 *(F38-F37) / F37 -> 2.7546565
A38: =A37+1 -> 1948 | B38: 0.96396396 | C38: 0.51008065 | D38: =B38*$D$6 -> 39.561081 | E38: =C38*$E$6 -> 11.691048 | F38: =F37+G37-H37+I37 -> 21422.538 | G38: =F38*D38/1000 -> 847.49878 | H38: =E38*F38/1000 -> 250.45193 | J38: =100 *(F39-F38) / F38 -> 2.7870033
A39: =A38+1 -> 1949 | B39: 0.96696697 | C39: 0.50604839 | D39: =B39*$D$6 -> 39.684324 | E39: =C39*$E$6 -> 11.598629 | F39: =F38+G38-H38+I38 -> 22019.585 | G39: =F39*D39/1000 -> 873.83236 | H39: =E39*F39/1000 -> 255.397 | J39: =100 *(F40-F39) / F39 -> 2.8085695
A40: =A39+1 -> 1950 | B40: 0.96796797 | C40: 0.49697581 | D40: =B40*$D$6 -> 39.725405 | E40: =C40*$E$6 -> 11.390685 | F40: =F39+G39-H39+I39 -> 22638.021 | G40: =F40*D40/1000 -> 899.30455 | H40: =E40*F40/1000 -> 257.86257 | J40: =100 *(F41-F40) / F40 -> 2.833472
A41: =A40+1 -> 1951 | B41: 0.97697698 | C41: 0.47681452 | D41: =B41*$D$6 -> 40.095135 | E41: =C41*$E$6 -> 10.928589 | F41: =F40+G40-H40+I40 -> 23279.463 | G41: =F41*D41/1000 -> 933.3932 | H41: =E41*F41/1000 -> 254.41167 | J41: =100 *(F42-F41) / F41 -> 2.9166546
A42: =A41+1 -> 1952 | B42: 0.97397397 | C42: 0.44455645 | D42: =B42*$D$6 -> 39.971892 | E42: =C42*$E$6 -> 10.189234 | F42: =F41+G41-H41+I41 -> 23958.444 | G42: =F42*D42/1000 -> 957.66434 | H42: =E42*F42/1000 -> 244.11819 | J42: =100 *(F43-F42) / F42 -> 2.9782658
A43: =A42+1 -> 1953 | B43: 0.98298298 | C43: 0.42439516 | D43: =B43*$D$6 -> 40.341622 | E43: =C43*$E$6 -> 9.7271371 | F43: =F42+G42-H42+I42 -> 24671.99 | G43: =F43*D43/1000 -> 995.3081 | H43: =E43*F43/1000 -> 239.98783 | J43: =100 *(F44-F43) / F43 -> 3.0614485
A44: =A43+1 -> 1954 | B44: 0.99099099 | C44: 0.40120968 | D44: =B44*$D$6 -> 40.67027 | E44: =C44*$E$6 -> 9.1957258 | F44: =F43+G43-H43+I43 -> 25427.311 | G44: =F44*D44/1000 -> 1034.1356 | H44: =E44*F44/1000 -> 233.82258 | J44: =100 *(F45-F44) / F44 -> 3.1474544
A45: =A44+1 -> 1955 | B45: 0.995996 | C45: 0.39112903 | D45: =B45*$D$6 -> 40.875676 | E45: =C45*$E$6 -> 8.9646774 | F45: =F44+G44-H44+I44 -> 26227.624 | G45: =F45*D45/1000 -> 1072.0718 | H45: =E45*F45/1000 -> 235.12218 | J45: =100 *(F46-F45) / F45 -> 3.1910998
A46: =A45+1 -> 1956 | B46: 1.002002 | C46: 0.37701613 | D46: =B46*$D$6 -> 41.122162 | E46: =C46*$E$6 -> 8.6412097 | F46: =F45+G45-H45+I45 -> 27064.573 | G46: =F46*D46/1000 -> 1112.9538 | H46: =E46*F46/1000 -> 233.87065 | J46: =100 *(F47-F46) / F46 -> 3.2480952
... A129: =A128+1 -> 2039 | B129: 0.22 | C129: 0.212 | D129: =B129*$D$6 -> 9.0288 | E129: =C129*$E$6 -> 4.85904 | F129: =F128+G128-H128+I128 -> 135207.21 | G129: =F129*D129/1000 -> 1220.7589 | H129: =E129*F129/1000 -> 656.97726 | J129: =100 *(F130-F129) / F129 -> 0.416976
A130: =A129+1 -> 2040 | F130: =F129+G129-H129+I129 -> 135771
A135: Ожидаемая численность населеления на даты состоявшихся переписей населения
...

Sheet USSR
A1: Ретропрогноз динамики демографического перехода для населения территории СССР
A3: Ожидаемая численность населения текущей территории СССР на даты состоявшихся переписей населения СССР, тыс. чел.
A4: Для 2020, 2030 и 2040 подсчёт не по СССР, а по России + Украине + Белоруссии.
S5: части Новороссии, Малороссии и Белоруссии вне границ СССР | V5: население СССР (текущая территория)
A6: год | B6: дата | C6: РСФСР-1991 | D6: Новороссия | E6: Малороссия | F6: Белоруссия | G6: Азербайджан | H6: Армения | I6: Грузия | J6: Латвия | K6: Литва | L6: Казак. | M6: Киргизия | N6: Таджикия | O6: Туркмения | P6: Узбек. | Q6: Эстония | R6: подавстрийские земли и Тува | S6: НР | T6: МР | U6: БР | V6: ожидаемое: сумма без частей НР, БР, МР вне СССР | W6: фактическое | X6: % потерь | Y6: величина потерь
A8: 1926 | B8: 17 дек | C8: =RSFSR!F139 -> 106845.82 | D8: =NR!F139 -> 18044.897 | E8: =MR!F139 -> 22616.293 | F8: =BR!F139 -> 13225.577 | G8: 2315 | H8: 880 | I8: 2666 | L8: 6503 | M8: 993 | N8: - | O8: 1001 | P8: 5273 | S8: =D8 * 0.168 -> 3031.5427 | T8: =E8 * 0.112 -> 2533.0248 | U8: =F8 * 0.179 -> 2367.3783 | V8: =SUM(C8:R8) - SUM(S8:U8) -> 172431.64 | W8: 148530 | X8: =100 * (V8-W8) / V8 -> 13.861515 | Y8: =V8-W8 -> 23901.638
A9: 1937 | B9: 6 янв | C9: =RSFSR!F140 -> 130704.49 | D9: =NR!F140 -> 22455.186 | E9: =MR!F140 -> 27583.59 | F9: =BR!F140 -> 16376.68 | G9: 3057 | H9: 1209 | I9: 3377 | L9: 5120 | M9: 1370 | N9: 1382 | O9: 1169 | P9: 5847 | S9: =D9 * 0.168 -> 3772.4712 | T9: =E9 * 0.112 -> 3089.3621 | U9: =F9 * 0.179 -> 2931.4256 | V9: =SUM(C9:R9) - SUM(S9:U9) -> 209857.69 | W9: 162039 | X9: =100 * (V9-W9) / V9 -> 22.786245 | Y9: =V9-W9 -> 47818.688
A10: 1939 | B10: 17 янв | C10: =RSFSR!F141 -> 136512 | D10: =NR!F141 -> 23536.67 | E10: =MR!F141 -> 28791.326 | F10: =BR!F141 -> 17142.391 | G10: 3205.15 | H10: 1282.338 | I10: 3540.023 | L10: 6151.102 | M10: 1458.213 | N10: 1484.44 | O10: 1251.883 | P10: 6271.269 | S10: =D10 * 0.168 -> 3954.1605 | T10: =E10 * 0.112 -> 3224.6285 | U10: =F10 * 0.179 -> 3068.488 | V10: =SUM(C10:R10) - SUM(S10:U10) -> 220379.53 | W10: 167650 | X10: =100 * (V10-W10) / V10 -> 23.926691 | Y10: =V10-W10 -> 52729.529
A11: 1959 | B11: 15 янв | C11: =RSFSR!F142 -> 220688.71 | D11: =NR!F142 -> 39089.743 | E11: =MR!F142 -> 49057.999 | F11: =BR!F142 -> 29834.115 | G11: 3697.717 | H11: 1763.048 | I11: 4044.045 | J11: 2093.458 | K11: 2711.445 | L11: 9309.847 | M11: 2065.837 | N11: 1979.897 | O11: 1516.375 | P11: 8105.704 | Q11: 1196.791 | R11: =H74 -> 6155 | V11: =SUM(C11:R11) - SUM(S11:U11) -> 383309.73 | W11: 208826.65 | X11: =100 * (V11-W11) / V11 -> 45.520128 | Y11: =V11-W11 -> 174483.08
A12: 1970 | B12: 15 янв | C12: =RSFSR!F143 -> 317618.53 | D12: =NR!F143 -> 56622.04 | E12: =MR!F143 -> 69527.974 | F12: =BR!F143 -> 42596.3 | G12: 5117 | H12: 2492 | I12: 4686.4 | J12: 2364.1 | K12: 3128.2 | L12: 12848.6 | M12: 2932.8 | N12: 2899.6 | O12: 2158.9 | P12: 11959.6 | Q12: 1356.1 | R12: =H75 -> 6964 | V12: =SUM(C12:R12) - SUM(S12:U12) -> 545272.14 | W12: 241720 | X12: =100 * (V12-W12) / V12 -> 55.669842 | Y12: =V12-W12 -> 303552.14
A13: 1979 | B13: 17 янв | C13: =RSFSR!F144 -> 445922.55 | D13: =NR!F144 -> 79216.98 | E13: =MR!F144 -> 90944.464 | F13: =BR!F144 -> 55977.842 | G13: 6028 | H13: 3031 | I13: 5015 | J13: 2521 | K13: 3398 | L13: 14685 | M13: 3529 | N13: 3801 | O13: 2759 | P13: 15391 | Q13: 1466 | R13: =H76 -> 7372 | V13: =SUM(C13:R13) - SUM(S13:U13) -> 741057.84 | W13: 262436 | X13: =100 * (V13-W13) / V13 -> 64.5863 | Y13: =V13-W13 -> 478621.84
A14: 1989 | B14: 12 янв | C14: =RSFSR!F145 -> 644973.97 | D14: =NR!F145 -> 113563.48 | E14: =MR!F145 -> 117667.83 | F14: =BR!F145 -> 72712.743 | G14: 7038 | H14: 3288 | I14: 5443 | J14: 2680 | K14: 3690 | L14: 16537 | M14: 4290 | N14: 5109 | O14: 3534 | P14: 19905 | Q14: 1573 | R14: =H77 -> 7839 | V14: =SUM(C14:R14) - SUM(S14:U14) -> 1029844 | W14: 286731 | X14: =100 * (V14-W14) / V14 -> 72.157823 | Y14: =V14-W14 -> 743113.03
A15: 2020 | B15: 1 янв | C15: =RSFSR!F146 -> 1405423.6 | D15: =NR!F146 -> 240156.33 | E15: =MR!F146 -> 188105.23 | F15: =BR!F146 -> 117539.03 | R15: =H78 -> 6707.7018 | V15: =SUM(C15:R15) - SUM(S15:U15) -> 1957931.9 | W15: =C89 -> 198061 | X15: =100 * (V15-W15) / V15 -> 89.884173 | Y15: =V15-W15 -> 1759870.9
A16: 2030 | B16: 1 янв | C16: =RSFSR!F147 -> 1628910.2 | D16: =NR!F147 -> 277227.89 | E16: =MR!F147 -> 204656.37 | F16: =BR!F147 -> 128368.08 | V16: =SUM(C16:R16) - SUM(S16:U16) -> 2239162.6
A17: 2040 | B17: 1 янв | C17: =RSFSR!F148 -> 1818185.4 | D17: =NR!F148 -> 308606.3 | E17: =MR!F148 -> 215667.77 | F17: =BR!F148 -> 135771 | V17: =SUM(C17:R17) - SUM(S17:U17) -> 2478230.4
A19: Величины в полях с зелёным фоном вычислены ретропрогнозом динамики демографического перехода.
A20: Величины в полях с синим фоном представляют фактические значения по переписям населения.
A21: Серым цветом помечены земли не входившие на дату переписи в состав СССР.
A22: Желтым цветом помечены земли входившие на дату переписи в административный состав других республик.
B24: РСФСР-1991 | D24: границы таксона не включают Туву
B26: СССР фактич. | D26: фактическая численность населения СССР по переписям
D27: для 2020 г. указана суммарная численность населения РФ (включая Туву), Украины (с подавстрийскими землями) и Белоруссии
B29: подавстрийские земли и Тува | D29: фактическая численность (по переписям) территорий присоединённых в 1939-1945 гг.
D30: и не входивших в состав России до 1914 года, и поэтому не входящих в состав таксонов РСФСР-1991, Новороссии, Малороссии и Белоруссии
B32: часть НР + МР + БР вне СССР | D32: части таксонов Новроссия, Малороссия, Белоруссия находившиеся в 1926-1939 гг. вне состава СССР
E34: На момент переписей 1926, 1937 и 1939 гг. в состав СССР не входили:
E35: – Бессарабская губерния, население которой в 1914 году составляло 16.8% всего населения Новороссии
E36: – Гродненская губерния, население которой в 1914 году составляло 17.9% всего населения Белоруссии
E37: – западная часть Волынской губернии, а именно Владимир-Волынский, Дубенский, Ковельский, Кременецкий, Луцкий, Острожский и Ровенский уезды
E38: по переписи 1897 года составлявшие 53.5% населения губернии;
E39: сама же губерния в 1914 году составла 20.9% населения Малороссии,
E40: таким образом 11.2% населения Малороссии в 1926-1939 гг оказались вне границ СССР
B42: сумма без вне СССР | D42: сумма колонок от РСФСР-1991 по Эстонию минус "НР, МР, БР вне СССР"
D43: представляет ожидаемую численность населения территории в текущих (на момент переписи) границах СССР
A45: Источники сведений переписей:
B47: 1926 | E47: ЦСУ СССР, "Всесоюзная перепись населения 1926 года", М. 1929, т. 17 отдел 1 (Союз СССР), стр. 2
E48: Таджикистан в 1926 году входил в состав Узбекистана и учтён вместе с ним
E49: Киргизия в 1926 году входила в состав РСФСР, но не входит в состав таксона РСФСР-1991
E50: Казакская АССР в 1926 входила в состав РСФСР, но не входит в состав таксона РСФСР-1991
E51: Численность населения для Киргизии и Казахстана см. ЦСУ СССР, "Всесоюзная перепись населения 1926 года", т. 9 (РСФСР), М. 1929, стр. 24
...

Sheet USSR-Simplified
A1: Ретропрогноз динамики демографического перехода для населения территории СССР, упрощённая таблица
A3: Ожидаемая численность населения текущей территории СССР на даты состоявшихся переписей населения СССР, тыс. чел.
A4: Для 2020, 2030 и 2040 подсчёт не по СССР, а по России + Украине + Белоруссии.
C5: ожидаемая численность | H5: фактическая численность | J5: население в текущих границах СССР
A6: год | B6: дата | C6: РСФСР-1991 | D6: Новороссия | E6: Малороссия | F6: Белоруссия | G6: части Новороссии, Малороссии и Белоруссии вне границ СССР | H6: нерусские этнические образования в составе СССР | I6: подавстрийские земли и Тува | J6: ожидаемое | K6: фактическое | L6: % потерь | M6: величина потерь
A8: {=INDIRECT("USSR!" & ADDRESS(ROW(), COLUMN(), 4))} -> 1926 | B8: {=INDIRECT("USSR!" & ADDRESS(ROW(), COLUMN(), 4))} -> 17 дек | C8: {=INDIRECT("USSR!" & ADDRESS(ROW(), COLUMN(), 4))} -> 106845.82 | D8: {=INDIRECT("USSR!" & ADDRESS(ROW(), COLUMN(), 4))} -> 18044.897 | E8: {=INDIRECT("USSR!" & ADDRESS(ROW(), COLUMN(), 4))} -> 22616.293 | F8: {=INDIRECT("USSR!" & ADDRESS(ROW(), COLUMN(), 4))} -> 13225.577 | G8: ="минус " & TEXT(SUM(USSR!S8:'USSR'!U8),"#,##0") -> минус 7,932 | H8: =SUM(USSR!G8:'USSR'!Q8) -> 19631 | J8: =USSR!V8 -> 172431.64 | K8: =USSR!W8 -> 148530 | L8: =USSR!X8 -> 13.861515 | M8: =USSR!Y8 -> 23901.638
A9: {=INDIRECT("USSR!" & ADDRESS(ROW(), COLUMN(), 4))} -> 1937 | B9: {=INDIRECT("USSR!" & ADDRESS(ROW(), COLUMN(), 4))} -> 6 янв | C9: {=INDIRECT("USSR!" & ADDRESS(ROW(), COLUMN(), 4))} -> 130704.49 | D9: {=INDIRECT("USSR!" & ADDRESS(ROW(), COLUMN(), 4))} -> 22455.186 | E9: {=INDIRECT("USSR!" & ADDRESS(ROW(), COLUMN(), 4))} -> 27583.59 | F9: {=INDIRECT("USSR!" & ADDRESS(ROW(), COLUMN(), 4))} -> 16376.68 | G9: ="минус " & TEXT(SUM(USSR!S9:'USSR'!U9),"#,##0") -> минус 9,793 | H9: =SUM(USSR!G9:'USSR'!Q9) -> 22531 | J9: =USSR!V9 -> 209857.69 | K9: =USSR!W9 -> 162039 | L9: =USSR!X9 -> 22.786245 | M9: =USSR!Y9 -> 47818.688
A10: {=INDIRECT("USSR!" & ADDRESS(ROW(), COLUMN(), 4))} -> 1939 | B10: {=INDIRECT("USSR!" & ADDRESS(ROW(), COLUMN(), 4))} -> 17 янв | C10: {=INDIRECT("USSR!" & ADDRESS(ROW(), COLUMN(), 4))} -> 136512 | D10: {=INDIRECT("USSR!" & ADDRESS(ROW(), COLUMN(), 4))} -> 23536.67 | E10: {=INDIRECT("USSR!" & ADDRESS(ROW(), COLUMN(), 4))} -> 28791.326 | F10: {=INDIRECT("USSR!" & ADDRESS(ROW(), COLUMN(), 4))} -> 17142.391 | G10: ="минус " & TEXT(SUM(USSR!S10:'USSR'!U10),"#,##0") -> минус 10,247 | H10: =SUM(USSR!G10:'USSR'!Q10) -> 24644.418 | J10: =USSR!V10 -> 220379.53 | K10: =USSR!W10 -> 167650 | L10: =USSR!X10 -> 23.926691 | M10: =USSR!Y10 -> 52729.529
A11: {=INDIRECT("USSR!" & ADDRESS(ROW(), COLUMN(), 4))} -> 1959 | B11: {=INDIRECT("USSR!" & ADDRESS(ROW(), COLUMN(), 4))} -> 15 янв | C11: {=INDIRECT("USSR!" & ADDRESS(ROW(), COLUMN(), 4))} -> 220688.71 | D11: {=INDIRECT("USSR!" & ADDRESS(ROW(), COLUMN(), 4))} -> 39089.743 | E11: {=INDIRECT("USSR!" & ADDRESS(ROW(), COLUMN(), 4))} -> 49057.999 | F11: {=INDIRECT("USSR!" & ADDRESS(ROW(), COLUMN(), 4))} -> 29834.115 | H11: =SUM(USSR!G11:'USSR'!Q11) -> 38484.164 | I11: =USSR!R11 -> 6155 | J11: =USSR!V11 -> 383309.73 | K11: =USSR!W11 -> 208826.65 | L11: =USSR!X11 -> 45.520128 | M11: =USSR!Y11 -> 174483.08
A12: {=INDIRECT("USSR!" & ADDRESS(ROW(), COLUMN(), 4))} -> 1970 | B12: {=INDIRECT("USSR!" & ADDRESS(ROW(), COLUMN(), 4))} -> 15 янв | C12: {=INDIRECT("USSR!" & ADDRESS(ROW(), COLUMN(), 4))} -> 317618.53 | D12: {=INDIRECT("USSR!" & ADDRESS(ROW(), COLUMN(), 4))} -> 56622.04 | E12: {=INDIRECT("USSR!" & ADDRESS(ROW(), COLUMN(), 4))} -> 69527.974 | F12: {=INDIRECT("USSR!" & ADDRESS(ROW(), COLUMN(), 4))} -> 42596.3 | H12: =SUM(USSR!G12:'USSR'!Q12) -> 51943.3 | I12: =USSR!R12 -> 6964 | J12: =USSR!V12 -> 545272.14 | K12: =USSR!W12 -> 241720 | L12: =USSR!X12 -> 55.669842 | M12: =USSR!Y12 -> 303552.14
A13: {=INDIRECT("USSR!" & ADDRESS(ROW(), COLUMN(), 4))} -> 1979 | B13: {=INDIRECT("USSR!" & ADDRESS(ROW(), COLUMN(), 4))} -> 17 янв | C13: {=INDIRECT("USSR!" & ADDRESS(ROW(), COLUMN(), 4))} -> 445922.55 | D13: {=INDIRECT("USSR!" & ADDRESS(ROW(), COLUMN(), 4))} -> 79216.98 | E13: {=INDIRECT("USSR!" & ADDRESS(ROW(), COLUMN(), 4))} -> 90944.464 | F13: {=INDIRECT("USSR!" & ADDRESS(ROW(), COLUMN(), 4))} -> 55977.842 | H13: =SUM(USSR!G13:'USSR'!Q13) -> 61624 | I13: =USSR!R13 -> 7372 | J13: =USSR!V13 -> 741057.84 | K13: =USSR!W13 -> 262436 | L13: =USSR!X13 -> 64.5863 | M13: =USSR!Y13 -> 478621.84
A14: {=INDIRECT("USSR!" & ADDRESS(ROW(), COLUMN(), 4))} -> 1989 | B14: {=INDIRECT("USSR!" & ADDRESS(ROW(), COLUMN(), 4))} -> 12 янв | C14: {=INDIRECT("USSR!" & ADDRESS(ROW(), COLUMN(), 4))} -> 644973.97 | D14: {=INDIRECT("USSR!" & ADDRESS(ROW(), COLUMN(), 4))} -> 113563.48 | E14: {=INDIRECT("USSR!" & ADDRESS(ROW(), COLUMN(), 4))} -> 117667.83 | F14: {=INDIRECT("USSR!" & ADDRESS(ROW(), COLUMN(), 4))} -> 72712.743 | H14: =SUM(USSR!G14:'USSR'!Q14) -> 73087 | I14: =USSR!R14 -> 7839 | J14: =USSR!V14 -> 1029844 | K14: =USSR!W14 -> 286731 | L14: =USSR!X14 -> 72.157823 | M14: =USSR!Y14 -> 743113.03
A15: {=INDIRECT("USSR!" & ADDRESS(ROW(), COLUMN(), 4))} -> 2020 | B15: {=INDIRECT("USSR!" & ADDRESS(ROW(), COLUMN(), 4))} -> 1 янв | C15: {=INDIRECT("USSR!" & ADDRESS(ROW(), COLUMN(), 4))} -> 1405423.6 | D15: {=INDIRECT("USSR!" & ADDRESS(ROW(), COLUMN(), 4))} -> 240156.33 | E15: {=INDIRECT("USSR!" & ADDRESS(ROW(), COLUMN(), 4))} -> 188105.23 | F15: {=INDIRECT("USSR!" & ADDRESS(ROW(), COLUMN(), 4))} -> 117539.03 | I15: =USSR!R15 -> 6707.7018 | J15: =USSR!V15 -> 1957931.9 | K15: =USSR!W15 -> 198061 | L15: =USSR!X15 -> 89.884173 | M15: =USSR!Y15 -> 1759870.9
A16: {=INDIRECT("USSR!" & ADDRESS(ROW(), COLUMN(), 4))} -> 2030 | B16: {=INDIRECT("USSR!" & ADDRESS(ROW(), COLUMN(), 4))} -> 1 янв | C16: {=INDIRECT("USSR!" & ADDRESS(ROW(), COLUMN(), 4))} -> 1628910.2 | D16: {=INDIRECT("USSR!" & ADDRESS(ROW(), COLUMN(), 4))} -> 277227.89 | E16: {=INDIRECT("USSR!" & ADDRESS(ROW(), COLUMN(), 4))} -> 204656.37 | F16: {=INDIRECT("USSR!" & ADDRESS(ROW(), COLUMN(), 4))} -> 128368.08 | J16: =USSR!V16 -> 2239162.6
