Workbook
Name STEP: NR!$V$5
Name STEP_BR: BR!$V$5
Name STEP_NR: NR!$V$5
Name STEP_RSFSR: RSFSR!$V$5

Sheet Notes
A2: Датировка момента, на который следует относить начало демографического перехода,
A3: принимая за таковой 10%-е падение рождаемости.
A5: Чтобы исключить осцилляции, 10%-е падение определяется по тренду линейной регрессии методом наименьших квадратов.
A6: Но с подтверждением устойчивого снижения фактического уровня рождаемости.
B8: Такое потверждение достигается для Белоруссии и Малороссии.
B9: Для РСФСР и Новороссии до 1914 года 10%-го снижения рождаемости ещё не происходит, и для них момент начала перехода определяется по тренду.
A11: Стоял вопрос, не следует ли исключить из набора построения тренда
A12: холерные годы и 1905 год революционных потрясений как аномальные,
A13: однако видно, что их исключение мало влияет на тренд для Новроссии, Малороссии и Белоруссии:
B15: Малороссия: сдвиг почти нулевой, около +0.1 года
B16: Белоруссия: около +0.6 года
B17: Новороссия: около -0.3 года
A19: Для РСФСР исключение аномальных лет сдвигает пересечение 10%-го уровня заметнее — примерно с 1921.5 к 1918.4.
A21: Итого:
A23: Если определять начало демографического перехода как момент достижения 10%-го снижения рождаемости
A24: по сглаженному линейным трендом ряду, то наиболее раннее начало обнаруживается
B26: в Малороссии (ок. 1905–1906)
B27: и Белоруссии (ок. 1907-1908),
B28: тогда как в Новороссии оно относится лишь к 1917 г.,
B29: а в РСФСР — к поздним 1910-м или началу 1920-х годов.
B31: Для великорусского ядра 10%-е снижение рождаемости по линейному тренду достигается лишь в поздние 1910-е — начале 1920-х;
B32: точная дата заметно зависит от обращения с аномальными годами.

Sheet RSFSR
A1: РСФСР-1991 без Тувы
A3: год | B3: рождаемость | C3: TREND | D3: шаг тренда | S3: год | T3: % падения рождаемости | U3: % падения тренда | V3: шаг %-го падения тренда
A4: 1896 | B4: 52.9 | C4: {=TREND($B$4:$B$22,$A$4:$A$22,A4:A22)} -> 52.657368 | D4: =C4-C5 -> 0.2145614 | S4: 1896
A5: =A4+1 -> 1897 | B5: 52.8 | C5: 52.442807 | S5: =S4+1 -> 1897 | T5: =100 - 100 * B5/$B$4 -> 0.18903592 | U5: =100 - 100 * C5/$C$4 -> 0.40746701 | V5: =U6-U5 -> 0.40746701
A6: =A5+1 -> 1898 | B6: 50.6 | C6: 52.228246 | S6: =S5+1 -> 1898 | T6: =100 - 100 * B6/$B$4 -> 4.3478261 | U6: =100 - 100 * C6/$C$4 -> 0.81493402
A7: =A6+1 -> 1899 | B7: 51.2 | C7: 52.013684 | S7: =S6+1 -> 1899 | T7: =100 - 100 * B7/$B$4 -> 3.2136106 | U7: =100 - 100 * C7/$C$4 -> 1.222401
A8: =A7+1 -> 1900 | B8: 51.9 | C8: 51.799123 | S8: =S7+1 -> 1900 | T8: =100 - 100 * B8/$B$4 -> 1.8903592 | U8: =100 - 100 * C8/$C$4 -> 1.629868
A9: =A8+1 -> 1901 | B9: 51.5 | C9: 51.584561 | S9: =S8+1 -> 1901 | T9: =100 - 100 * B9/$B$4 -> 2.6465028 | U9: =100 - 100 * C9/$C$4 -> 2.037335
A10: =A9+1 -> 1902 | B10: 52.4 | C10: 51.37 | S10: =S9+1 -> 1902 | T10: =100 - 100 * B10/$B$4 -> 0.94517958 | U10: =100 - 100 * C10/$C$4 -> 2.444802
A11: =A10+1 -> 1903 | B11: 52 | C11: 51.155439 | S11: =S10+1 -> 1903 | T11: =100 - 100 * B11/$B$4 -> 1.7013233 | U11: =100 - 100 * C11/$C$4 -> 2.8522691
A12: =A11+1 -> 1904 | B12: 52.2 | C12: 50.940877 | S12: =S11+1 -> 1904 | T12: =100 - 100 * B12/$B$4 -> 1.3232514 | U12: =100 - 100 * C12/$C$4 -> 3.2597361
A13: =A12+1 -> 1905 | B13: 48.6 | C13: 50.726316 | S13: =S12+1 -> 1905 | T13: =100 - 100 * B13/$B$4 -> 8.1285444 | U13: =100 - 100 * C13/$C$4 -> 3.6672031
A14: =A13+1 -> 1906 | B14: 51.1 | C14: 50.511754 | S14: =S13+1 -> 1906 | T14: =100 - 100 * B14/$B$4 -> 3.4026465 | U14: =100 - 100 * C14/$C$4 -> 4.0746701
A15: =A14+1 -> 1907 | B15: 51.1 | C15: 50.297193 | S15: =S14+1 -> 1907 | T15: =100 - 100 * B15/$B$4 -> 3.4026465 | U15: =100 - 100 * C15/$C$4 -> 4.4821371
A16: =A15+1 -> 1908 | B16: 49.5 | C16: 50.082632 | S16: =S15+1 -> 1908 | T16: =100 - 100 * B16/$B$4 -> 6.4272212 | U16: =100 - 100 * C16/$C$4 -> 4.8896041
A17: =A16+1 -> 1909 | B17: 49.9 | C17: 49.86807 | S17: =S16+1 -> 1909 | T17: =100 - 100 * B17/$B$4 -> 5.6710775 | U17: =100 - 100 * C17/$C$4 -> 5.2970711
... A21: =A20+1 -> 1913 | B21: 48.4 | C21: 49.009825 | S21: =S20+1 -> 1913 | T21: =100 - 100 * B21/$B$4 -> 8.5066163 | U21: =100 - 100 * C21/$C$4 -> 6.9269391
A22: 1914 | B22: 48 | C22: 48.795263 | S22: 1914 | T22: =100 - 100 * B22/$B$4 -> 9.2627599 | U22: =100 - 100 * C22/$C$4 -> 7.3344061
A23: =A22+1 -> 1915 | C23: =C22-$D$4 -> 48.580702 | S23: =S22+1 -> 1915 | U23: =U22+STEP -> 7.7856853
A24: =A23+1 -> 1916 | C24: =C23-$D$4 -> 48.36614 | S24: =S23+1 -> 1916 | U24: =U23+STEP -> 8.2369645
A25: =A24+1 -> 1917 | C25: =C24-$D$4 -> 48.151579 | S25: =S24+1 -> 1917 | U25: =U24+STEP -> 8.6882437
A26: =A25+1 -> 1918 | C26: =C25-$D$4 -> 47.937018 | S26: =S25+1 -> 1918 | U26: =U25+STEP -> 9.139523
A27: =A26+1 -> 1919 | C27: =C26-$D$4 -> 47.722456 | S27: =S26+1 -> 1919 | U27: =U26+STEP -> 9.5908022
A28: =A27+1 -> 1920 | C28: =C27-$D$4 -> 47.507895 | S28: =S27+1 -> 1920 | U28: =U27+STEP -> 10.042081
A29: =A28+1 -> 1921 | C29: =C28-$D$4 -> 47.293333 | S29: =S28+1 -> 1921 | U29: =U28+STEP -> 10.493361
S30: =S29+1 -> 1922 | U30: =U29+STEP -> 10.94464
S31: =S30+1 -> 1923 | U31: =U30+STEP -> 11.395919
S32: =S31+1 -> 1924 | U32: =U31+STEP -> 11.847198
S33: =S32+1 -> 1925 | U33: =U32+STEP -> 12.298477
S34: =S33+1 -> 1926 | U34: =U33+STEP -> 12.749757
S35: =S34+1 -> 1927 | U35: =U34+STEP -> 13.201036
A39: Исключение холерных и революционных лет (1898, 1905, 1908-1910)
A41: год | B41: рождаемость
A42: 1896 | B42: 53.3
A43: =A42+1 -> 1897 | B43: 53.3
A44: =A43+1 -> 1898
A45: =A44+1 -> 1899 | B45: 51.7
A46: =A45+1 -> 1900 | B46: 52.4
A47: =A46+1 -> 1901 | B47: 52
A48: =A47+1 -> 1902 | B48: 52.8
...

Sheet NR
A1: Новороссия
A3: год | B3: рождаемость | C3: TREND | D3: шаг тренда | S3: год | T3: % падения рождаемости | U3: % падения тренда | V3: шаг %-го падения тренда
A4: 1896 | B4: 51.5 | C4: {=TREND($B$4:$B$21,$A$4:$A$21,A4:A21)} -> 50.538596 | D4: =C4-C5 -> 0.22807018 | S4: 1896
A5: =A4+1 -> 1897 | B5: 50.9 | C5: 50.310526 | S5: =S4+1 -> 1897 | T5: =100 - 100 * B5/$B$4 -> 1.1650485 | U5: =100 - 100 * C5/$C$4 -> 0.4512792 | V5: =U6-U5 -> 0.4512792
A6: =A5+1 -> 1898 | B6: 49.9 | C6: 50.082456 | S6: =S5+1 -> 1898 | T6: =100 - 100 * B6/$B$4 -> 3.1067961 | U6: =100 - 100 * C6/$C$4 -> 0.90255841
A7: =A6+1 -> 1899 | B7: 50.6 | C7: 49.854386 | S7: =S6+1 -> 1899 | T7: =100 - 100 * B7/$B$4 -> 1.7475728 | U7: =100 - 100 * C7/$C$4 -> 1.3538376
A8: =A7+1 -> 1900 | B8: 49.8 | C8: 49.626316 | S8: =S7+1 -> 1900 | T8: =100 - 100 * B8/$B$4 -> 3.3009709 | U8: =100 - 100 * C8/$C$4 -> 1.8051168
A9: =A8+1 -> 1901 | B9: 46.3 | C9: 49.398246 | S9: =S8+1 -> 1901 | T9: =100 - 100 * B9/$B$4 -> 10.097087 | U9: =100 - 100 * C9/$C$4 -> 2.256396
A10: =A9+1 -> 1902 | B10: 49.9 | C10: 49.170175 | S10: =S9+1 -> 1902 | T10: =100 - 100 * B10/$B$4 -> 3.1067961 | U10: =100 - 100 * C10/$C$4 -> 2.7076752
A11: =A10+1 -> 1903 | B11: 49.5 | C11: 48.942105 | S11: =S10+1 -> 1903 | T11: =100 - 100 * B11/$B$4 -> 3.8834951 | U11: =100 - 100 * C11/$C$4 -> 3.1589544
A12: =A11+1 -> 1904 | B12: 49.6 | C12: 48.714035 | S12: =S11+1 -> 1904 | T12: =100 - 100 * B12/$B$4 -> 3.6893204 | U12: =100 - 100 * C12/$C$4 -> 3.6102336
A13: =A12+1 -> 1905 | B13: 45.6 | C13: 48.485965 | S13: =S12+1 -> 1905 | T13: =100 - 100 * B13/$B$4 -> 11.456311 | U13: =100 - 100 * C13/$C$4 -> 4.0615128
A14: =A13+1 -> 1906 | B14: 46.6 | C14: 48.257895 | S14: =S13+1 -> 1906 | T14: =100 - 100 * B14/$B$4 -> 9.5145631 | U14: =100 - 100 * C14/$C$4 -> 4.512792
A15: =A14+1 -> 1907 | B15: 49.8 | C15: 48.029825 | S15: =S14+1 -> 1907 | T15: =100 - 100 * B15/$B$4 -> 3.3009709 | U15: =100 - 100 * C15/$C$4 -> 4.9640712
A16: =A15+1 -> 1908 | B16: 47.2 | C16: 47.801754 | S16: =S15+1 -> 1908 | T16: =100 - 100 * B16/$B$4 -> 8.3495146 | U16: =100 - 100 * C16/$C$4 -> 5.4153504
A17: =A16+1 -> 1909 | B17: 48.5 | C17: 47.573684 | S17: =S16+1 -> 1909 | T17: =100 - 100 * B17/$B$4 -> 5.8252427 | U17: =100 - 100 * C17/$C$4 -> 5.8666296
... A21: =A20+1 -> 1913 | B21: 46.1 | C21: 46.661404 | S21: =S20+1 -> 1913 | T21: =100 - 100 * B21/$B$4 -> 10.485437 | U21: =100 - 100 * C21/$C$4 -> 7.6717465
A22: =A21+1 -> 1914 | B22: 44.2 | C22: =C21-$D$4 -> 46.433333 | S22: 1914 | U22: =U21+STEP_NR -> 8.1230257
A23: =A22+1 -> 1915 | C23: =C22-$D$4 -> 46.205263 | S23: 1915 | U23: =U22+STEP_NR -> 8.5743049
A24: =A23+1 -> 1916 | C24: =C23-$D$4 -> 45.977193 | S24: 1916 | U24: =U23+STEP_NR -> 9.0255841
A25: =A24+1 -> 1917 | C25: =C24-$D$4 -> 45.749123 | S25: 1917 | U25: =U24+STEP_NR -> 9.4768633
A26: =A25+1 -> 1918 | C26: =C25-$D$4 -> 45.521053
A28: Исключение холерных и революционных лет (1898, 1905, 1908-1910)
A31: год | B31: рождаемость
A32: 1896 | B32: 52.1
A33: =A32+1 -> 1897 | B33: 51.5
A34: =A33+1 -> 1898
A35: =A34+1 -> 1899 | B35: 51.2
A36: =A35+1 -> 1900 | B36: 50.4
A37: =A36+1 -> 1901 | B37: 46.8
A38: =A37+1 -> 1902 | B38: 50.4
A39: =A38+1 -> 1903 | B39: 50.1
A40: =A39+1 -> 1904 | B40: 50.1
A41: =A40+1 -> 1905
A42: =A41+1 -> 1906 | B42: 46.9
A43: =A42+1 -> 1907 | B43: 50.2
A44: =A43+1 -> 1908
A45: =A44+1 -> 1909
A46: =A45+1 -> 1910
A47: =A46+1 -> 1911 | B47: 48.2
...

Sheet MR
A1: Малороссия
A3: год | B3: рождаемость | C3: TREND | D3: шаг тренда | S3: год | T3: % падения рождаемости | U3: % падения тренда | V3: шаг %-го падения тренда
A4: 1896 | B4: 48.6 | C4: {=TREND($B$4:$B$21,$A$4:$A$21,A4:A21)} -> 48.038596 | D4: =C4-C5 -> 0.50454076 | S4: 1896
A5: =A4+1 -> 1897 | B5: 48 | C5: 47.534056 | S5: =S4+1 -> 1897 | T5: =100 - 100 * B5/$B$4 -> 1.2345679 | U5: =100 - 100 * C5/$C$4 -> 1.0502821 | V5: =U6-U5 -> 1.0502821
A6: =A5+1 -> 1898 | B6: 45.8 | C6: 47.029515 | S6: =S5+1 -> 1898 | T6: =100 - 100 * B6/$B$4 -> 5.7613169 | U6: =100 - 100 * C6/$C$4 -> 2.1005641
A7: =A6+1 -> 1899 | B7: 47.2 | C7: 46.524974 | S7: =S6+1 -> 1899 | T7: =100 - 100 * B7/$B$4 -> 2.8806584 | U7: =100 - 100 * C7/$C$4 -> 3.1508462
A8: =A7+1 -> 1900 | B8: 47.5 | C8: 46.020433 | S8: =S7+1 -> 1900 | T8: =100 - 100 * B8/$B$4 -> 2.2633745 | U8: =100 - 100 * C8/$C$4 -> 4.2011283
A9: =A8+1 -> 1901 | B9: 43.6 | C9: 45.515893 | S9: =S8+1 -> 1901 | T9: =100 - 100 * B9/$B$4 -> 10.288066 | U9: =100 - 100 * C9/$C$4 -> 5.2514103
A10: =A9+1 -> 1902 | B10: 45.5 | C10: 45.011352 | S10: =S9+1 -> 1902 | T10: =100 - 100 * B10/$B$4 -> 6.3786008 | U10: =100 - 100 * C10/$C$4 -> 6.3016924
A11: =A10+1 -> 1903 | B11: 44.5 | C11: 44.506811 | S11: =S10+1 -> 1903 | T11: =100 - 100 * B11/$B$4 -> 8.436214 | U11: =100 - 100 * C11/$C$4 -> 7.3519745
A12: =A11+1 -> 1904 | B12: 43.8 | C12: 44.00227 | S12: =S11+1 -> 1904 | T12: =100 - 100 * B12/$B$4 -> 9.8765432 | U12: =100 - 100 * C12/$C$4 -> 8.4022565
A13: =A12+1 -> 1905 | B13: 41.2 | C13: 43.49773 | S13: =S12+1 -> 1905 | T13: =100 - 100 * B13/$B$4 -> 15.226337 | U13: =100 - 100 * C13/$C$4 -> 9.4525386
A14: =A13+1 -> 1906 | B14: 43 | C14: 42.993189 | S14: =S13+1 -> 1906 | T14: =100 - 100 * B14/$B$4 -> 11.522634 | U14: =100 - 100 * C14/$C$4 -> 10.502821
A15: =A14+1 -> 1907 | B15: 44.3 | C15: 42.488648 | S15: =S14+1 -> 1907 | T15: =100 - 100 * B15/$B$4 -> 8.8477366 | U15: =100 - 100 * C15/$C$4 -> 11.553103
A16: =A15+1 -> 1908 | B16: 42 | C16: 41.984107 | S16: =S15+1 -> 1908 | T16: =100 - 100 * B16/$B$4 -> 13.580247 | U16: =100 - 100 * C16/$C$4 -> 12.603385
A17: =A16+1 -> 1909 | B17: 41 | C17: 41.479567 | S17: =S16+1 -> 1909 | T17: =100 - 100 * B17/$B$4 -> 15.63786 | U17: =100 - 100 * C17/$C$4 -> 13.653667
... A21: =A20+1 -> 1913 | B21: 38.6 | C21: 39.461404 | S21: =S20+1 -> 1913 | T21: =100 - 100 * B21/$B$4 -> 20.576132 | U21: =100 - 100 * C21/$C$4 -> 17.854795
A22: =A21+1 -> 1914 | C22: =C21-$D$4 -> 38.956863
A23: =A22+1 -> 1915 | C23: =C22-$D$4 -> 38.452322
A24: =A23+1 -> 1916 | C24: =C23-$D$4 -> 37.947781
A25: =A24+1 -> 1917 | C25: =C24-$D$4 -> 37.44324
A27: Исключение холерных и революционных лет (1898, 1905, 1908-1910)
A30: год | B30: рождаемость
A31: 1896 | B31: 48.9
A32: =A31+1 -> 1897 | B32: 48.4
A33: =A32+1 -> 1898
A34: =A33+1 -> 1899 | B34: 47.6
A35: =A34+1 -> 1900 | B35: 47.9
A36: =A35+1 -> 1901 | B36: 44
A37: =A36+1 -> 1902 | B37: 46
A38: =A37+1 -> 1903 | B38: 44.9
A39: =A38+1 -> 1904 | B39: 44.2
A40: =A39+1 -> 1905
A41: =A40+1 -> 1906 | B41: 43.3
A42: =A41+1 -> 1907 | B42: 44.6
A43: =A42+1 -> 1908
A44: =A43+1 -> 1909
A45: =A44+1 -> 1910
A46: =A45+1 -> 1911 | B46: 41.4
A47: =A46+1 -> 1912 | B47: 41.5
...

Sheet BR
A1: Белоруссия со Смоленской губернией
A3: год | B3: рождаемость | C3: TREND | D3: шаг тренда | S3: год | T3: % падения рождаемости | U3: % падения тренда | V3: шаг %-го падения тренда
A4: 1896 | B4: 46.2 | C4: {=TREND($B$4:$B$21,$A$4:$A$21,A4:A21)} -> 47.476608 | D4: =C4-C5 -> 0.43384933 | S4: 1896
A5: =A4+1 -> 1897 | B5: 46.6 | C5: 47.042759 | S5: =S4+1 -> 1897 | T5: =100 - 100 * B5/$B$4 -> -0.86580087 | U5: =100 - 100 * C5/$C$4 -> 0.91381703 | V5: =U6-U5 -> 0.91381703
A6: =A5+1 -> 1898 | B6: 45.5 | C6: 46.60891 | S6: =S5+1 -> 1898 | T6: =100 - 100 * B6/$B$4 -> 1.5151515 | U6: =100 - 100 * C6/$C$4 -> 1.8276341
A7: =A6+1 -> 1899 | B7: 46.3 | C7: 46.17506 | S7: =S6+1 -> 1899 | T7: =100 - 100 * B7/$B$4 -> -0.21645022 | U7: =100 - 100 * C7/$C$4 -> 2.7414511
A8: =A7+1 -> 1900 | B8: 47.3 | C8: 45.741211 | S8: =S7+1 -> 1900 | T8: =100 - 100 * B8/$B$4 -> -2.3809524 | U8: =100 - 100 * C8/$C$4 -> 3.6552681
A9: =A8+1 -> 1901 | B9: 45.4 | C9: 45.307362 | S9: =S8+1 -> 1901 | T9: =100 - 100 * B9/$B$4 -> 1.7316017 | U9: =100 - 100 * C9/$C$4 -> 4.5690851
A10: =A9+1 -> 1902 | B10: 48.5 | C10: 44.873512 | S10: =S9+1 -> 1902 | T10: =100 - 100 * B10/$B$4 -> -4.978355 | U10: =100 - 100 * C10/$C$4 -> 5.4829022
A11: =A10+1 -> 1903 | B11: 43.2 | C11: 44.439663 | S11: =S10+1 -> 1903 | T11: =100 - 100 * B11/$B$4 -> 6.4935065 | U11: =100 - 100 * C11/$C$4 -> 6.3967192
A12: =A11+1 -> 1904 | B12: 44.9 | C12: 44.005814 | S12: =S11+1 -> 1904 | T12: =100 - 100 * B12/$B$4 -> 2.8138528 | U12: =100 - 100 * C12/$C$4 -> 7.3105362
A13: =A12+1 -> 1905 | B13: 41.6 | C13: 43.571964 | S13: =S12+1 -> 1905 | T13: =100 - 100 * B13/$B$4 -> 9.95671 | U13: =100 - 100 * C13/$C$4 -> 8.2243532
A14: =A13+1 -> 1906 | B14: 43.5 | C14: 43.138115 | S14: =S13+1 -> 1906 | T14: =100 - 100 * B14/$B$4 -> 5.8441558 | U14: =100 - 100 * C14/$C$4 -> 9.1381703
A15: =A14+1 -> 1907 | B15: 44.4 | C15: 42.704266 | S15: =S14+1 -> 1907 | T15: =100 - 100 * B15/$B$4 -> 3.8961039 | U15: =100 - 100 * C15/$C$4 -> 10.051987
A16: =A15+1 -> 1908 | B16: 41 | C16: 42.270416 | S16: =S15+1 -> 1908 | T16: =100 - 100 * B16/$B$4 -> 11.255411 | U16: =100 - 100 * C16/$C$4 -> 10.965804
A17: =A16+1 -> 1909 | B17: 41.3 | C17: 41.836567 | S17: =S16+1 -> 1909 | T17: =100 - 100 * B17/$B$4 -> 10.606061 | U17: =100 - 100 * C17/$C$4 -> 11.879621
... A21: =A20+1 -> 1913 | B21: 40.2 | C21: 40.10117 | S21: =S20+1 -> 1913 | T21: =100 - 100 * B21/$B$4 -> 12.987013 | U21: =100 - 100 * C21/$C$4 -> 15.534889
A22: =A21+1 -> 1914 | C22: =C21-$D$4 -> 39.66732
A23: =A22+1 -> 1915 | C23: =C22-$D$4 -> 39.233471
A24: =A23+1 -> 1916 | C24: =C23-$D$4 -> 38.799622
A25: =A24+1 -> 1917 | C25: =C24-$D$4 -> 38.365772
A29: Исключение холерных и революционных лет (1898, 1905, 1908-1910)
A31: год | B31: рождаемость
A32: 1896 | B32: 46.5
A33: =A32+1 -> 1897 | B33: 46.9
A34: =A33+1 -> 1898
A35: =A34+1 -> 1899 | B35: 46.7
A36: =A35+1 -> 1900 | B36: 47.7
A37: =A36+1 -> 1901 | B37: 45.7
A38: =A37+1 -> 1902 | B38: 48.9
A39: =A38+1 -> 1903 | B39: 43.4
A40: =A39+1 -> 1904 | B40: 45.3
A41: =A40+1 -> 1905
A42: =A41+1 -> 1906 | B42: 43.8
A43: =A42+1 -> 1907 | B43: 44.6
A44: =A43+1 -> 1908
A45: =A44+1 -> 1909
A46: =A45+1 -> 1910
A47: =A46+1 -> 1911 | B47: 41.2
A48: =A47+1 -> 1912 | B48: 40.8
...

Sheet BR без Смоленской
A1: Белоруссия без Смоленской губернии
A3: год | B3: рождаемость | C3: TREND | D3: шаг тренда | S3: год | T3: % падения рождаемости | U3: % падения тренда | V3: шаг %-го падения тренда
A4: 1896 | B4: 44.8 | C4: {=TREND($B$4:$B$21,$A$4:$A$21,A4:A21)} -> 45.78538 | D4: =C4-C5 -> 0.44272446 | S4: 1896
A5: =A4+1 -> 1897 | B5: 44.8 | C5: 45.342656 | S5: =S4+1 -> 1897 | T5: =100 - 100 * B5/$B$4 -> 0 | U5: =100 - 100 * C5/$C$4 -> 0.96695595 | V5: =U6-U5 -> 0.96695595
A6: =A5+1 -> 1898 | B6: 43.7 | C6: 44.899931 | S6: =S5+1 -> 1898 | T6: =100 - 100 * B6/$B$4 -> 2.4553571 | U6: =100 - 100 * C6/$C$4 -> 1.9339119
A7: =A6+1 -> 1899 | B7: 44.6 | C7: 44.457207 | S7: =S6+1 -> 1899 | T7: =100 - 100 * B7/$B$4 -> 0.44642857 | U7: =100 - 100 * C7/$C$4 -> 2.9008679
A8: =A7+1 -> 1900 | B8: 45.8 | C8: 44.014482 | S8: =S7+1 -> 1900 | T8: =100 - 100 * B8/$B$4 -> -2.2321429 | U8: =100 - 100 * C8/$C$4 -> 3.8678238
A9: =A8+1 -> 1901 | B9: 43.7 | C9: 43.571758 | S9: =S8+1 -> 1901 | T9: =100 - 100 * B9/$B$4 -> 2.4553571 | U9: =100 - 100 * C9/$C$4 -> 4.8347798
A10: =A9+1 -> 1902 | B10: 46.3 | C10: 43.129033 | S10: =S9+1 -> 1902 | T10: =100 - 100 * B10/$B$4 -> -3.3482143 | U10: =100 - 100 * C10/$C$4 -> 5.8017357
A11: =A10+1 -> 1903 | B11: 41.6 | C11: 42.686309 | S11: =S10+1 -> 1903 | T11: =100 - 100 * B11/$B$4 -> 7.1428571 | U11: =100 - 100 * C11/$C$4 -> 6.7686917
A12: =A11+1 -> 1904 | B12: 42.6 | C12: 42.243584 | S12: =S11+1 -> 1904 | T12: =100 - 100 * B12/$B$4 -> 4.9107143 | U12: =100 - 100 * C12/$C$4 -> 7.7356476
A13: =A12+1 -> 1905 | B13: 40.2 | C13: 41.80086 | S13: =S12+1 -> 1905 | T13: =100 - 100 * B13/$B$4 -> 10.267857 | U13: =100 - 100 * C13/$C$4 -> 8.7026036
A14: =A13+1 -> 1906 | B14: 41.2 | C14: 41.358136 | S14: =S13+1 -> 1906 | T14: =100 - 100 * B14/$B$4 -> 8.0357143 | U14: =100 - 100 * C14/$C$4 -> 9.6695595
A15: =A14+1 -> 1907 | B15: 42.6 | C15: 40.915411 | S15: =S14+1 -> 1907 | T15: =100 - 100 * B15/$B$4 -> 4.9107143 | U15: =100 - 100 * C15/$C$4 -> 10.636515
A16: =A15+1 -> 1908 | B16: 39.6 | C16: 40.472687 | S16: =S15+1 -> 1908 | T16: =100 - 100 * B16/$B$4 -> 11.607143 | U16: =100 - 100 * C16/$C$4 -> 11.603471
A17: =A16+1 -> 1909 | B17: 39.7 | C17: 40.029962 | S17: =S16+1 -> 1909 | T17: =100 - 100 * B17/$B$4 -> 11.383929 | U17: =100 - 100 * C17/$C$4 -> 12.570427
... A21: =A20+1 -> 1913 | B21: 38.1 | C21: 38.259064 | S21: =S20+1 -> 1913 | T21: =100 - 100 * B21/$B$4 -> 14.955357 | U21: =100 - 100 * C21/$C$4 -> 16.438251
A22: =A21+1 -> 1914 | C22: =C21-$D$4 -> 37.81634
A23: =A22+1 -> 1915 | C23: =C22-$D$4 -> 37.373615
A24: =A23+1 -> 1916 | C24: =C23-$D$4 -> 36.930891
A25: =A24+1 -> 1917 | C25: =C24-$D$4 -> 36.488166
A29: Исключение холерных и революционных лет (1898, 1905, 1908-1910)
A31: год | B31: рождаемость
A32: 1896 | B32: 45.1
A33: =A32+1 -> 1897 | B33: 45.1
A34: =A33+1 -> 1898
A35: =A34+1 -> 1899 | B35: 45
A36: =A35+1 -> 1900 | B36: 46.1
A37: =A36+1 -> 1901 | B37: 44
A38: =A37+1 -> 1902 | B38: 46.8
A39: =A38+1 -> 1903 | B39: 41.8
A40: =A39+1 -> 1904 | B40: 43
A41: =A40+1 -> 1905
A42: =A41+1 -> 1906 | B42: 41.5
A43: =A42+1 -> 1907 | B43: 42.8
A44: =A43+1 -> 1908
A45: =A44+1 -> 1909
A46: =A45+1 -> 1910
A47: =A46+1 -> 1911 | B47: 39.3
A48: =A47+1 -> 1912 | B48: 39.2
...

Sheet все вместе
A3: год | B3: РСФСР-1991 | C3: Новороссия | D3: Малороссия | E3: Белоруссия | F3: Белоруссия без Смоленской
A4: 1896 | B4: =RSFSR!B4 -> 52.9 | C4: =NR!B4 -> 51.5 | D4: =MR!B4 -> 48.6 | E4: =F4 -> 44.8 | F4: ='BR без Смоленской'!B4 -> 44.8
A5: =A4+1 -> 1897 | B5: =RSFSR!B5 -> 52.8 | C5: =NR!B5 -> 50.9 | D5: =MR!B5 -> 48 | E5: =BR!B5 -> 46.6 | F5: ='BR без Смоленской'!B5 -> 44.8
A6: =A5+1 -> 1898 | B6: =RSFSR!B6 -> 50.6 | C6: =NR!B6 -> 49.9 | D6: =MR!B6 -> 45.8 | E6: =BR!B6 -> 45.5 | F6: ='BR без Смоленской'!B6 -> 43.7
A7: =A6+1 -> 1899 | B7: =RSFSR!B7 -> 51.2 | C7: =NR!B7 -> 50.6 | D7: =MR!B7 -> 47.2 | E7: =BR!B7 -> 46.3 | F7: ='BR без Смоленской'!B7 -> 44.6
A8: =A7+1 -> 1900 | B8: =RSFSR!B8 -> 51.9 | C8: =NR!B8 -> 49.8 | D8: =MR!B8 -> 47.5 | E8: =BR!B8 -> 47.3 | F8: ='BR без Смоленской'!B8 -> 45.8
A9: =A8+1 -> 1901 | B9: =RSFSR!B9 -> 51.5 | C9: =NR!B9 -> 46.3 | D9: =MR!B9 -> 43.6 | E9: =BR!B9 -> 45.4 | F9: ='BR без Смоленской'!B9 -> 43.7
A10: =A9+1 -> 1902 | B10: =RSFSR!B10 -> 52.4 | C10: =NR!B10 -> 49.9 | D10: =MR!B10 -> 45.5 | E10: =BR!B10 -> 48.5 | F10: ='BR без Смоленской'!B10 -> 46.3
A11: =A10+1 -> 1903 | B11: =RSFSR!B11 -> 52 | C11: =NR!B11 -> 49.5 | D11: =MR!B11 -> 44.5 | E11: =BR!B11 -> 43.2 | F11: ='BR без Смоленской'!B11 -> 41.6
A12: =A11+1 -> 1904 | B12: =RSFSR!B12 -> 52.2 | C12: =NR!B12 -> 49.6 | D12: =MR!B12 -> 43.8 | E12: =BR!B12 -> 44.9 | F12: ='BR без Смоленской'!B12 -> 42.6
A13: =A12+1 -> 1905 | B13: =RSFSR!B13 -> 48.6 | C13: =NR!B13 -> 45.6 | D13: =MR!B13 -> 41.2 | E13: =BR!B13 -> 41.6 | F13: ='BR без Смоленской'!B13 -> 40.2
A14: =A13+1 -> 1906 | B14: =RSFSR!B14 -> 51.1 | C14: =NR!B14 -> 46.6 | D14: =MR!B14 -> 43 | E14: =BR!B14 -> 43.5 | F14: ='BR без Смоленской'!B14 -> 41.2
A15: =A14+1 -> 1907 | B15: =RSFSR!B15 -> 51.1 | C15: =NR!B15 -> 49.8 | D15: =MR!B15 -> 44.3 | E15: =BR!B15 -> 44.4 | F15: ='BR без Смоленской'!B15 -> 42.6
A16: =A15+1 -> 1908 | B16: =RSFSR!B16 -> 49.5 | C16: =NR!B16 -> 47.2 | D16: =MR!B16 -> 42 | E16: =BR!B16 -> 41 | F16: ='BR без Смоленской'!B16 -> 39.6
... A21: =A20+1 -> 1913 | B21: =RSFSR!B21 -> 48.4 | C21: =NR!B21 -> 46.1 | D21: =MR!B21 -> 38.6 | E21: =BR!B21 -> 40.2 | F21: ='BR без Смоленской'!B21 -> 38.1
A22: 1914 | B22: =RSFSR!B22 -> 48 | C22: =NR!B22 -> 44.2
