Workbook

Sheet Notes
A1: SALA 2002
A2: Источник:
A3: Statistical Abstract of Latin America (vol 38, 2002), UCLA Latin America Center Publications, стр. 150-159
A5: Значения даны на середину календарного года
B7: Для Колумбии стоит два примечания: (а) на середину года и (б) на 24 октября календарного года.
B8: Это примечание является редакционной нестыковкой.
B9: 24 октября действительно является днём переписи Колумбии 1973 года; но это не универсальная дата всех колумбийских переписей:
B10: IPUMS указывает для Колумбии 1964 день переписи 15 июля, для 1973 — 24 октября, для 1985 — 15 октября.
B11: Оговорка про 24 октября, вероятно, унаследована от переписно-оценочных источников или от одной из колумбийских дат переписи,
B12: но в SALA 2002 она поставлена слишком широко.
B14: На пракитике следует считать ряд Колумбии mid-year series, как остальные страны.
B15: Сама таблица надёжно не объясняет статуса, а поздние сегменты SALA 2002 идут из IMF/UN-источников;
B16: UN Demographic Yearbook, в свою очередь, стандартно публикует mid-year estimates в соответствующих таблицах.
B18: Эффект сдвига в любом случае мал: 24 октября примерно на 115 дней позже 1 июля, то есть на 0.315 года.
B19: При росте 2–3% в год это даёт разницу порядка 0.6–1.0%.
B20: Для грубой демографической склейки это меньше многих межисточниковых расхождений SALA.
A22: Для Бразилии и Венецуэллы данные не включают туземное население в удалённых областях
A24: Для Эквадора данные не включают кочевое туземное население.
A26: Для Гватемалы, Перу и Уругвая данные выправлены на недоучёт.
A28: Исторические данные за 1900-1950 приведены по
A29: Statistical Abstract of Latin America, Supplement 3 (1974) "Statistics and National Policy", UCLA Latin American Center, стр. 173-187
A30: где они даны с дополнительным десятичным знаком
A31: далее по UN Demographic Yearbook, отдельные годы по UN Population Division и МВФ
A33: Исправленные опечаткт помечены синим фоном
A35: SALA 1974
A36: Источник:
A37: Statistical Abstract ofLatin America, Supplement 3 (1974) "Statistics and National Policy", UCLA Latin American Center, стр. 173-187
A38: Исправлена опечатка Парагвай 1966
... A43: Statistical Abstract ofLatin America, Supplement 3 (1974) "Statistics and National Policy", UCLA Latin American Center, стр. 186
B45: Источники:
B46: O. Andrew Collver, Birth Rates in Latin America: New Estimates of Historical Trends and Fluctuations, passim
B47: Nicolas Sanchez-Albornoz, The Population of Latin America, pp. 169 and 184 - data since 1930 are quoted from Centro Latinoamericano de Demograffa (CELADE), Boletfn Demografico V:10 (1972), pp. 4-5
B48: United Nations, World Population Prospects as Assessed in 1963 (New York: Department of Economic and Social Affairs, 1966), pp. 143-144
A50: WPP 2024 начало года
A51: WPP 2024 середина года
B53: Численность населения по UN WPP 2024
A55: SALA WPP 2024 199x
A56: Склейка данных из SALA 1974/SALA 2002 c данными "WPP 2024 середина года" c соединением в 1995-2000
A58: SALA WPP 2024 195x
A59: Склейка данных из SALA 1974 c данными "WPP 2024 середина года" c соединением в 1950-1960
...

Sheet SALA 1974
A1: год | B1: Аргентина | C1: Боливия | D1: Бразилия | E1: Чили | F1: Колумбия | G1: Коста-Рика | H1: Куба | I1: Доминиканская республика | J1: Эквадор | K1: Эль-Сальвадор | L1: Гватемала | M1: Гаити | N1: Гондурас | O1: Мексика | P1: Никарагуа | Q1: Панама | R1: Парагвай | S1: Перу | T1: Уругвай | U1: Венецуэлла
A2: 1900 | B2: 4607 | C2: 1766 | D2: 17984 | E2: 2959 | F2: 3894 | G2: 307 | H2: 1600 | I2: 600 | J2: 1300 | K2: 801 | L2: 885 | M2: 1250 | N2: 420 | O2: 13607 | P2: 420 | Q2: 263 | R2: 490 | S2: 3000 | T2: 963 | U2: 2445
A3: =A2+1 -> 1901 | B3: 4741 | C3: 1785 | D3: 18392 | E3: 2994 | F3: 3944 | G3: 313 | H3: 1679 | I3: 614 | J3: 1312 | K3: 819 | L3: 910 | M3: 1294 | N3: 436 | O3: 13755 | P3: 434 | Q3: 270 | R3: 506 | S3: 3100 | T3: 965 | U3: 2451
A4: =A3+1 -> 1902 | B4: 4872 | C4: 1803 | D4: 18782 | E4: 3030 | F4: 3994 | G4: 318 | H4: 1758 | I4: 628 | J4: 1324 | K4: 838 | L4: 936 | M4: 1338 | N4: 452 | O4: 13905 | P4: 448 | Q4: 276 | R4: 522 | S4: 3200 | T4: 990 | U4: 2458
A5: =A4+1 -> 1903 | B5: 4976 | C5: 1822 | D5: 19180 | E5: 3066 | F5: 4044 | G5: 324 | H5: 1837 | I5: 642 | J5: 1336 | K5: 856 | L5: 961 | M5: 1381 | N5: 468 | O5: 14065 | P5: 462 | Q5: 283 | R5: 539 | S5: 3300 | T5: 1019 | U5: 2465
A6: =A5+1 -> 1904 | B6: 5104 | C6: 1840 | D6: 19587 | E6: 3102 | F6: 4094 | G6: 330 | H6: 1879 | I6: 656 | J6: 1348 | K6: 874 | L6: 987 | M6: 1425 | N6: 484 | O6: 14208 | P6: 477 | Q6: 290 | R6: 555 | S6: 3400 | T6: 1038 | U6: 2471
A7: =A6+1 -> 1905 | B7: 5290 | C7: 1859 | D7: 20003 | E7: 3139 | F7: 4144 | G7: 336 | H7: 1927 | I7: 670 | J7: 1360 | K7: 893 | L7: 1013 | M7: 1468 | N7: 500 | O7: 14363 | P7: 491 | Q7: 297 | R7: 571 | S7: 3500 | T7: 1071 | U7: 2492
A8: =A7+1 -> 1906 | B8: 5524 | C8: 1877 | D8: 20427 | E8: 3176 | F8: 4277 | G8: 341 | H8: 1979 | I8: 684 | J8: 1372 | K8: 911 | L8: 1029 | M8: 1512 | N8: 511 | O8: 14519 | P8: 505 | Q8: 304 | R8: 580 | S8: 3600 | T8: 1103 | U8: 2512
A9: =A8+1 -> 1907 | B9: 5822 | C9: 1896 | D9: 20860 | E9: 3213 | F9: 4409 | G9: 347 | H9: 2034 | I9: 698 | J9: 1384 | K9: 929 | L9: 1046 | M9: 1555 | N9: 521 | O9: 14677 | P9: 515 | Q9: 311 | R9: 590 | S9: 3700 | T9: 1141 | U9: 2532
A10: =A9+1 -> 1908 | B10: 6145 | C10: 1914 | D10: 21303 | E10: 3253 | F10: 4542 | G10: 353 | H10: 2092 | I10: 712 | J10: 1396 | K10: 948 | L10: 1062 | M10: 1559 | N10: 532 | O10: 14836 | P10: 524 | Q10: 318 | R10: 600 | S10: 3800 | T10: 1054 | U10: 2554
A11: =A10+1 -> 1909 | B11: 6432 | C11: 1933 | D11: 21754 | E11: 3294 | F11: 4674 | G11: 358 | H11: 2154 | I11: 726 | J11: 1408 | K11: 966 | L11: 1079 | M11: 1643 | N11: 542 | O11: 14997 | P11: 534 | Q11: 325 | R11: 610 | S11: 3900 | T11: 1095 | U11: 2575
A12: =A11+1 -> 1910 | B12: 6799 | C12: 1951 | D12: 22216 | E12: 3336 | F12: 4807 | G12: 364 | H12: 2219 | I12: 740 | J12: 1421 | K12: 985 | L12: 1096 | M12: 1687 | N12: 553 | O12: 15160 | P12: 543 | Q12: 332 | R12: 620 | S12: 4000 | T12: 1132 | U12: 2596
A13: =A12+1 -> 1911 | B13: 7070 | C13: 1970 | D13: 22687 | E13: 3378 | F13: 4940 | G13: 370 | H13: 2287 | I13: 753 | J13: 1433 | K13: 1003 | L13: 1119 | M13: 1730 | N13: 562 | O13: 15333 | P13: 553 | Q13: 339 | R13: 630 | S13: 4100 | T13: 1178 | U13: 2612
A14: =A13+1 -> 1912 | B14: 7467 | C14: 1988 | D14: 23168 | E14: 3421 | F14: 5072 | G14: 375 | H14: 2358 | I14: 767 | J14: 1445 | K14: 1021 | L14: 1142 | M14: 1774 | N14: 571 | O14: 15508 | P14: 562 | Q14: 352 | R14: 640 | S14: 4187 | T14: 1226 | U14: 2639
... A74: =A73+1 -> 1972 | B74: 24745 | C74: 4894 | D74: 99201 | E74: 10498 | F74: 22490 | G74: 1901 | H74: 8636 | I74: 4595 | J74: 6302 | K74: 3647 | L74: 5375 | M74: 5070 | N74: 2946 | O74: 52641 | P74: 2231 | Q74: 1520 | R74: 2428 | S74: 14456 | T74: 2865 | U74: 11170
A76: notes:
A78: Боливия: включает оценку живущих в джунглях
A80: Колумбия:
B81: The 1905 census has been the subject of controversy; for discussion which accepts a revised estimate of 4355, see J de D Higuita, "Estudio Historico Anali'tico de la Poblacion Colombiana en 170 Anos,” Anales de Economia Estadistica; Boletin de la Contraloria General 3:2 (April 1940), Suplemento (published by Colombia, Contraloria General, Direccion Nacional de Estadistica). In any case, total excludes Panama.
B82: The 1928 census was not accepted by the Colombian National Congress because census was believed to be inflated for certain civil divisions.
A84: Панама:
B85: Excluding Canal Zone; including estimates for jungle Indians.

Sheet SALA 2002
A1: год | B1: Аргентина | C1: Боливия | D1: Бразилия | E1: Чили | F1: Колумбия | G1: Коста-Рика | H1: Куба | I1: Доминиканская республика | J1: Эквадор | K1: Эль-Сальвадор | L1: Гватемала | M1: Гаити | N1: Гондурас | O1: Мексика | P1: Никарагуа | Q1: Панама | R1: Парагвай | S1: Перу | T1: Уругвай | U1: Венецуэлла
A2: 1900 | B2: 4.61 | C2: 1.77 | D2: 17.98 | E2: 2.96 | F2: 3.89 | G2: 0.31 | H2: 1.6 | I2: 0.6 | J2: 1.3 | K2: 0.8 | L2: 0.89 | M2: 1.25 | N2: 0.42 | O2: 13.61 | P2: 0.42 | Q2: 0.26 | R2: 0.49 | S2: 3 | T2: 0.96 | U2: 2.45
A3: =A2+1 -> 1901 | B3: 4.74 | C3: 1.79 | D3: 18.39 | E3: 2.99 | F3: 3.94 | G3: 0.31 | H3: 1.68 | I3: 0.61 | J3: 1.31 | K3: 0.82 | L3: 0.91 | M3: 1.29 | N3: 0.44 | O3: 13.76 | P3: 0.43 | Q3: 0.27 | R3: 0.51 | S3: 3.1 | T3: 0.97 | U3: 2.45
A4: =A3+1 -> 1902 | B4: 4.87 | C4: 1.8 | D4: 18.78 | E4: 3.03 | F4: 3.99 | G4: 0.32 | H4: 1.76 | I4: 0.63 | J4: 1.32 | K4: 0.84 | L4: 0.94 | M4: 1.34 | N4: 0.45 | O4: 13.91 | P4: 0.45 | Q4: 0.28 | R4: 0.52 | S4: 3.2 | T4: 0.99 | U4: 2.46
A5: =A4+1 -> 1903 | B5: 4.98 | C5: 1.82 | D5: 19.18 | E5: 3.07 | F5: 4.04 | G5: 0.32 | H5: 1.84 | I5: 0.64 | J5: 1.34 | K5: 0.86 | L5: 0.96 | M5: 1.38 | N5: 0.47 | O5: 14.07 | P5: 0.46 | Q5: 0.28 | R5: 0.54 | S5: 3.3 | T5: 1.02 | U5: 2.47
A6: =A5+1 -> 1904 | B6: 5.1 | C6: 1.84 | D6: 19.58 | E6: 3.1 | F6: 4.09 | G6: 0.33 | H6: 1.88 | I6: 0.66 | J6: 1.35 | K6: 0.87 | L6: 0.99 | M6: 1.43 | N6: 0.48 | O6: 14.21 | P6: 0.48 | Q6: 0.29 | R6: 0.56 | S6: 3.4 | T6: 1.04 | U6: 2.47
A7: =A6+1 -> 1905 | B7: 5.29 | C7: 1.86 | D7: 20 | E7: 3.14 | F7: 4.14 | G7: 0.34 | H7: 1.93 | I7: 0.67 | J7: 1.36 | K7: 0.89 | L7: 1.01 | M7: 1.47 | N7: 0.5 | O7: 14.36 | P7: 0.49 | Q7: 0.3 | R7: 0.57 | S7: 3.5 | T7: 1.07 | U7: 2.49
A8: =A7+1 -> 1906 | B8: 5.52 | C8: 1.88 | D8: 20.43 | E8: 3.18 | F8: 4.28 | G8: 0.34 | H8: 1.98 | I8: 0.68 | J8: 1.37 | K8: 0.91 | L8: 1.03 | M8: 1.51 | N8: 0.51 | O8: 14.52 | P8: 0.51 | Q8: 0.3 | R8: 0.58 | S8: 3.6 | T8: 1.1 | U8: 2.51
A9: =A8+1 -> 1907 | B9: 5.82 | C9: 1.9 | D9: 20.86 | E9: 3.21 | F9: 4.41 | G9: 0.35 | H9: 2.03 | I9: 0.7 | J9: 1.38 | K9: 0.93 | L9: 1.05 | M9: 1.56 | N9: 0.52 | O9: 14.68 | P9: 0.52 | Q9: 0.31 | R9: 0.59 | S9: 3.7 | T9: 1.14 | U9: 2.53
A10: =A9+1 -> 1908 | B10: 6.15 | C10: 1.91 | D10: 21.3 | E10: 3.25 | F10: 4.54 | G10: 0.35 | H10: 2.09 | I10: 0.71 | J10: 1.4 | K10: 0.95 | L10: 1.06 | M10: 1.56 | N10: 0.53 | O10: 14.84 | P10: 0.52 | Q10: 0.32 | R10: 0.6 | S10: 3.8 | T10: 1.05 | U10: 2.55
A11: =A10+1 -> 1909 | B11: 6.43 | C11: 1.93 | D11: 21.75 | E11: 3.29 | F11: 4.67 | G11: 0.36 | H11: 2.15 | I11: 0.73 | J11: 1.41 | K11: 0.97 | L11: 1.08 | M11: 1.64 | N11: 0.54 | O11: 15 | P11: 0.53 | Q11: 0.33 | R11: 0.61 | S11: 3.9 | T11: 1.1 | U11: 2.57
A12: =A11+1 -> 1910 | B12: 6.8 | C12: 1.95 | D12: 22.22 | E12: 3.34 | F12: 4.81 | G12: 0.36 | H12: 2.22 | I12: 0.74 | J12: 1.42 | K12: 0.99 | L12: 1.1 | M12: 1.69 | N12: 0.55 | O12: 15.16 | P12: 0.54 | Q12: 0.33 | R12: 0.62 | S12: 4 | T12: 1.13 | U12: 2.6
A13: =A12+1 -> 1911 | B13: 7.07 | C13: 1.97 | D13: 22.69 | E13: 3.38 | F13: 4.94 | G13: 0.37 | H13: 2.29 | I13: 0.75 | J13: 1.43 | K13: 1 | L13: 1.12 | M13: 1.73 | N13: 0.56 | O13: 15.33 | P13: 0.55 | Q13: 0.34 | R13: 0.63 | S13: 4.1 | T13: 1.18 | U13: 2.61
A14: =A13+1 -> 1912 | B14: 7.47 | C14: 1.98 | D14: 23.17 | E14: 3.42 | F14: 5.07 | G14: 0.38 | H14: 2.36 | I14: 0.77 | J14: 1.45 | K14: 1.02 | L14: 1.14 | M14: 1.77 | N14: 0.57 | O14: 15.51 | P14: 0.56 | Q14: 0.35 | R14: 0.64 | S14: 4.19 | T14: 1.23 | U14: 2.64
... A102: =A101+1 -> 2000 | B102: 37.03 | C102: 8.33 | D102: 170.12 | E102: 15.21 | F102: 42.32 | G102: 4.02 | H102: 11.2 | I102: 8.5 | J102: 12.65 | K102: 6.28 | L102: 11.38 | M102: 8.22 | N102: 6.48 | O102: 98.88 | P102: 5.07 | Q102: 2.86 | R102: 5.5 | S102: 25.66 | T102: 3.34 | U102: 24.17

Sheet SALA Alt
B1: 1900 | C1: 1900 | D1: 1910 | E1: 1920 | F1: 1920 | G1: 1930 | H1: 1930 | I1: 1930 | J1: 1940 | K1: 1940 | L1: 1940 | M1: 1950 | N1: 1950 | O1: 1950 | P1: 1960 | Q1: 1960 | R1: 1960 | S1: 1970 | T1: 1970
A2: страна | B2: Collver | C2: SA | D2: Collver | E2: Collver | F2: WPP | G2: Collver | H2: SA | I2: WPP | J2: Collver | K2: SA | L2: WPP | M2: Collver | N2: SA | O2: WPP | P2: Collver | Q2: SA | R2: WPP | S2: SA | T2: WPP
A4: Латинская Америка | B4: 31247 | C4: 60059 | D4: 37981 | E4: 43789 | F4: 85595 | G4: 53672 | H4: 102889 | I4: 102899 | J4: 72735 | K4: 124194 | L4: 124445 | M4: 90345 | N4: 157296 | O4: 155967 | P4: 111489 | Q4: 206432 | R4: 205018 | S4: 274314 | T4: 271416
A5: Аргениина | B5: 4556 | C5: 4743 | D5: 6595 | E5: 8749 | F5: 8861 | G5: 11711 | H5: 11896 | I5: 11896 | J5: 13964 | K5: 14169 | L5: 14169 | M5: 16733 | N5: 17085 | O5: 17189 | P5: 20378 | Q5: 20850 | R5: 20956 | S5: 24352 | T5: 24784
A6: Боливия | C6: 1696 | F6: 1864 | H6: 2153 | I6: 2153 | J6: 2052 | K6: 2508 | L6: 2508 | M6: 2670 | N6: 3013 | O6: 3013 | P6: 3044 | Q6: 3696 | R6: 3696 | S6: 4658 | T6: 4658
A7: Бразилия | C7: 17318 | F7: 27554 | H7: 33568 | I7: 33718 | K7: 41233 | L7: 41525 | N7: 52328 | O7: 52328 | Q7: 70327 | R7: 70459 | S7: 93245 | T7: 93902
A8: Чили | B8: 2856 | C8: 2904 | D8: 3229 | E8: 3664 | F8: 3785 | G8: 4221 | H8: 4424 | I8: 4365 | J8: 4912 | K8: 5147 | L8: 5063 | M8: 5929 | N8: 6058 | O8: 6073 | P8: 7556 | Q8: 7683 | R8: 7627 | S8: 9117 | T8: 9753
A9: Колумбия | B9: 4100 | C9: 3825 | D9: 4850 | E9: 5840 | F9: 6089 | G9: 7260 | H9: 7350 | I9: 7280 | J9: 8950 | K9: 9077 | L9: 9097 | M9: 11200 | N9: 11629 | O9: 11679 | P9: 14735 | Q9: 15877 | R9: 15468 | S9: 22160 | T9: 20514
A10: Коста Рика | B10: 254 | C10: 285 | D10: 325 | E10: 399 | F10: 421 | G10: 501 | H10: 499 | I10: 499 | J10: 637 | K10: 619 | L10: 619 | M10: 841 | N10: 849 | O10: 801 | P10: 1202 | Q10: 1249 | R10: 1171 | S10: 1736 | T10: 1718
A11: Куба | B11: 1638 | C11: 1573 | D11: 2192 | E11: 2957 | F11: 2950 | G11: 3828 | H11: 3837 | I11: 3837 | J11: 4449 | K11: 4566 | L11: 4566 | M11: 5513 | N11: 5520 | O11: 5508 | Q11: 6819 | R11: 6797 | S11: 8341 | T11: 8307
A12: Доминиканская республика | C12: 700 | F12: 1140 | H12: 1400 | I12: 1400 | K12: 1759 | L12: 1759 | N12: 2303 | O12: 2243 | Q12: 3129 | R12: 3030 | S12: 4348 | T12: 4277
A13: Эквадор | C13: 1400 | E13: 1607 | F13: 1930 | G13: 1959 | H13: 2160 | I13: 2102 | J13: 2453 | K13: 2586 | L13: 2546 | M13: 3117 | N13: 3225 | O13: 3277 | P13: 4201 | Q13: 4323 | R13: 4355 | S13: 6028 | T13: 5819
A14: Эль Сальвадор | B14: 943 | C14: 932 | D14: 1075 | E14: 1161 | F14: 1168 | G14: 1328 | H14: 1443 | I14: 1350 | J14: 1540 | K14: 1633 | L14: 1550 | M14: 1869 | N14: 1922 | O14: 1868 | P14: 2500 | Q14: 2512 | R14: 2442 | S14: 3441 | T14: 3346
A15: Гватемала | B15: 1430 | C15: 1425 | D15: 1580 | E15: 1711 | F15: 1450 | G15: 2000 | H15: 1771 | I15: 1771 | J15: 2300 | K15: 2201 | L15: 2201 | M15: 2800 | N15: 3024 | O15: 2805 | P15: 3715 | Q15: 3965 | R15: 3765 | S15: 5282 | T15: 5033
A16: Гаита | C16: 1270 | F16: 2124 | H16: 2422 | I16: 2422 | K16: 2825 | L16: 2827 | N16: 3380 | O16: 3380 | Q16: 4138 | R16: 4140 | S16: 5229 | T16: 5255
A17: Гондурас | C17: 443 | D17: 575 | E17: 680 | F17: 783 | G17: 840 | H17: 948 | I17: 948 | J17: 1027 | K17: 1119 | L17: 1146 | M17: 1290 | N17: 1389 | O17: 1428 | P17: 1784 | Q17: 1849 | R17: 1838 | S17: 2583 | T17: 2592
A18: Мексика | B18: 13250 | C18: 13607 | D18: 15000 | E18: 14000 | F18: 14500 | G18: 16450 | H18: 16589 | I18: 16589 | J18: 19950 | K18: 19815 | L18: 19815 | M18: 25350 | N18: 26640 | O18: 25826 | P18: 34650 | Q18: 36046 | R18: 34988 | S18: 50718 | T18: 49282
A19: Никарагуа | C19: 448 | F19: 600 | H19: 742 | I19: 700 | K19: 893 | L19: 825 | N19: 1133 | O19: 1060 | Q19: 1501 | R19: 1403 | S19: 2021 | T19: 1979
A20: Панама | B20: 227 | D20: 277 | E20: 385 | F20: 447 | G20: 439 | H20: 502 | I20: 523 | J20: 557 | K20: 595 | L20: 620 | M20: 731 | N20: 765 | O20: 797 | P20: 991 | Q20: 1021 | R20: 1079 | S20: 1406 | T20: 1458
A21: Парагвай | C21: 440 | F21: 699 | H21: 880 | I21: 880 | K21: 1111 | L21: 1111 | N21: 1337 | O21: 1397 | Q21: 1740 | R21: 1720 | S21: 2419 | T21: 2233
A22: Перу | C22: 3791 | F22: 5313 | H22: 5651 | I22: 5752 | J22: 6160 | K22: 6681 | L22: 6784 | M22: 7370 | N22: 7968 | O22: 8096 | P22: 9502 | Q22: 10024 | R22: 10199 | S22: 13586 | T22: 13275
A23: Уругвай | C23: 915 | F23: 1479 | H23: 1734 | I23: 1713 | K23: 1947 | L23: 1974 | N23: 2198 | O23: 2195 | Q23: 2542 | R23: 2491 | S23: 2889 | T23: 2802
A24: Венецуэлла | B24: 1993 | C24: 2344 | D24: 2283 | E24: 2636 | F24: 2438 | G24: 3135 | H24: 2950 | I24: 2980 | J24: 3784 | K24: 3710 | L24: 3740 | M24: 4932 | N24: 5530 | O24: 5004 | P24: 7231 | Q24: 7141 | R24: 7394 | S24: 10755 | T24: 10429
A26: notes:
A28: SA = Sanchez-Albornoz
A29: Желтым цветом помечена неполная сумма по части стран
A30: Источники не указывают, включают ли они оценку населения в джунглях

Sheet WPP 2024 начало года
A1: год | B1: Аргентина | C1: Боливия | D1: Бразилия | E1: Чили | F1: Колумбия | G1: Коста-Рика | H1: Куба | I1: Доминиканская республика | J1: Эквадор | K1: Эль-Сальвадор | L1: Гватемала | M1: Гаити | N1: Гондурас | O1: Мексика | P1: Никарагуа | Q1: Панама | R1: Парагвай | S1: Перу | T1: Уругвай | U1: Венецуэлла
A2: 1950 | B2: 16849.7 | C2: 3067.1 | D2: 52620.4 | E2: 6566.6 | F2: 11614.8 | G2: 911.4 | H2: 5865.9 | I2: 2345.8 | J2: 3472.2 | K2: 2157.5 | L2: 3058.3 | M2: 3241.7 | N2: 1538.1 | O2: 27231.6 | P2: 1312.5 | Q2: 850.6 | R2: 1487.8 | S2: 7571.2 | T2: 2224.1 | U2: 5368.3
A3: 1951 | B3: 17186.4 | C3: 3112.9 | D3: 54196.7 | E3: 6690.6 | F3: 11919.1 | G3: 942.1 | H3: 5983.1 | I3: 2414 | J3: 3561.4 | K3: 2209.5 | L3: 3136.1 | M3: 3289.7 | N3: 1579.8 | O3: 27944.3 | P3: 1350.4 | Q3: 871.1 | R3: 1520.9 | S3: 7783.6 | T3: 2244.7 | U3: 5609.4
A4: 1952 | B4: 17526.5 | C4: 3161.7 | D4: 55841 | E4: 6822.7 | F4: 12238.5 | G4: 974.7 | H4: 6101.3 | I4: 2486.3 | J4: 3654.3 | K4: 2261.1 | L4: 3218.6 | M4: 3340.1 | N4: 1623.2 | O4: 28696.6 | P4: 1388.9 | Q4: 892.9 | R4: 1555 | S4: 8003.6 | T4: 2268.1 | U4: 5855.8
A5: 1953 | B5: 17871.2 | C5: 3213.3 | D5: 57548.8 | E5: 6961.2 | F5: 12573.2 | G5: 1008.9 | H5: 6223.1 | I5: 2563.8 | J5: 3750.5 | K5: 2314.8 | L5: 3304.7 | M5: 3392.4 | N5: 1668.5 | O5: 29483.7 | P5: 1429.1 | Q5: 916 | R5: 1590.2 | S5: 8229.7 | T5: 2294.1 | U5: 6106.9
A6: 1954 | B6: 18211.4 | C6: 3268.6 | D6: 59318.7 | E6: 7105.8 | F6: 12918.9 | G6: 1045.1 | H6: 6348.4 | I6: 2645.9 | J6: 3850 | K6: 2369.2 | L6: 3392.9 | M6: 3447.3 | N6: 1715.5 | O6: 30314.8 | P6: 1470.7 | Q6: 940.4 | R6: 1626.4 | S6: 8460.1 | T6: 2322 | U6: 6362.6
A7: 1955 | B7: 18551 | C7: 3327.1 | D7: 61151.5 | E7: 7255.3 | F7: 13282.8 | G7: 1083.1 | H7: 6477.3 | I7: 2732.3 | J7: 3953 | K7: 2426.5 | L7: 3485.3 | M7: 3503.8 | N7: 1764.2 | O7: 31191.2 | P7: 1513.8 | Q7: 965.8 | R7: 1663.4 | S7: 8698.6 | T7: 2351.7 | U7: 6623
A8: 1956 | B8: 18881 | C8: 3388.9 | D8: 63051.3 | E8: 7409.3 | F8: 13663.3 | G8: 1123 | H8: 6608.9 | I8: 2822.9 | J8: 4059.4 | K8: 2486.7 | L8: 3581.3 | M8: 3563.7 | N8: 1814.6 | O8: 32110 | P8: 1558.7 | Q8: 992.1 | R8: 1701.1 | S8: 8945.5 | T8: 2382.4 | U8: 6888.6
A9: 1957 | B9: 19218.9 | C9: 3453.8 | D9: 65016.7 | E9: 7569.8 | F9: 14060.3 | G9: 1164.7 | H9: 6743.2 | I9: 2917.1 | J9: 4169.7 | K9: 2549.6 | L9: 3681 | M9: 3625.9 | N9: 1866.7 | O9: 33065.9 | P9: 1605.3 | Q9: 1019.6 | R9: 1739.7 | S9: 9201.5 | T9: 2414.4 | U9: 7160
A10: 1958 | B10: 19547.2 | C10: 3521.4 | D10: 67046.3 | E10: 7732.8 | F10: 14480.2 | G10: 1208.5 | H10: 6880.3 | I10: 3014.4 | J10: 4284.1 | K10: 2615.4 | L10: 3784.4 | M10: 3689.7 | N10: 1920.5 | O10: 34059.5 | P10: 1653.7 | Q10: 1048.2 | R10: 1779.3 | S10: 9466.3 | T10: 2447.2 | U10: 7438.9
A11: 1959 | B11: 19881.3 | C11: 3591.7 | D11: 69138 | E11: 7899.1 | F11: 14906.3 | G11: 1254.6 | H11: 7020.3 | I11: 3114.3 | J11: 4402.9 | K11: 2681.9 | L11: 3889.6 | M11: 3755.7 | N11: 1975.8 | O11: 35090.6 | P11: 1703.8 | Q11: 1078.1 | R11: 1820 | S11: 9741 | T11: 2480.6 | U11: 7725.1
A12: 1960 | B12: 20217.9 | C12: 3664.6 | D12: 71290.9 | E12: 8067.7 | F12: 15366.1 | G12: 1302.6 | H12: 7164.4 | I12: 3216.3 | J12: 4526.6 | K12: 2753.1 | L12: 4003.4 | M12: 3823.7 | N12: 2032.8 | O12: 36163.9 | P12: 1755.7 | Q12: 1109.5 | R12: 1861.9 | S12: 10026.3 | T12: 2513.7 | U12: 8013.4
A13: 1961 | B13: 20554.2 | C13: 3740 | D13: 73485.3 | E13: 8239 | F13: 15846.3 | G13: 1352.4 | H13: 7311.8 | I13: 3320.3 | J13: 4655.2 | K13: 2829.8 | L13: 4123.9 | M13: 3893.2 | N13: 2091.3 | O13: 37285.3 | P13: 1809 | Q13: 1142.5 | R13: 1905.1 | S13: 10322 | T13: 2546.2 | U13: 8306.8
... A75: 2023 | B75: 45459 | C75: 12159.5 | D75: 210707 | E75: 19603.2 | F75: 52032.6 | G75: 5093 | H75: 11039.3 | I75: 11282.5 | J75: 17902 | K75: 6295.3 | L75: 17984.5 | M75: 11569.6 | N75: 10554.3 | O75: 129171.1 | P75: 6777.2 | Q75: 4430 | R75: 6801.5 | S75: 33656.3 | T75: 3388.7 | U75: 28250.8

Sheet WPP 2024 середина года
A1: год | B1: Аргентина | C1: Боливия | D1: Бразилия | E1: Чили | F1: Колумбия | G1: Коста-Рика | H1: Куба | I1: Доминиканская республика | J1: Эквадор | K1: Эль-Сальвадор | L1: Гватемала | M1: Гаити | N1: Гондурас | O1: Мексика | P1: Никарагуа | Q1: Панама | R1: Парагвай | S1: Перу | T1: Уругвай | U1: Венецуэлла
A2: 1950 | B2: 17018 | C2: 3090 | D2: 53408.6 | E2: 6628.6 | F2: 11767 | G2: 926.8 | H2: 5924.5 | I2: 2379.9 | J2: 3516.8 | K2: 2183.5 | L2: 3097.2 | M2: 3265.7 | N2: 1558.9 | O2: 27587.9 | P2: 1331.4 | Q2: 860.9 | R2: 1504.3 | S2: 7677.4 | T2: 2234.4 | U2: 5488.9
A3: 1951 | B3: 17356.5 | C3: 3137.3 | D3: 55018.9 | E3: 6756.7 | F3: 12078.8 | G3: 958.4 | H3: 6042.2 | I3: 2450.1 | J3: 3607.8 | K3: 2235.3 | L3: 3177.4 | M3: 3314.9 | N3: 1601.5 | O3: 28320.5 | P3: 1369.7 | Q3: 882 | R3: 1537.9 | S3: 7893.6 | T3: 2256.4 | U3: 5732.6
A4: 1952 | B4: 17698.9 | C4: 3187.5 | D4: 56694.9 | E4: 6892 | F4: 12405.8 | G4: 991.8 | H4: 6162.2 | I4: 2525 | J4: 3702.4 | K4: 2288 | L4: 3261.7 | M4: 3366.3 | N4: 1645.8 | O4: 29090.2 | P4: 1409 | Q4: 904.5 | R4: 1572.6 | S4: 8116.7 | T4: 2281.1 | U4: 5981.4
A5: 1953 | B5: 18041.3 | C5: 3241 | D5: 58433.8 | E5: 7033.5 | F5: 12746 | G5: 1027 | H5: 6285.7 | I5: 2604.8 | J5: 3800.3 | K5: 2342 | L5: 3348.8 | M5: 3419.8 | N5: 1692 | O5: 29899.2 | P5: 1449.9 | Q5: 928.2 | R5: 1608.3 | S5: 8344.9 | T5: 2308.1 | U5: 6234.8
A6: 1954 | B6: 18381.2 | C6: 3297.8 | D6: 60235.1 | E6: 7180.6 | F6: 13100.8 | G6: 1064.1 | H6: 6412.8 | I6: 2689.1 | J6: 3901.5 | K6: 2397.8 | L6: 3439.1 | M6: 3475.5 | N6: 1739.8 | O6: 30753 | P6: 1492.3 | Q6: 953.1 | R6: 1644.9 | S6: 8579.3 | T6: 2336.9 | U6: 6492.8
A7: 1955 | B7: 18716 | C7: 3358 | D7: 62101.4 | E7: 7332.3 | F7: 13473.1 | G7: 1103 | H7: 6543.1 | I7: 2777.6 | J7: 4006.2 | K7: 2456.6 | L7: 3533.3 | M7: 3533.7 | N7: 1789.4 | O7: 31650.6 | P7: 1536.2 | Q7: 979 | R7: 1682.3 | S7: 8822 | T7: 2367 | U7: 6755.8
A8: 1956 | B8: 19050 | C8: 3421.3 | D8: 64034 | E8: 7489.5 | F8: 13861.8 | G8: 1143.8 | H8: 6676.1 | I8: 2870 | J8: 4114.5 | K8: 2518.2 | L8: 3631.2 | M8: 3594.8 | N8: 1840.7 | O8: 32587.9 | P8: 1582 | Q8: 1005.9 | R8: 1720.4 | S8: 9073.5 | T8: 2398.4 | U8: 7024.3
A9: 1957 | B9: 19383 | C9: 3487.6 | D9: 66031.5 | E9: 7651.3 | F9: 14270.3 | G9: 1186.6 | H9: 6811.7 | I9: 2965.8 | J9: 4226.9 | K9: 2582.5 | L9: 3732.7 | M9: 3657.8 | N9: 1893.6 | O9: 33562.7 | P9: 1629.5 | Q9: 1033.9 | R9: 1759.5 | S9: 9333.9 | T9: 2430.8 | U9: 7299.4
A10: 1958 | B10: 19714.3 | C10: 3556.6 | D10: 68092.1 | E10: 7816 | F10: 14693.3 | G10: 1231.6 | H10: 6950.3 | I10: 3064.3 | J10: 4343.5 | K10: 2648.7 | L10: 3837 | M10: 3722.7 | N10: 1948.2 | O10: 34575.1 | P10: 1678.7 | Q10: 1063.2 | R10: 1799.6 | S10: 9603.6 | T10: 2463.9 | U10: 7582
A11: 1959 | B11: 20049.6 | C11: 3628.2 | D11: 70214.5 | E11: 7983.4 | F11: 15136.2 | G11: 1278.6 | H11: 7092.3 | I11: 3165.3 | J11: 4464.8 | K11: 2717.5 | L11: 3946.5 | M11: 3789.7 | N11: 2004.3 | O11: 35627.3 | P11: 1729.8 | Q11: 1093.8 | R11: 1841 | S11: 9883.7 | T11: 2497.1 | U11: 7869.2
A12: 1960 | B12: 20386 | C12: 3702.3 | D12: 72388.1 | E12: 8153.4 | F12: 15606.2 | G12: 1327.5 | H12: 7238.1 | I12: 3268.3 | J12: 4590.9 | K12: 2791.5 | L12: 4063.7 | M12: 3858.4 | N12: 2062.1 | O12: 36724.6 | P12: 1782.4 | Q12: 1126 | R12: 1883.5 | S12: 10174.1 | T12: 2530 | U12: 8160.1
A13: 1961 | B13: 20726.3 | C13: 3778.7 | D13: 74605.4 | E13: 8324.8 | F13: 16095.2 | G13: 1377.9 | H13: 7387.1 | I13: 3373.2 | J13: 4722.3 | K13: 2870 | L13: 4186.2 | M13: 3929 | N13: 2121.2 | O13: 37890.1 | P13: 1836.5 | Q13: 1159.9 | R13: 1927.4 | S13: 10475.1 | T13: 2562 | U13: 8455.9
... A75: 2023 | B75: 45538.4 | C75: 12244.2 | D75: 211140.7 | E75: 19658.8 | F75: 52321.2 | G75: 5105.5 | H75: 11019.9 | I75: 11331.3 | J75: 17980.1 | K75: 6309.6 | L75: 18124.8 | M75: 11637.4 | N75: 10644.9 | O75: 129739.8 | P75: 6823.6 | Q75: 4458.8 | R75: 6844.1 | S75: 33845.6 | T75: 3388.1 | U75: 28300.9

Sheet SALA WPP 2024 195x
A1: год | B1: Аргентина | C1: Боливия | D1: Бразилия | E1: Чили | F1: Колумбия | G1: Коста-Рика | H1: Куба | I1: Доминиканская республика | J1: Эквадор | K1: Эль-Сальвадор | L1: Гватемала | M1: Гаити | N1: Гондурас | O1: Мексика | P1: Никарагуа | Q1: Панама | R1: Парагвай | S1: Перу | T1: Уругвай | U1: Венецуэлла
A2: 1900 | B2: 4607 | C2: 1766 | D2: 17984 | E2: 2959 | F2: 3894 | G2: 307 | H2: 1600 | I2: 600 | J2: 1300 | K2: 801 | L2: 885 | M2: 1250 | N2: 420 | O2: 13607 | P2: 420 | Q2: 263 | R2: 490 | S2: 3000 | T2: 963 | U2: 2445
A3: 1901 | B3: 4741 | C3: 1785 | D3: 18392 | E3: 2994 | F3: 3944 | G3: 313 | H3: 1679 | I3: 614 | J3: 1312 | K3: 819 | L3: 910 | M3: 1294 | N3: 436 | O3: 13755 | P3: 434 | Q3: 270 | R3: 506 | S3: 3100 | T3: 965 | U3: 2451
A4: 1902 | B4: 4872 | C4: 1803 | D4: 18782 | E4: 3030 | F4: 3994 | G4: 318 | H4: 1758 | I4: 628 | J4: 1324 | K4: 838 | L4: 936 | M4: 1338 | N4: 452 | O4: 13905 | P4: 448 | Q4: 276 | R4: 522 | S4: 3200 | T4: 990 | U4: 2458
A5: 1903 | B5: 4976 | C5: 1822 | D5: 19180 | E5: 3066 | F5: 4044 | G5: 324 | H5: 1837 | I5: 642 | J5: 1336 | K5: 856 | L5: 961 | M5: 1381 | N5: 468 | O5: 14065 | P5: 462 | Q5: 283 | R5: 539 | S5: 3300 | T5: 1019 | U5: 2465
A6: 1904 | B6: 5104 | C6: 1840 | D6: 19587 | E6: 3102 | F6: 4094 | G6: 330 | H6: 1879 | I6: 656 | J6: 1348 | K6: 874 | L6: 987 | M6: 1425 | N6: 484 | O6: 14208 | P6: 477 | Q6: 290 | R6: 555 | S6: 3400 | T6: 1038 | U6: 2471
A7: 1905 | B7: 5290 | C7: 1859 | D7: 20003 | E7: 3139 | F7: 4144 | G7: 336 | H7: 1927 | I7: 670 | J7: 1360 | K7: 893 | L7: 1013 | M7: 1468 | N7: 500 | O7: 14363 | P7: 491 | Q7: 297 | R7: 571 | S7: 3500 | T7: 1071 | U7: 2492
A8: 1906 | B8: 5524 | C8: 1877 | D8: 20427 | E8: 3176 | F8: 4277 | G8: 341 | H8: 1979 | I8: 684 | J8: 1372 | K8: 911 | L8: 1029 | M8: 1512 | N8: 511 | O8: 14519 | P8: 505 | Q8: 304 | R8: 580 | S8: 3600 | T8: 1103 | U8: 2512
A9: 1907 | B9: 5822 | C9: 1896 | D9: 20860 | E9: 3213 | F9: 4409 | G9: 347 | H9: 2034 | I9: 698 | J9: 1384 | K9: 929 | L9: 1046 | M9: 1555 | N9: 521 | O9: 14677 | P9: 515 | Q9: 311 | R9: 590 | S9: 3700 | T9: 1141 | U9: 2532
A10: 1908 | B10: 6145 | C10: 1914 | D10: 21303 | E10: 3253 | F10: 4542 | G10: 353 | H10: 2092 | I10: 712 | J10: 1396 | K10: 948 | L10: 1062 | M10: 1559 | N10: 532 | O10: 14836 | P10: 524 | Q10: 318 | R10: 600 | S10: 3800 | T10: 1054 | U10: 2554
A11: 1909 | B11: 6432 | C11: 1933 | D11: 21754 | E11: 3294 | F11: 4674 | G11: 358 | H11: 2154 | I11: 726 | J11: 1408 | K11: 966 | L11: 1079 | M11: 1643 | N11: 542 | O11: 14997 | P11: 534 | Q11: 325 | R11: 610 | S11: 3900 | T11: 1095 | U11: 2575
A12: 1910 | B12: 6799 | C12: 1951 | D12: 22216 | E12: 3336 | F12: 4807 | G12: 364 | H12: 2219 | I12: 740 | J12: 1421 | K12: 985 | L12: 1096 | M12: 1687 | N12: 553 | O12: 15160 | P12: 543 | Q12: 332 | R12: 620 | S12: 4000 | T12: 1132 | U12: 2596
A13: 1911 | B13: 7070 | C13: 1970 | D13: 22687 | E13: 3378 | F13: 4940 | G13: 370 | H13: 2287 | I13: 753 | J13: 1433 | K13: 1003 | L13: 1119 | M13: 1730 | N13: 562 | O13: 15333 | P13: 553 | Q13: 339 | R13: 630 | S13: 4100 | T13: 1178 | U13: 2612
... A125: 2023 | B125: 45538.4 | C125: 12244.2 | D125: 211140.7 | E125: 19658.8 | F125: 52321.2 | G125: 5105.5 | H125: 11019.9 | I125: 11331.3 | J125: 17980.1 | K125: 6309.6 | L125: 18124.8 | M125: 11637.4 | N125: 10644.9 | O125: 129739.8 | P125: 6823.6 | Q125: 4458.8 | R125: 6844.1 | S125: 33845.6 | T125: 3388.1 | U125: 28300.9

Sheet SALA WPP 2024 199x
A1: год | B1: Аргентина | C1: Боливия | D1: Бразилия | E1: Чили | F1: Колумбия | G1: Коста-Рика | H1: Куба | I1: Доминиканская республика | J1: Эквадор | K1: Эль-Сальвадор | L1: Гватемала | M1: Гаити | N1: Гондурас | O1: Мексика | P1: Никарагуа | Q1: Панама | R1: Парагвай | S1: Перу | T1: Уругвай | U1: Венецуэлла
A2: 1900 | B2: =IF($A2<=1951,INDEX('SALA 1974'!$B:$U,MATCH($A2,'SALA 1974'!$A:$A,0),MATCH(B$1,'SALA 1974'!$B$1:$U$1,0)),IF($A2<=1994,1000*INDEX('SALA 2002'!$B:$U,MATCH($A2,'SALA 2002'!$A:$A,0),MATCH(B$1,'SALA 2002'!$B$1:$U$1,0)),IF($A2<=2000,1000*INDEX('SALA 2002'!$B:$U,MATCH($A2,'SALA 2002'!$A:$A,0),MATCH(B$1,'SALA 2002'!$B$1:$U$1,0))*POWER(INDEX('WPP 2024 середина года'!$B:$U,MATCH($A2,'WPP 2024 середина года'!$A:$A,0),MATCH(B$1,'WPP 2024 середина года'!$B$1:$U$1,0))/(1000*INDEX('SALA 2002'!$B:$U,MATCH($A2,'SALA 2002'!$A:$A,0),MATCH(B$1,'SALA 2002'!$B$1:$U$1,0))),($A2-1994)/7),INDEX('WPP 2024 середина года'!$B:$U,MATCH($A2,'WPP 2024 середина года'!$A:$A,0),MATCH(B$1,'WPP 2024 середина года'!$B$1:$U$1,0))))) -> 4607 | C2: =IF($A2<=1951,INDEX('SALA 1974'!$B:$U,MATCH($A2,'SALA 1974'!$A:$A,0),MATCH(C$1,'SALA 1974'!$B$1:$U$1,0)),IF($A2<=1994,1000*INDEX('SALA 2002'!$B:$U,MATCH($A2,'SALA 2002'!$A:$A,0),MATCH(C$1,'SALA 2002'!$B$1:$U$1,0)),IF($A2<=2000,1000*INDEX('SALA 2002'!$B:$U,MATCH($A2,'SALA 2002'!$A:$A,0),MATCH(C$1,'SALA 2002'!$B$1:$U$1,0))*POWER(INDEX('WPP 2024 середина года'!$B:$U,MATCH($A2,'WPP 2024 середина года'!$A:$A,0),MATCH(C$1,'WPP 2024 середина года'!$B$1:$U$1,0))/(1000*INDEX('SALA 2002'!$B:$U,MATCH($A2,'SALA 2002'!$A:$A,0),MATCH(C$1,'SALA 2002'!$B$1:$U$1,0))),($A2-1994)/7),INDEX('WPP 2024 середина года'!$B:$U,MATCH($A2,'WPP 2024 середина года'!$A:$A,0),MATCH(C$1,'WPP 2024 середина года'!$B$1:$U$1,0))))) -> 1766 | D2: =IF($A2<=1951,INDEX('SALA 1974'!$B:$U,MATCH($A2,'SALA 1974'!$A:$A,0),MATCH(D$1,'SALA 1974'!$B$1:$U$1,0)),IF($A2<=1994,1000*INDEX('SALA 2002'!$B:$U,MATCH($A2,'SALA 2002'!$A:$A,0),MATCH(D$1,'SALA 2002'!$B$1:$U$1,0)),IF($A2<=2000,1000*INDEX('SALA 2002'!$B:$U,MATCH($A2,'SALA 2002'!$A:$A,0),MATCH(D$1,'SALA 2002'!$B$1:$U$1,0))*POWER(INDEX('WPP 2024 середина года'!$B:$U,MATCH($A2,'WPP 2024 середина года'!$A:$A,0),MATCH(D$1,'WPP 2024 середина года'!$B$1:$U$1,0))/(1000*INDEX('SALA 2002'!$B:$U,MATCH($A2,'SALA 2002'!$A:$A,0),MATCH(D$1,'SALA 2002'!$B$1:$U$1,0))),($A2-1994)/7),INDEX('WPP 2024 середина года'!$B:$U,MATCH($A2,'WPP 2024 середина года'!$A:$A,0),MATCH(D$1,'WPP 2024 середина года'!$B$1:$U$1,0))))) -> 17984 | E2: =IF($A2<=1951,INDEX('SALA 1974'!$B:$U,MATCH($A2,'SALA 1974'!$A:$A,0),MATCH(E$1,'SALA 1974'!$B$1:$U$1,0)),IF($A2<=1994,1000*INDEX('SALA 2002'!$B:$U,MATCH($A2,'SALA 2002'!$A:$A,0),MATCH(E$1,'SALA 2002'!$B$1:$U$1,0)),IF($A2<=2000,1000*INDEX('SALA 2002'!$B:$U,MATCH($A2,'SALA 2002'!$A:$A,0),MATCH(E$1,'SALA 2002'!$B$1:$U$1,0))*POWER(INDEX('WPP 2024 середина года'!$B:$U,MATCH($A2,'WPP 2024 середина года'!$A:$A,0),MATCH(E$1,'WPP 2024 середина года'!$B$1:$U$1,0))/(1000*INDEX('SALA 2002'!$B:$U,MATCH($A2,'SALA 2002'!$A:$A,0),MATCH(E$1,'SALA 2002'!$B$1:$U$1,0))),($A2-1994)/7),INDEX('WPP 2024 середина года'!$B:$U,MATCH($A2,'WPP 2024 середина года'!$A:$A,0),MATCH(E$1,'WPP 2024 середина года'!$B$1:$U$1,0))))) -> 2959 | F2: =IF($A2<=1947,INDEX('SALA 1974'!$B:$U,MATCH($A2,'SALA 1974'!$A:$A,0),MATCH(F$1,'SALA 1974'!$B$1:$U$1,0)),IF($A2<=1994,1000*INDEX('SALA 2002'!$B:$U,MATCH($A2,'SALA 2002'!$A:$A,0),MATCH(F$1,'SALA 2002'!$B$1:$U$1,0)),IF($A2<=2000,1000*INDEX('SALA 2002'!$B:$U,MATCH($A2,'SALA 2002'!$A:$A,0),MATCH(F$1,'SALA 2002'!$B$1:$U$1,0))*POWER(INDEX('WPP 2024 середина года'!$B:$U,MATCH($A2,'WPP 2024 середина года'!$A:$A,0),MATCH(F$1,'WPP 2024 середина года'!$B$1:$U$1,0))/(1000*INDEX('SALA 2002'!$B:$U,MATCH($A2,'SALA 2002'!$A:$A,0),MATCH(F$1,'SALA 2002'!$B$1:$U$1,0))),($A2-1994)/7),INDEX('WPP 2024 середина года'!$B:$U,MATCH($A2,'WPP 2024 середина года'!$A:$A,0),MATCH(F$1,'WPP 2024 середина года'!$B$1:$U$1,0))))) -> 3894 | G2: =IF($A2<=1951,INDEX('SALA 1974'!$B:$U,MATCH($A2,'SALA 1974'!$A:$A,0),MATCH(G$1,'SALA 1974'!$B$1:$U$1,0)),IF($A2<=1994,1000*INDEX('SALA 2002'!$B:$U,MATCH($A2,'SALA 2002'!$A:$A,0),MATCH(G$1,'SALA 2002'!$B$1:$U$1,0)),IF($A2<=2000,1000*INDEX('SALA 2002'!$B:$U,MATCH($A2,'SALA 2002'!$A:$A,0),MATCH(G$1,'SALA 2002'!$B$1:$U$1,0))*POWER(INDEX('WPP 2024 середина года'!$B:$U,MATCH($A2,'WPP 2024 середина года'!$A:$A,0),MATCH(G$1,'WPP 2024 середина года'!$B$1:$U$1,0))/(1000*INDEX('SALA 2002'!$B:$U,MATCH($A2,'SALA 2002'!$A:$A,0),MATCH(G$1,'SALA 2002'!$B$1:$U$1,0))),($A2-1994)/7),INDEX('WPP 2024 середина года'!$B:$U,MATCH($A2,'WPP 2024 середина года'!$A:$A,0),MATCH(G$1,'WPP 2024 середина года'!$B$1:$U$1,0))))) -> 307 | H2: =IF($A2<=1951,INDEX('SALA 1974'!$B:$U,MATCH($A2,'SALA 1974'!$A:$A,0),MATCH(H$1,'SALA 1974'!$B$1:$U$1,0)),IF($A2<=1994,1000*INDEX('SALA 2002'!$B:$U,MATCH($A2,'SALA 2002'!$A:$A,0),MATCH(H$1,'SALA 2002'!$B$1:$U$1,0)),IF($A2<=2000,1000*INDEX('SALA 2002'!$B:$U,MATCH($A2,'SALA 2002'!$A:$A,0),MATCH(H$1,'SALA 2002'!$B$1:$U$1,0))*POWER(INDEX('WPP 2024 середина года'!$B:$U,MATCH($A2,'WPP 2024 середина года'!$A:$A,0),MATCH(H$1,'WPP 2024 середина года'!$B$1:$U$1,0))/(1000*INDEX('SALA 2002'!$B:$U,MATCH($A2,'SALA 2002'!$A:$A,0),MATCH(H$1,'SALA 2002'!$B$1:$U$1,0))),($A2-1994)/7),INDEX('WPP 2024 середина года'!$B:$U,MATCH($A2,'WPP 2024 середина года'!$A:$A,0),MATCH(H$1,'WPP 2024 середина года'!$B$1:$U$1,0))))) -> 1600 | I2: =IF($A2<=1951,INDEX('SALA 1974'!$B:$U,MATCH($A2,'SALA 1974'!$A:$A,0),MATCH(I$1,'SALA 1974'!$B$1:$U$1,0)),IF($A2<=1994,1000*INDEX('SALA 2002'!$B:$U,MATCH($A2,'SALA 2002'!$A:$A,0),MATCH(I$1,'SALA 2002'!$B$1:$U$1,0)),IF($A2<=2000,1000*INDEX('SALA 2002'!$B:$U,MATCH($A2,'SALA 2002'!$A:$A,0),MATCH(I$1,'SALA 2002'!$B$1:$U$1,0))*POWER(INDEX('WPP 2024 середина года'!$B:$U,MATCH($A2,'WPP 2024 середина года'!$A:$A,0),MATCH(I$1,'WPP 2024 середина года'!$B$1:$U$1,0))/(1000*INDEX('SALA 2002'!$B:$U,MATCH($A2,'SALA 2002'!$A:$A,0),MATCH(I$1,'SALA 2002'!$B$1:$U$1,0))),($A2-1994)/7),INDEX('WPP 2024 середина года'!$B:$U,MATCH($A2,'WPP 2024 середина года'!$A:$A,0),MATCH(I$1,'WPP 2024 середина года'!$B$1:$U$1,0))))) -> 600 | J2: =IF($A2<=1951,INDEX('SALA 1974'!$B:$U,MATCH($A2,'SALA 1974'!$A:$A,0),MATCH(J$1,'SALA 1974'!$B$1:$U$1,0)),IF($A2<=1994,1000*INDEX('SALA 2002'!$B:$U,MATCH($A2,'SALA 2002'!$A:$A,0),MATCH(J$1,'SALA 2002'!$B$1:$U$1,0)),IF($A2<=2000,1000*INDEX('SALA 2002'!$B:$U,MATCH($A2,'SALA 2002'!$A:$A,0),MATCH(J$1,'SALA 2002'!$B$1:$U$1,0))*POWER(INDEX('WPP 2024 середина года'!$B:$U,MATCH($A2,'WPP 2024 середина года'!$A:$A,0),MATCH(J$1,'WPP 2024 середина года'!$B$1:$U$1,0))/(1000*INDEX('SALA 2002'!$B:$U,MATCH($A2,'SALA 2002'!$A:$A,0),MATCH(J$1,'SALA 2002'!$B$1:$U$1,0))),($A2-1994)/7),INDEX('WPP 2024 середина года'!$B:$U,MATCH($A2,'WPP 2024 середина года'!$A:$A,0),MATCH(J$1,'WPP 2024 середина года'!$B$1:$U$1,0))))) -> 1300 | K2: =IF($A2<=1951,INDEX('SALA 1974'!$B:$U,MATCH($A2,'SALA 1974'!$A:$A,0),MATCH(K$1,'SALA 1974'!$B$1:$U$1,0)),IF($A2<=1994,1000*INDEX('SALA 2002'!$B:$U,MATCH($A2,'SALA 2002'!$A:$A,0),MATCH(K$1,'SALA 2002'!$B$1:$U$1,0)),IF($A2<=2000,1000*INDEX('SALA 2002'!$B:$U,MATCH($A2,'SALA 2002'!$A:$A,0),MATCH(K$1,'SALA 2002'!$B$1:$U$1,0))*POWER(INDEX('WPP 2024 середина года'!$B:$U,MATCH($A2,'WPP 2024 середина года'!$A:$A,0),MATCH(K$1,'WPP 2024 середина года'!$B$1:$U$1,0))/(1000*INDEX('SALA 2002'!$B:$U,MATCH($A2,'SALA 2002'!$A:$A,0),MATCH(K$1,'SALA 2002'!$B$1:$U$1,0))),($A2-1994)/7),INDEX('WPP 2024 середина года'!$B:$U,MATCH($A2,'WPP 2024 середина года'!$A:$A,0),MATCH(K$1,'WPP 2024 середина года'!$B$1:$U$1,0))))) -> 801 | L2: =IF($A2<=1951,INDEX('SALA 1974'!$B:$U,MATCH($A2,'SALA 1974'!$A:$A,0),MATCH(L$1,'SALA 1974'!$B$1:$U$1,0)),IF($A2<=1994,1000*INDEX('SALA 2002'!$B:$U,MATCH($A2,'SALA 2002'!$A:$A,0),MATCH(L$1,'SALA 2002'!$B$1:$U$1,0)),IF($A2<=2000,1000*INDEX('SALA 2002'!$B:$U,MATCH($A2,'SALA 2002'!$A:$A,0),MATCH(L$1,'SALA 2002'!$B$1:$U$1,0))*POWER(INDEX('WPP 2024 середина года'!$B:$U,MATCH($A2,'WPP 2024 середина года'!$A:$A,0),MATCH(L$1,'WPP 2024 середина года'!$B$1:$U$1,0))/(1000*INDEX('SALA 2002'!$B:$U,MATCH($A2,'SALA 2002'!$A:$A,0),MATCH(L$1,'SALA 2002'!$B$1:$U$1,0))),($A2-1994)/7),INDEX('WPP 2024 середина года'!$B:$U,MATCH($A2,'WPP 2024 середина года'!$A:$A,0),MATCH(L$1,'WPP 2024 середина года'!$B$1:$U$1,0))))) -> 885 | M2: =IF($A2<=1951,INDEX('SALA 1974'!$B:$U,MATCH($A2,'SALA 1974'!$A:$A,0),MATCH(M$1,'SALA 1974'!$B$1:$U$1,0)),IF($A2<=1994,1000*INDEX('SALA 2002'!$B:$U,MATCH($A2,'SALA 2002'!$A:$A,0),MATCH(M$1,'SALA 2002'!$B$1:$U$1,0)),IF($A2<=2000,1000*INDEX('SALA 2002'!$B:$U,MATCH($A2,'SALA 2002'!$A:$A,0),MATCH(M$1,'SALA 2002'!$B$1:$U$1,0))*POWER(INDEX('WPP 2024 середина года'!$B:$U,MATCH($A2,'WPP 2024 середина года'!$A:$A,0),MATCH(M$1,'WPP 2024 середина года'!$B$1:$U$1,0))/(1000*INDEX('SALA 2002'!$B:$U,MATCH($A2,'SALA 2002'!$A:$A,0),MATCH(M$1,'SALA 2002'!$B$1:$U$1,0))),($A2-1994)/7),INDEX('WPP 2024 середина года'!$B:$U,MATCH($A2,'WPP 2024 середина года'!$A:$A,0),MATCH(M$1,'WPP 2024 середина года'!$B$1:$U$1,0))))) -> 1250 | N2: =IF($A2<=1951,INDEX('SALA 1974'!$B:$U,MATCH($A2,'SALA 1974'!$A:$A,0),MATCH(N$1,'SALA 1974'!$B$1:$U$1,0)),IF($A2<=1994,1000*INDEX('SALA 2002'!$B:$U,MATCH($A2,'SALA 2002'!$A:$A,0),MATCH(N$1,'SALA 2002'!$B$1:$U$1,0)),IF($A2<=2000,1000*INDEX('SALA 2002'!$B:$U,MATCH($A2,'SALA 2002'!$A:$A,0),MATCH(N$1,'SALA 2002'!$B$1:$U$1,0))*POWER(INDEX('WPP 2024 середина года'!$B:$U,MATCH($A2,'WPP 2024 середина года'!$A:$A,0),MATCH(N$1,'WPP 2024 середина года'!$B$1:$U$1,0))/(1000*INDEX('SALA 2002'!$B:$U,MATCH($A2,'SALA 2002'!$A:$A,0),MATCH(N$1,'SALA 2002'!$B$1:$U$1,0))),($A2-1994)/7),INDEX('WPP 2024 середина года'!$B:$U,MATCH($A2,'WPP 2024 середина года'!$A:$A,0),MATCH(N$1,'WPP 2024 середина года'!$B$1:$U$1,0))))) -> 420 | ... U2: =IF($A2<=1951,INDEX('SALA 1974'!$B:$U,MATCH($A2,'SALA 1974'!$A:$A,0),MATCH(U$1,'SALA 1974'!$B$1:$U$1,0)),IF($A2<=1994,1000*INDEX('SALA 2002'!$B:$U,MATCH($A2,'SALA 2002'!$A:$A,0),MATCH(U$1,'SALA 2002'!$B$1:$U$1,0)),IF($A2<=2000,1000*INDEX('SALA 2002'!$B:$U,MATCH($A2,'SALA 2002'!$A:$A,0),MATCH(U$1,'SALA 2002'!$B$1:$U$1,0))*POWER(INDEX('WPP 2024 середина года'!$B:$U,MATCH($A2,'WPP 2024 середина года'!$A:$A,0),MATCH(U$1,'WPP 2024 середина года'!$B$1:$U$1,0))/(1000*INDEX('SALA 2002'!$B:$U,MATCH($A2,'SALA 2002'!$A:$A,0),MATCH(U$1,'SALA 2002'!$B$1:$U$1,0))),($A2-1994)/7),INDEX('WPP 2024 середина года'!$B:$U,MATCH($A2,'WPP 2024 середина года'!$A:$A,0),MATCH(U$1,'WPP 2024 середина года'!$B$1:$U$1,0))))) -> 2445
A3: =A2+1 -> 1901 | B3: =IF($A3<=1951,INDEX('SALA 1974'!$B:$U,MATCH($A3,'SALA 1974'!$A:$A,0),MATCH(B$1,'SALA 1974'!$B$1:$U$1,0)),IF($A3<=1994,1000*INDEX('SALA 2002'!$B:$U,MATCH($A3,'SALA 2002'!$A:$A,0),MATCH(B$1,'SALA 2002'!$B$1:$U$1,0)),IF($A3<=2000,1000*INDEX('SALA 2002'!$B:$U,MATCH($A3,'SALA 2002'!$A:$A,0),MATCH(B$1,'SALA 2002'!$B$1:$U$1,0))*POWER(INDEX('WPP 2024 середина года'!$B:$U,MATCH($A3,'WPP 2024 середина года'!$A:$A,0),MATCH(B$1,'WPP 2024 середина года'!$B$1:$U$1,0))/(1000*INDEX('SALA 2002'!$B:$U,MATCH($A3,'SALA 2002'!$A:$A,0),MATCH(B$1,'SALA 2002'!$B$1:$U$1,0))),($A3-1994)/7),INDEX('WPP 2024 середина года'!$B:$U,MATCH($A3,'WPP 2024 середина года'!$A:$A,0),MATCH(B$1,'WPP 2024 середина года'!$B$1:$U$1,0))))) -> 4741 | C3: =IF($A3<=1951,INDEX('SALA 1974'!$B:$U,MATCH($A3,'SALA 1974'!$A:$A,0),MATCH(C$1,'SALA 1974'!$B$1:$U$1,0)),IF($A3<=1994,1000*INDEX('SALA 2002'!$B:$U,MATCH($A3,'SALA 2002'!$A:$A,0),MATCH(C$1,'SALA 2002'!$B$1:$U$1,0)),IF($A3<=2000,1000*INDEX('SALA 2002'!$B:$U,MATCH($A3,'SALA 2002'!$A:$A,0),MATCH(C$1,'SALA 2002'!$B$1:$U$1,0))*POWER(INDEX('WPP 2024 середина года'!$B:$U,MATCH($A3,'WPP 2024 середина года'!$A:$A,0),MATCH(C$1,'WPP 2024 середина года'!$B$1:$U$1,0))/(1000*INDEX('SALA 2002'!$B:$U,MATCH($A3,'SALA 2002'!$A:$A,0),MATCH(C$1,'SALA 2002'!$B$1:$U$1,0))),($A3-1994)/7),INDEX('WPP 2024 середина года'!$B:$U,MATCH($A3,'WPP 2024 середина года'!$A:$A,0),MATCH(C$1,'WPP 2024 середина года'!$B$1:$U$1,0))))) -> 1785 | D3: =IF($A3<=1951,INDEX('SALA 1974'!$B:$U,MATCH($A3,'SALA 1974'!$A:$A,0),MATCH(D$1,'SALA 1974'!$B$1:$U$1,0)),IF($A3<=1994,1000*INDEX('SALA 2002'!$B:$U,MATCH($A3,'SALA 2002'!$A:$A,0),MATCH(D$1,'SALA 2002'!$B$1:$U$1,0)),IF($A3<=2000,1000*INDEX('SALA 2002'!$B:$U,MATCH($A3,'SALA 2002'!$A:$A,0),MATCH(D$1,'SALA 2002'!$B$1:$U$1,0))*POWER(INDEX('WPP 2024 середина года'!$B:$U,MATCH($A3,'WPP 2024 середина года'!$A:$A,0),MATCH(D$1,'WPP 2024 середина года'!$B$1:$U$1,0))/(1000*INDEX('SALA 2002'!$B:$U,MATCH($A3,'SALA 2002'!$A:$A,0),MATCH(D$1,'SALA 2002'!$B$1:$U$1,0))),($A3-1994)/7),INDEX('WPP 2024 середина года'!$B:$U,MATCH($A3,'WPP 2024 середина года'!$A:$A,0),MATCH(D$1,'WPP 2024 середина года'!$B$1:$U$1,0))))) -> 18392 | E3: =IF($A3<=1951,INDEX('SALA 1974'!$B:$U,MATCH($A3,'SALA 1974'!$A:$A,0),MATCH(E$1,'SALA 1974'!$B$1:$U$1,0)),IF($A3<=1994,1000*INDEX('SALA 2002'!$B:$U,MATCH($A3,'SALA 2002'!$A:$A,0),MATCH(E$1,'SALA 2002'!$B$1:$U$1,0)),IF($A3<=2000,1000*INDEX('SALA 2002'!$B:$U,MATCH($A3,'SALA 2002'!$A:$A,0),MATCH(E$1,'SALA 2002'!$B$1:$U$1,0))*POWER(INDEX('WPP 2024 середина года'!$B:$U,MATCH($A3,'WPP 2024 середина года'!$A:$A,0),MATCH(E$1,'WPP 2024 середина года'!$B$1:$U$1,0))/(1000*INDEX('SALA 2002'!$B:$U,MATCH($A3,'SALA 2002'!$A:$A,0),MATCH(E$1,'SALA 2002'!$B$1:$U$1,0))),($A3-1994)/7),INDEX('WPP 2024 середина года'!$B:$U,MATCH($A3,'WPP 2024 середина года'!$A:$A,0),MATCH(E$1,'WPP 2024 середина года'!$B$1:$U$1,0))))) -> 2994 | F3: =IF($A3<=1947,INDEX('SALA 1974'!$B:$U,MATCH($A3,'SALA 1974'!$A:$A,0),MATCH(F$1,'SALA 1974'!$B$1:$U$1,0)),IF($A3<=1994,1000*INDEX('SALA 2002'!$B:$U,MATCH($A3,'SALA 2002'!$A:$A,0),MATCH(F$1,'SALA 2002'!$B$1:$U$1,0)),IF($A3<=2000,1000*INDEX('SALA 2002'!$B:$U,MATCH($A3,'SALA 2002'!$A:$A,0),MATCH(F$1,'SALA 2002'!$B$1:$U$1,0))*POWER(INDEX('WPP 2024 середина года'!$B:$U,MATCH($A3,'WPP 2024 середина года'!$A:$A,0),MATCH(F$1,'WPP 2024 середина года'!$B$1:$U$1,0))/(1000*INDEX('SALA 2002'!$B:$U,MATCH($A3,'SALA 2002'!$A:$A,0),MATCH(F$1,'SALA 2002'!$B$1:$U$1,0))),($A3-1994)/7),INDEX('WPP 2024 середина года'!$B:$U,MATCH($A3,'WPP 2024 середина года'!$A:$A,0),MATCH(F$1,'WPP 2024 середина года'!$B$1:$U$1,0))))) -> 3944 | G3: =IF($A3<=1951,INDEX('SALA 1974'!$B:$U,MATCH($A3,'SALA 1974'!$A:$A,0),MATCH(G$1,'SALA 1974'!$B$1:$U$1,0)),IF($A3<=1994,1000*INDEX('SALA 2002'!$B:$U,MATCH($A3,'SALA 2002'!$A:$A,0),MATCH(G$1,'SALA 2002'!$B$1:$U$1,0)),IF($A3<=2000,1000*INDEX('SALA 2002'!$B:$U,MATCH($A3,'SALA 2002'!$A:$A,0),MATCH(G$1,'SALA 2002'!$B$1:$U$1,0))*POWER(INDEX('WPP 2024 середина года'!$B:$U,MATCH($A3,'WPP 2024 середина года'!$A:$A,0),MATCH(G$1,'WPP 2024 середина года'!$B$1:$U$1,0))/(1000*INDEX('SALA 2002'!$B:$U,MATCH($A3,'SALA 2002'!$A:$A,0),MATCH(G$1,'SALA 2002'!$B$1:$U$1,0))),($A3-1994)/7),INDEX('WPP 2024 середина года'!$B:$U,MATCH($A3,'WPP 2024 середина года'!$A:$A,0),MATCH(G$1,'WPP 2024 середина года'!$B$1:$U$1,0))))) -> 313 | H3: =IF($A3<=1951,INDEX('SALA 1974'!$B:$U,MATCH($A3,'SALA 1974'!$A:$A,0),MATCH(H$1,'SALA 1974'!$B$1:$U$1,0)),IF($A3<=1994,1000*INDEX('SALA 2002'!$B:$U,MATCH($A3,'SALA 2002'!$A:$A,0),MATCH(H$1,'SALA 2002'!$B$1:$U$1,0)),IF($A3<=2000,1000*INDEX('SALA 2002'!$B:$U,MATCH($A3,'SALA 2002'!$A:$A,0),MATCH(H$1,'SALA 2002'!$B$1:$U$1,0))*POWER(INDEX('WPP 2024 середина года'!$B:$U,MATCH($A3,'WPP 2024 середина года'!$A:$A,0),MATCH(H$1,'WPP 2024 середина года'!$B$1:$U$1,0))/(1000*INDEX('SALA 2002'!$B:$U,MATCH($A3,'SALA 2002'!$A:$A,0),MATCH(H$1,'SALA 2002'!$B$1:$U$1,0))),($A3-1994)/7),INDEX('WPP 2024 середина года'!$B:$U,MATCH($A3,'WPP 2024 середина года'!$A:$A,0),MATCH(H$1,'WPP 2024 середина года'!$B$1:$U$1,0))))) -> 1679 | I3: =IF($A3<=1951,INDEX('SALA 1974'!$B:$U,MATCH($A3,'SALA 1974'!$A:$A,0),MATCH(I$1,'SALA 1974'!$B$1:$U$1,0)),IF($A3<=1994,1000*INDEX('SALA 2002'!$B:$U,MATCH($A3,'SALA 2002'!$A:$A,0),MATCH(I$1,'SALA 2002'!$B$1:$U$1,0)),IF($A3<=2000,1000*INDEX('SALA 2002'!$B:$U,MATCH($A3,'SALA 2002'!$A:$A,0),MATCH(I$1,'SALA 2002'!$B$1:$U$1,0))*POWER(INDEX('WPP 2024 середина года'!$B:$U,MATCH($A3,'WPP 2024 середина года'!$A:$A,0),MATCH(I$1,'WPP 2024 середина года'!$B$1:$U$1,0))/(1000*INDEX('SALA 2002'!$B:$U,MATCH($A3,'SALA 2002'!$A:$A,0),MATCH(I$1,'SALA 2002'!$B$1:$U$1,0))),($A3-1994)/7),INDEX('WPP 2024 середина года'!$B:$U,MATCH($A3,'WPP 2024 середина года'!$A:$A,0),MATCH(I$1,'WPP 2024 середина года'!$B$1:$U$1,0))))) -> 614 | J3: =IF($A3<=1951,INDEX('SALA 1974'!$B:$U,MATCH($A3,'SALA 1974'!$A:$A,0),MATCH(J$1,'SALA 1974'!$B$1:$U$1,0)),IF($A3<=1994,1000*INDEX('SALA 2002'!$B:$U,MATCH($A3,'SALA 2002'!$A:$A,0),MATCH(J$1,'SALA 2002'!$B$1:$U$1,0)),IF($A3<=2000,1000*INDEX('SALA 2002'!$B:$U,MATCH($A3,'SALA 2002'!$A:$A,0),MATCH(J$1,'SALA 2002'!$B$1:$U$1,0))*POWER(INDEX('WPP 2024 середина года'!$B:$U,MATCH($A3,'WPP 2024 середина года'!$A:$A,0),MATCH(J$1,'WPP 2024 середина года'!$B$1:$U$1,0))/(1000*INDEX('SALA 2002'!$B:$U,MATCH($A3,'SALA 2002'!$A:$A,0),MATCH(J$1,'SALA 2002'!$B$1:$U$1,0))),($A3-1994)/7),INDEX('WPP 2024 середина года'!$B:$U,MATCH($A3,'WPP 2024 середина года'!$A:$A,0),MATCH(J$1,'WPP 2024 середина года'!$B$1:$U$1,0))))) -> 1312 | K3: =IF($A3<=1951,INDEX('SALA 1974'!$B:$U,MATCH($A3,'SALA 1974'!$A:$A,0),MATCH(K$1,'SALA 1974'!$B$1:$U$1,0)),IF($A3<=1994,1000*INDEX('SALA 2002'!$B:$U,MATCH($A3,'SALA 2002'!$A:$A,0),MATCH(K$1,'SALA 2002'!$B$1:$U$1,0)),IF($A3<=2000,1000*INDEX('SALA 2002'!$B:$U,MATCH($A3,'SALA 2002'!$A:$A,0),MATCH(K$1,'SALA 2002'!$B$1:$U$1,0))*POWER(INDEX('WPP 2024 середина года'!$B:$U,MATCH($A3,'WPP 2024 середина года'!$A:$A,0),MATCH(K$1,'WPP 2024 середина года'!$B$1:$U$1,0))/(1000*INDEX('SALA 2002'!$B:$U,MATCH($A3,'SALA 2002'!$A:$A,0),MATCH(K$1,'SALA 2002'!$B$1:$U$1,0))),($A3-1994)/7),INDEX('WPP 2024 середина года'!$B:$U,MATCH($A3,'WPP 2024 середина года'!$A:$A,0),MATCH(K$1,'WPP 2024 середина года'!$B$1:$U$1,0))))) -> 819 | L3: =IF($A3<=1951,INDEX('SALA 1974'!$B:$U,MATCH($A3,'SALA 1974'!$A:$A,0),MATCH(L$1,'SALA 1974'!$B$1:$U$1,0)),IF($A3<=1994,1000*INDEX('SALA 2002'!$B:$U,MATCH($A3,'SALA 2002'!$A:$A,0),MATCH(L$1,'SALA 2002'!$B$1:$U$1,0)),IF($A3<=2000,1000*INDEX('SALA 2002'!$B:$U,MATCH($A3,'SALA 2002'!$A:$A,0),MATCH(L$1,'SALA 2002'!$B$1:$U$1,0))*POWER(INDEX('WPP 2024 середина года'!$B:$U,MATCH($A3,'WPP 2024 середина года'!$A:$A,0),MATCH(L$1,'WPP 2024 середина года'!$B$1:$U$1,0))/(1000*INDEX('SALA 2002'!$B:$U,MATCH($A3,'SALA 2002'!$A:$A,0),MATCH(L$1,'SALA 2002'!$B$1:$U$1,0))),($A3-1994)/7),INDEX('WPP 2024 середина года'!$B:$U,MATCH($A3,'WPP 2024 середина года'!$A:$A,0),MATCH(L$1,'WPP 2024 середина года'!$B$1:$U$1,0))))) -> 910 | M3: =IF($A3<=1951,INDEX('SALA 1974'!$B:$U,MATCH($A3,'SALA 1974'!$A:$A,0),MATCH(M$1,'SALA 1974'!$B$1:$U$1,0)),IF($A3<=1994,1000*INDEX('SALA 2002'!$B:$U,MATCH($A3,'SALA 2002'!$A:$A,0),MATCH(M$1,'SALA 2002'!$B$1:$U$1,0)),IF($A3<=2000,1000*INDEX('SALA 2002'!$B:$U,MATCH($A3,'SALA 2002'!$A:$A,0),MATCH(M$1,'SALA 2002'!$B$1:$U$1,0))*POWER(INDEX('WPP 2024 середина года'!$B:$U,MATCH($A3,'WPP 2024 середина года'!$A:$A,0),MATCH(M$1,'WPP 2024 середина года'!$B$1:$U$1,0))/(1000*INDEX('SALA 2002'!$B:$U,MATCH($A3,'SALA 2002'!$A:$A,0),MATCH(M$1,'SALA 2002'!$B$1:$U$1,0))),($A3-1994)/7),INDEX('WPP 2024 середина года'!$B:$U,MATCH($A3,'WPP 2024 середина года'!$A:$A,0),MATCH(M$1,'WPP 2024 середина года'!$B$1:$U$1,0))))) -> 1294 | N3: =IF($A3<=1951,INDEX('SALA 1974'!$B:$U,MATCH($A3,'SALA 1974'!$A:$A,0),MATCH(N$1,'SALA 1974'!$B$1:$U$1,0)),IF($A3<=1994,1000*INDEX('SALA 2002'!$B:$U,MATCH($A3,'SALA 2002'!$A:$A,0),MATCH(N$1,'SALA 2002'!$B$1:$U$1,0)),IF($A3<=2000,1000*INDEX('SALA 2002'!$B:$U,MATCH($A3,'SALA 2002'!$A:$A,0),MATCH(N$1,'SALA 2002'!$B$1:$U$1,0))*POWER(INDEX('WPP 2024 середина года'!$B:$U,MATCH($A3,'WPP 2024 середина года'!$A:$A,0),MATCH(N$1,'WPP 2024 середина года'!$B$1:$U$1,0))/(1000*INDEX('SALA 2002'!$B:$U,MATCH($A3,'SALA 2002'!$A:$A,0),MATCH(N$1,'SALA 2002'!$B$1:$U$1,0))),($A3-1994)/7),INDEX('WPP 2024 середина года'!$B:$U,MATCH($A3,'WPP 2024 середина года'!$A:$A,0),MATCH(N$1,'WPP 2024 середина года'!$B$1:$U$1,0))))) -> 436 | ... U3: =IF($A3<=1951,INDEX('SALA 1974'!$B:$U,MATCH($A3,'SALA 1974'!$A:$A,0),MATCH(U$1,'SALA 1974'!$B$1:$U$1,0)),IF($A3<=1994,1000*INDEX('SALA 2002'!$B:$U,MATCH($A3,'SALA 2002'!$A:$A,0),MATCH(U$1,'SALA 2002'!$B$1:$U$1,0)),IF($A3<=2000,1000*INDEX('SALA 2002'!$B:$U,MATCH($A3,'SALA 2002'!$A:$A,0),MATCH(U$1,'SALA 2002'!$B$1:$U$1,0))*POWER(INDEX('WPP 2024 середина года'!$B:$U,MATCH($A3,'WPP 2024 середина года'!$A:$A,0),MATCH(U$1,'WPP 2024 середина года'!$B$1:$U$1,0))/(1000*INDEX('SALA 2002'!$B:$U,MATCH($A3,'SALA 2002'!$A:$A,0),MATCH(U$1,'SALA 2002'!$B$1:$U$1,0))),($A3-1994)/7),INDEX('WPP 2024 середина года'!$B:$U,MATCH($A3,'WPP 2024 середина года'!$A:$A,0),MATCH(U$1,'WPP 2024 середина года'!$B$1:$U$1,0))))) -> 2451
A4: =A3+1 -> 1902 | B4: =IF($A4<=1951,INDEX('SALA 1974'!$B:$U,MATCH($A4,'SALA 1974'!$A:$A,0),MATCH(B$1,'SALA 1974'!$B$1:$U$1,0)),IF($A4<=1994,1000*INDEX('SALA 2002'!$B:$U,MATCH($A4,'SALA 2002'!$A:$A,0),MATCH(B$1,'SALA 2002'!$B$1:$U$1,0)),IF($A4<=2000,1000*INDEX('SALA 2002'!$B:$U,MATCH($A4,'SALA 2002'!$A:$A,0),MATCH(B$1,'SALA 2002'!$B$1:$U$1,0))*POWER(INDEX('WPP 2024 середина года'!$B:$U,MATCH($A4,'WPP 2024 середина года'!$A:$A,0),MATCH(B$1,'WPP 2024 середина года'!$B$1:$U$1,0))/(1000*INDEX('SALA 2002'!$B:$U,MATCH($A4,'SALA 2002'!$A:$A,0),MATCH(B$1,'SALA 2002'!$B$1:$U$1,0))),($A4-1994)/7),INDEX('WPP 2024 середина года'!$B:$U,MATCH($A4,'WPP 2024 середина года'!$A:$A,0),MATCH(B$1,'WPP 2024 середина года'!$B$1:$U$1,0))))) -> 4872 | C4: =IF($A4<=1951,INDEX('SALA 1974'!$B:$U,MATCH($A4,'SALA 1974'!$A:$A,0),MATCH(C$1,'SALA 1974'!$B$1:$U$1,0)),IF($A4<=1994,1000*INDEX('SALA 2002'!$B:$U,MATCH($A4,'SALA 2002'!$A:$A,0),MATCH(C$1,'SALA 2002'!$B$1:$U$1,0)),IF($A4<=2000,1000*INDEX('SALA 2002'!$B:$U,MATCH($A4,'SALA 2002'!$A:$A,0),MATCH(C$1,'SALA 2002'!$B$1:$U$1,0))*POWER(INDEX('WPP 2024 середина года'!$B:$U,MATCH($A4,'WPP 2024 середина года'!$A:$A,0),MATCH(C$1,'WPP 2024 середина года'!$B$1:$U$1,0))/(1000*INDEX('SALA 2002'!$B:$U,MATCH($A4,'SALA 2002'!$A:$A,0),MATCH(C$1,'SALA 2002'!$B$1:$U$1,0))),($A4-1994)/7),INDEX('WPP 2024 середина года'!$B:$U,MATCH($A4,'WPP 2024 середина года'!$A:$A,0),MATCH(C$1,'WPP 2024 середина года'!$B$1:$U$1,0))))) -> 1803 | D4: =IF($A4<=1951,INDEX('SALA 1974'!$B:$U,MATCH($A4,'SALA 1974'!$A:$A,0),MATCH(D$1,'SALA 1974'!$B$1:$U$1,0)),IF($A4<=1994,1000*INDEX('SALA 2002'!$B:$U,MATCH($A4,'SALA 2002'!$A:$A,0),MATCH(D$1,'SALA 2002'!$B$1:$U$1,0)),IF($A4<=2000,1000*INDEX('SALA 2002'!$B:$U,MATCH($A4,'SALA 2002'!$A:$A,0),MATCH(D$1,'SALA 2002'!$B$1:$U$1,0))*POWER(INDEX('WPP 2024 середина года'!$B:$U,MATCH($A4,'WPP 2024 середина года'!$A:$A,0),MATCH(D$1,'WPP 2024 середина года'!$B$1:$U$1,0))/(1000*INDEX('SALA 2002'!$B:$U,MATCH($A4,'SALA 2002'!$A:$A,0),MATCH(D$1,'SALA 2002'!$B$1:$U$1,0))),($A4-1994)/7),INDEX('WPP 2024 середина года'!$B:$U,MATCH($A4,'WPP 2024 середина года'!$A:$A,0),MATCH(D$1,'WPP 2024 середина года'!$B$1:$U$1,0))))) -> 18782 | E4: =IF($A4<=1951,INDEX('SALA 1974'!$B:$U,MATCH($A4,'SALA 1974'!$A:$A,0),MATCH(E$1,'SALA 1974'!$B$1:$U$1,0)),IF($A4<=1994,1000*INDEX('SALA 2002'!$B:$U,MATCH($A4,'SALA 2002'!$A:$A,0),MATCH(E$1,'SALA 2002'!$B$1:$U$1,0)),IF($A4<=2000,1000*INDEX('SALA 2002'!$B:$U,MATCH($A4,'SALA 2002'!$A:$A,0),MATCH(E$1,'SALA 2002'!$B$1:$U$1,0))*POWER(INDEX('WPP 2024 середина года'!$B:$U,MATCH($A4,'WPP 2024 середина года'!$A:$A,0),MATCH(E$1,'WPP 2024 середина года'!$B$1:$U$1,0))/(1000*INDEX('SALA 2002'!$B:$U,MATCH($A4,'SALA 2002'!$A:$A,0),MATCH(E$1,'SALA 2002'!$B$1:$U$1,0))),($A4-1994)/7),INDEX('WPP 2024 середина года'!$B:$U,MATCH($A4,'WPP 2024 середина года'!$A:$A,0),MATCH(E$1,'WPP 2024 середина года'!$B$1:$U$1,0))))) -> 3030 | F4: =IF($A4<=1947,INDEX('SALA 1974'!$B:$U,MATCH($A4,'SALA 1974'!$A:$A,0),MATCH(F$1,'SALA 1974'!$B$1:$U$1,0)),IF($A4<=1994,1000*INDEX('SALA 2002'!$B:$U,MATCH($A4,'SALA 2002'!$A:$A,0),MATCH(F$1,'SALA 2002'!$B$1:$U$1,0)),IF($A4<=2000,1000*INDEX('SALA 2002'!$B:$U,MATCH($A4,'SALA 2002'!$A:$A,0),MATCH(F$1,'SALA 2002'!$B$1:$U$1,0))*POWER(INDEX('WPP 2024 середина года'!$B:$U,MATCH($A4,'WPP 2024 середина года'!$A:$A,0),MATCH(F$1,'WPP 2024 середина года'!$B$1:$U$1,0))/(1000*INDEX('SALA 2002'!$B:$U,MATCH($A4,'SALA 2002'!$A:$A,0),MATCH(F$1,'SALA 2002'!$B$1:$U$1,0))),($A4-1994)/7),INDEX('WPP 2024 середина года'!$B:$U,MATCH($A4,'WPP 2024 середина года'!$A:$A,0),MATCH(F$1,'WPP 2024 середина года'!$B$1:$U$1,0))))) -> 3994 | G4: =IF($A4<=1951,INDEX('SALA 1974'!$B:$U,MATCH($A4,'SALA 1974'!$A:$A,0),MATCH(G$1,'SALA 1974'!$B$1:$U$1,0)),IF($A4<=1994,1000*INDEX('SALA 2002'!$B:$U,MATCH($A4,'SALA 2002'!$A:$A,0),MATCH(G$1,'SALA 2002'!$B$1:$U$1,0)),IF($A4<=2000,1000*INDEX('SALA 2002'!$B:$U,MATCH($A4,'SALA 2002'!$A:$A,0),MATCH(G$1,'SALA 2002'!$B$1:$U$1,0))*POWER(INDEX('WPP 2024 середина года'!$B:$U,MATCH($A4,'WPP 2024 середина года'!$A:$A,0),MATCH(G$1,'WPP 2024 середина года'!$B$1:$U$1,0))/(1000*INDEX('SALA 2002'!$B:$U,MATCH($A4,'SALA 2002'!$A:$A,0),MATCH(G$1,'SALA 2002'!$B$1:$U$1,0))),($A4-1994)/7),INDEX('WPP 2024 середина года'!$B:$U,MATCH($A4,'WPP 2024 середина года'!$A:$A,0),MATCH(G$1,'WPP 2024 середина года'!$B$1:$U$1,0))))) -> 318 | H4: =IF($A4<=1951,INDEX('SALA 1974'!$B:$U,MATCH($A4,'SALA 1974'!$A:$A,0),MATCH(H$1,'SALA 1974'!$B$1:$U$1,0)),IF($A4<=1994,1000*INDEX('SALA 2002'!$B:$U,MATCH($A4,'SALA 2002'!$A:$A,0),MATCH(H$1,'SALA 2002'!$B$1:$U$1,0)),IF($A4<=2000,1000*INDEX('SALA 2002'!$B:$U,MATCH($A4,'SALA 2002'!$A:$A,0),MATCH(H$1,'SALA 2002'!$B$1:$U$1,0))*POWER(INDEX('WPP 2024 середина года'!$B:$U,MATCH($A4,'WPP 2024 середина года'!$A:$A,0),MATCH(H$1,'WPP 2024 середина года'!$B$1:$U$1,0))/(1000*INDEX('SALA 2002'!$B:$U,MATCH($A4,'SALA 2002'!$A:$A,0),MATCH(H$1,'SALA 2002'!$B$1:$U$1,0))),($A4-1994)/7),INDEX('WPP 2024 середина года'!$B:$U,MATCH($A4,'WPP 2024 середина года'!$A:$A,0),MATCH(H$1,'WPP 2024 середина года'!$B$1:$U$1,0))))) -> 1758 | I4: =IF($A4<=1951,INDEX('SALA 1974'!$B:$U,MATCH($A4,'SALA 1974'!$A:$A,0),MATCH(I$1,'SALA 1974'!$B$1:$U$1,0)),IF($A4<=1994,1000*INDEX('SALA 2002'!$B:$U,MATCH($A4,'SALA 2002'!$A:$A,0),MATCH(I$1,'SALA 2002'!$B$1:$U$1,0)),IF($A4<=2000,1000*INDEX('SALA 2002'!$B:$U,MATCH($A4,'SALA 2002'!$A:$A,0),MATCH(I$1,'SALA 2002'!$B$1:$U$1,0))*POWER(INDEX('WPP 2024 середина года'!$B:$U,MATCH($A4,'WPP 2024 середина года'!$A:$A,0),MATCH(I$1,'WPP 2024 середина года'!$B$1:$U$1,0))/(1000*INDEX('SALA 2002'!$B:$U,MATCH($A4,'SALA 2002'!$A:$A,0),MATCH(I$1,'SALA 2002'!$B$1:$U$1,0))),($A4-1994)/7),INDEX('WPP 2024 середина года'!$B:$U,MATCH($A4,'WPP 2024 середина года'!$A:$A,0),MATCH(I$1,'WPP 2024 середина года'!$B$1:$U$1,0))))) -> 628 | J4: =IF($A4<=1951,INDEX('SALA 1974'!$B:$U,MATCH($A4,'SALA 1974'!$A:$A,0),MATCH(J$1,'SALA 1974'!$B$1:$U$1,0)),IF($A4<=1994,1000*INDEX('SALA 2002'!$B:$U,MATCH($A4,'SALA 2002'!$A:$A,0),MATCH(J$1,'SALA 2002'!$B$1:$U$1,0)),IF($A4<=2000,1000*INDEX('SALA 2002'!$B:$U,MATCH($A4,'SALA 2002'!$A:$A,0),MATCH(J$1,'SALA 2002'!$B$1:$U$1,0))*POWER(INDEX('WPP 2024 середина года'!$B:$U,MATCH($A4,'WPP 2024 середина года'!$A:$A,0),MATCH(J$1,'WPP 2024 середина года'!$B$1:$U$1,0))/(1000*INDEX('SALA 2002'!$B:$U,MATCH($A4,'SALA 2002'!$A:$A,0),MATCH(J$1,'SALA 2002'!$B$1:$U$1,0))),($A4-1994)/7),INDEX('WPP 2024 середина года'!$B:$U,MATCH($A4,'WPP 2024 середина года'!$A:$A,0),MATCH(J$1,'WPP 2024 середина года'!$B$1:$U$1,0))))) -> 1324 | K4: =IF($A4<=1951,INDEX('SALA 1974'!$B:$U,MATCH($A4,'SALA 1974'!$A:$A,0),MATCH(K$1,'SALA 1974'!$B$1:$U$1,0)),IF($A4<=1994,1000*INDEX('SALA 2002'!$B:$U,MATCH($A4,'SALA 2002'!$A:$A,0),MATCH(K$1,'SALA 2002'!$B$1:$U$1,0)),IF($A4<=2000,1000*INDEX('SALA 2002'!$B:$U,MATCH($A4,'SALA 2002'!$A:$A,0),MATCH(K$1,'SALA 2002'!$B$1:$U$1,0))*POWER(INDEX('WPP 2024 середина года'!$B:$U,MATCH($A4,'WPP 2024 середина года'!$A:$A,0),MATCH(K$1,'WPP 2024 середина года'!$B$1:$U$1,0))/(1000*INDEX('SALA 2002'!$B:$U,MATCH($A4,'SALA 2002'!$A:$A,0),MATCH(K$1,'SALA 2002'!$B$1:$U$1,0))),($A4-1994)/7),INDEX('WPP 2024 середина года'!$B:$U,MATCH($A4,'WPP 2024 середина года'!$A:$A,0),MATCH(K$1,'WPP 2024 середина года'!$B$1:$U$1,0))))) -> 838 | L4: =IF($A4<=1951,INDEX('SALA 1974'!$B:$U,MATCH($A4,'SALA 1974'!$A:$A,0),MATCH(L$1,'SALA 1974'!$B$1:$U$1,0)),IF($A4<=1994,1000*INDEX('SALA 2002'!$B:$U,MATCH($A4,'SALA 2002'!$A:$A,0),MATCH(L$1,'SALA 2002'!$B$1:$U$1,0)),IF($A4<=2000,1000*INDEX('SALA 2002'!$B:$U,MATCH($A4,'SALA 2002'!$A:$A,0),MATCH(L$1,'SALA 2002'!$B$1:$U$1,0))*POWER(INDEX('WPP 2024 середина года'!$B:$U,MATCH($A4,'WPP 2024 середина года'!$A:$A,0),MATCH(L$1,'WPP 2024 середина года'!$B$1:$U$1,0))/(1000*INDEX('SALA 2002'!$B:$U,MATCH($A4,'SALA 2002'!$A:$A,0),MATCH(L$1,'SALA 2002'!$B$1:$U$1,0))),($A4-1994)/7),INDEX('WPP 2024 середина года'!$B:$U,MATCH($A4,'WPP 2024 середина года'!$A:$A,0),MATCH(L$1,'WPP 2024 середина года'!$B$1:$U$1,0))))) -> 936 | M4: =IF($A4<=1951,INDEX('SALA 1974'!$B:$U,MATCH($A4,'SALA 1974'!$A:$A,0),MATCH(M$1,'SALA 1974'!$B$1:$U$1,0)),IF($A4<=1994,1000*INDEX('SALA 2002'!$B:$U,MATCH($A4,'SALA 2002'!$A:$A,0),MATCH(M$1,'SALA 2002'!$B$1:$U$1,0)),IF($A4<=2000,1000*INDEX('SALA 2002'!$B:$U,MATCH($A4,'SALA 2002'!$A:$A,0),MATCH(M$1,'SALA 2002'!$B$1:$U$1,0))*POWER(INDEX('WPP 2024 середина года'!$B:$U,MATCH($A4,'WPP 2024 середина года'!$A:$A,0),MATCH(M$1,'WPP 2024 середина года'!$B$1:$U$1,0))/(1000*INDEX('SALA 2002'!$B:$U,MATCH($A4,'SALA 2002'!$A:$A,0),MATCH(M$1,'SALA 2002'!$B$1:$U$1,0))),($A4-1994)/7),INDEX('WPP 2024 середина года'!$B:$U,MATCH($A4,'WPP 2024 середина года'!$A:$A,0),MATCH(M$1,'WPP 2024 середина года'!$B$1:$U$1,0))))) -> 1338 | N4: =IF($A4<=1951,INDEX('SALA 1974'!$B:$U,MATCH($A4,'SALA 1974'!$A:$A,0),MATCH(N$1,'SALA 1974'!$B$1:$U$1,0)),IF($A4<=1994,1000*INDEX('SALA 2002'!$B:$U,MATCH($A4,'SALA 2002'!$A:$A,0),MATCH(N$1,'SALA 2002'!$B$1:$U$1,0)),IF($A4<=2000,1000*INDEX('SALA 2002'!$B:$U,MATCH($A4,'SALA 2002'!$A:$A,0),MATCH(N$1,'SALA 2002'!$B$1:$U$1,0))*POWER(INDEX('WPP 2024 середина года'!$B:$U,MATCH($A4,'WPP 2024 середина года'!$A:$A,0),MATCH(N$1,'WPP 2024 середина года'!$B$1:$U$1,0))/(1000*INDEX('SALA 2002'!$B:$U,MATCH($A4,'SALA 2002'!$A:$A,0),MATCH(N$1,'SALA 2002'!$B$1:$U$1,0))),($A4-1994)/7),INDEX('WPP 2024 середина года'!$B:$U,MATCH($A4,'WPP 2024 середина года'!$A:$A,0),MATCH(N$1,'WPP 2024 середина года'!$B$1:$U$1,0))))) -> 452 | ... U4: =IF($A4<=1951,INDEX('SALA 1974'!$B:$U,MATCH($A4,'SALA 1974'!$A:$A,0),MATCH(U$1,'SALA 1974'!$B$1:$U$1,0)),IF($A4<=1994,1000*INDEX('SALA 2002'!$B:$U,MATCH($A4,'SALA 2002'!$A:$A,0),MATCH(U$1,'SALA 2002'!$B$1:$U$1,0)),IF($A4<=2000,1000*INDEX('SALA 2002'!$B:$U,MATCH($A4,'SALA 2002'!$A:$A,0),MATCH(U$1,'SALA 2002'!$B$1:$U$1,0))*POWER(INDEX('WPP 2024 середина года'!$B:$U,MATCH($A4,'WPP 2024 середина года'!$A:$A,0),MATCH(U$1,'WPP 2024 середина года'!$B$1:$U$1,0))/(1000*INDEX('SALA 2002'!$B:$U,MATCH($A4,'SALA 2002'!$A:$A,0),MATCH(U$1,'SALA 2002'!$B$1:$U$1,0))),($A4-1994)/7),INDEX('WPP 2024 середина года'!$B:$U,MATCH($A4,'WPP 2024 середина года'!$A:$A,0),MATCH(U$1,'WPP 2024 середина года'!$B$1:$U$1,0))))) -> 2458
