Workbook

Sheet Notes
A1: Источник для стран Латинской Америки:
B3: Страница "SALA WPP 2024" файла Latin-America-Population.xlsx
B5: 1900-2000
B6: Statistical Abstract of Latin America (vol 38, 2002), UCLA Latin America Center Publications, стр. 150-159
B7: Значения для большинства стран даны на середину календарного года
B8: Для Колумбии на 24 октября календарного года.
B10: Для Бразилии и Венецуэллы данные не включают туземное население в удалённых областях
B12: Для Эквадора данные не включают кочевое туземное население.
B14: Для Гватемалы, Перу и Уругвая данные выправлены на недоучёт.
B16: Исторические данные за 1900-1950 приведены по
B17: Statistical Abstract ofLatin America, Supplement 3 (1974) "Statistics and National Policy", UCLA Latin American Center, стр. 173-187
B18: где они даны с дополнительным десятичным знаком
B19: далее по UN Demographic Yearbook, отдельные годы по UN Population Division и МВФ
... B24: В переходные годы 1995-2000 склейка
A26: Источники для РСФСР/РФ:
A28: 1917 | C28: Госкомстат России, "Население России за 100 лет (1897-1997)", М. 1998, стр. 32
A29: 1920
A30: 1923
A31: 1926
A33: 1918 | C33: Заполнены интерполяцией
A34: 1919
A35: 1921
A36: 1922
A37: 1924
A38: 1925
A40: 1927-1959 | C40: реконструкция АДХ
C41: Е.М.Андреев, Л.Е.Дарский, Т.Л. Харькова, "Демографическая история России : 1927-1959", НИИ статистики Госкомстата России, Отделение демографии, М. 1998, 157-160
C42: кроме 1942-1945
A44: 1942-1945 | C44: Заполнены интерполяцией
A46: 1960-1988 | C46: Госкомстат России, "Население России за 100 лет (1897-1997)", М. 1998, стр. 32-34
A48: 1989-2000 | C48: Росстат, "Демографический ежегодник России 2010", стр. 25
A49: 2001-2014 | C49: Росстат, "Демографический ежегодник России 2023", стр. 15
A50: 2015-2022 | C50: Из РосБРиС через rtss.losses199x.util.PrintPopulation (численность населения на начало календарного года в границах РФ 1991-2014)

Sheet LA
A1: год | B1: Аргентина | C1: Боливия | D1: Бразилия | E1: Чили | F1: Колумбия | G1: Коста-Рика | H1: Куба | I1: Доминиканская республика | J1: Эквадор | K1: Эль-Сальвадор | L1: Гватемала | M1: Гаити | N1: Гондурас | O1: Мексика | P1: Никарагуа | Q1: Панама | R1: Парагвай | S1: Перу | T1: Уругвай | U1: Венецуэлла
A2: 1900 | B2: 4607 | C2: 1766 | D2: 17984 | E2: 2959 | F2: 3894 | G2: 307 | H2: 1600 | I2: 600 | J2: 1300 | K2: 801 | L2: 885 | M2: 1250 | N2: 420 | O2: 13607 | P2: 420 | Q2: 263 | R2: 490 | S2: 3000 | T2: 963 | U2: 2445
A3: 1901 | B3: 4741 | C3: 1785 | D3: 18392 | E3: 2994 | F3: 3944 | G3: 313 | H3: 1679 | I3: 614 | J3: 1312 | K3: 819 | L3: 910 | M3: 1294 | N3: 436 | O3: 13755 | P3: 434 | Q3: 270 | R3: 506 | S3: 3100 | T3: 965 | U3: 2451
A4: 1902 | B4: 4872 | C4: 1803 | D4: 18782 | E4: 3030 | F4: 3994 | G4: 318 | H4: 1758 | I4: 628 | J4: 1324 | K4: 838 | L4: 936 | M4: 1338 | N4: 452 | O4: 13905 | P4: 448 | Q4: 276 | R4: 522 | S4: 3200 | T4: 990 | U4: 2458
A5: 1903 | B5: 4976 | C5: 1822 | D5: 19180 | E5: 3066 | F5: 4044 | G5: 324 | H5: 1837 | I5: 642 | J5: 1336 | K5: 856 | L5: 961 | M5: 1381 | N5: 468 | O5: 14065 | P5: 462 | Q5: 283 | R5: 539 | S5: 3300 | T5: 1019 | U5: 2465
A6: 1904 | B6: 5104 | C6: 1840 | D6: 19587 | E6: 3102 | F6: 4094 | G6: 330 | H6: 1879 | I6: 656 | J6: 1348 | K6: 874 | L6: 987 | M6: 1425 | N6: 484 | O6: 14208 | P6: 477 | Q6: 290 | R6: 555 | S6: 3400 | T6: 1038 | U6: 2471
A7: 1905 | B7: 5290 | C7: 1859 | D7: 20003 | E7: 3139 | F7: 4144 | G7: 336 | H7: 1927 | I7: 670 | J7: 1360 | K7: 893 | L7: 1013 | M7: 1468 | N7: 500 | O7: 14363 | P7: 491 | Q7: 297 | R7: 571 | S7: 3500 | T7: 1071 | U7: 2492
A8: 1906 | B8: 5524 | C8: 1877 | D8: 20427 | E8: 3176 | F8: 4277 | G8: 341 | H8: 1979 | I8: 684 | J8: 1372 | K8: 911 | L8: 1029 | M8: 1512 | N8: 511 | O8: 14519 | P8: 505 | Q8: 304 | R8: 580 | S8: 3600 | T8: 1103 | U8: 2512
A9: 1907 | B9: 5822 | C9: 1896 | D9: 20860 | E9: 3213 | F9: 4409 | G9: 347 | H9: 2034 | I9: 698 | J9: 1384 | K9: 929 | L9: 1046 | M9: 1555 | N9: 521 | O9: 14677 | P9: 515 | Q9: 311 | R9: 590 | S9: 3700 | T9: 1141 | U9: 2532
A10: 1908 | B10: 6145 | C10: 1914 | D10: 21303 | E10: 3253 | F10: 4542 | G10: 353 | H10: 2092 | I10: 712 | J10: 1396 | K10: 948 | L10: 1062 | M10: 1559 | N10: 532 | O10: 14836 | P10: 524 | Q10: 318 | R10: 600 | S10: 3800 | T10: 1054 | U10: 2554
A11: 1909 | B11: 6432 | C11: 1933 | D11: 21754 | E11: 3294 | F11: 4674 | G11: 358 | H11: 2154 | I11: 726 | J11: 1408 | K11: 966 | L11: 1079 | M11: 1643 | N11: 542 | O11: 14997 | P11: 534 | Q11: 325 | R11: 610 | S11: 3900 | T11: 1095 | U11: 2575
A12: 1910 | B12: 6799 | C12: 1951 | D12: 22216 | E12: 3336 | F12: 4807 | G12: 364 | H12: 2219 | I12: 740 | J12: 1421 | K12: 985 | L12: 1096 | M12: 1687 | N12: 553 | O12: 15160 | P12: 543 | Q12: 332 | R12: 620 | S12: 4000 | T12: 1132 | U12: 2596
A13: 1911 | B13: 7070 | C13: 1970 | D13: 22687 | E13: 3378 | F13: 4940 | G13: 370 | H13: 2287 | I13: 753 | J13: 1433 | K13: 1003 | L13: 1119 | M13: 1730 | N13: 562 | O13: 15333 | P13: 553 | Q13: 339 | R13: 630 | S13: 4100 | T13: 1178 | U13: 2612
... A125: 2023 | B125: 45538.4 | C125: 12244.2 | D125: 211140.7 | E125: 19658.8 | F125: 52321.2 | G125: 5105.5 | H125: 11019.9 | I125: 11331.3 | J125: 17980.1 | K125: 6309.6 | L125: 18124.8 | M125: 11637.4 | N125: 10644.9 | O125: 129739.8 | P125: 6823.6 | Q125: 4458.8 | R125: 6844.1 | S125: 33845.6 | T125: 3388.1 | U125: 28300.9

Sheet RSFSR
A4: =A5-1 -> 1917 | B4: 91000
A5: =A6-1 -> 1918 | B5: 90073
A6: =A7-1 -> 1919 | B6: 89155
A7: =A8-1 -> 1920 | B7: 88247
A8: =A9-1 -> 1921 | B8: 88083
A9: =A10-1 -> 1922 | B9: 87919
A10: =A11-1 -> 1923 | B10: 87755
A11: =A12-1 -> 1924 | B11: 89385
A12: =A13-1 -> 1925 | B12: 91044
A13: =A14-1 -> 1926 | B13: 92735
A14: 1927 | B14: 93604
A15: 1928 | B15: 95587
A16: 1929 | B16: 97721
A17: 1930 | B17: 99566
A18: 1931 | B18: 101272
A19: 1932 | B19: 102625
A20: 1933 | B20: 103648
A21: 1934 | B21: 101763
A22: 1935 | B22: 102080
A23: 1936 | B23: 103288
A24: 1937 | B24: 104520
A25: 1938 | B25: 106195
... A28: 1941 | B28: 110988
A29: =A28+1 -> 1942 | B29: 108159
A30: =A29+1 -> 1943 | B30: 105403
A31: =A30+1 -> 1944 | B31: 102717
A32: =A31+1 -> 1945 | B32: 100099
A33: 1946 | B33: 97548
A34: 1947 | B34: 98509
A35: 1948 | B35: 99159
A36: 1949 | B36: 100252
A37: 1950 | B37: 102067
A38: 1951 | B38: 103599
A39: 1952 | B39: 105278
A40: 1953 | B40: 107049
A41: 1954 | B41: 108607
A42: 1955 | B42: 110678
A43: 1956 | B43: 112465
A44: 1957 | B44: 114189
... A46: 1959 | B46: 117616
...

Sheet вместе-абс
A1: год | B1: Аргентина | C1: Боливия | D1: Бразилия | E1: Чили | F1: Колумбия | G1: Коста-Рика | H1: Куба | I1: Доминиканская республика | J1: Эквадор | K1: Эль-Сальвадор | L1: Гватемала | M1: Гаити | N1: Гондурас | O1: Мексика | P1: Никарагуа | Q1: Панама | R1: Парагвай | S1: Перу | T1: Уругвай | U1: Венецуэлла | V1: РСФСР
A2: 1917 | B2: 8445 | C2: 2081 | D2: 25732 | E2: 3644 | F2: 5715 | G2: 404 | H2: 2746 | I2: 837 | J2: 1505 | K2: 1113 | L2: 1226 | M2: 1993 | N2: 633 | O2: 13898 | P2: 610 | Q2: 413 | R2: 678 | S2: 4588 | T2: 1407 | U2: 2750 | V2: 91000
A3: =A2+1 -> 1918 | B3: 8590 | C3: 2099 | D3: 26277 | E3: 3690 | F3: 5855 | G3: 410 | H3: 2828 | I3: 851 | J3: 1517 | K3: 1131 | L3: 1241 | M3: 2037 | N3: 660 | O3: 14000 | P3: 619 | Q3: 426 | R3: 685 | S3: 4668 | T3: 1430 | U3: 2772 | V3: 90073
A4: =A3+1 -> 1919 | B4: 8754 | C4: 2118 | D4: 26835 | E4: 3737 | F4: 6029 | G4: 415 | H4: 2912 | I4: 865 | J4: 1529 | K4: 1150 | L4: 1257 | M4: 2080 | N4: 688 | O4: 14150 | P4: 629 | Q4: 437 | R4: 692 | S4: 4748 | T4: 1463 | U4: 2795 | V4: 89155
A5: =A4+1 -> 1920 | B5: 8969 | C5: 2136 | D5: 27404 | E5: 3785 | F5: 6089 | G5: 421 | H5: 2997 | I5: 879 | J5: 1541 | K5: 1168 | L5: 1272 | M5: 2124 | N5: 715 | O5: 14150 | P5: 638 | Q5: 447 | R5: 699 | S5: 4828 | T5: 1481 | U5: 2818 | V5: 88247
A6: =A5+1 -> 1921 | B6: 9215 | C6: 2161 | D6: 27969 | E6: 3853 | F6: 6211 | G6: 425 | H6: 3083 | I6: 912 | J6: 1570 | K6: 1193 | L6: 1319 | M6: 2151 | N6: 742 | O6: 14335 | P6: 643 | Q6: 449 | R6: 715 | S6: 4908 | T6: 1499 | U6: 2843 | V6: 88083
A7: =A6+1 -> 1922 | B7: 9521 | C7: 2186 | D7: 28542 | E7: 3907 | F7: 6336 | G7: 431 | H7: 3170 | I7: 946 | J7: 1610 | K7: 1217 | L7: 1367 | M7: 2178 | N7: 769 | O7: 14444 | P7: 647 | Q7: 451 | R7: 732 | S7: 4989 | T7: 1517 | U7: 2870 | V7: 87919
A8: =A7+1 -> 1923 | B8: 9892 | C8: 2212 | D8: 29126 | E8: 3961 | F8: 6463 | G8: 439 | H8: 3257 | I8: 981 | J8: 1646 | K8: 1244 | L8: 1416 | M8: 2206 | N8: 796 | O8: 14693 | P8: 652 | Q8: 453 | R8: 749 | S8: 5069 | T8: 1535 | U8: 2898 | V8: 87755
A9: =A8+1 -> 1924 | B9: 10216 | C9: 2237 | D9: 29723 | E9: 4017 | F9: 6592 | G9: 447 | H9: 3345 | I9: 1017 | J9: 1685 | K9: 1274 | L9: 1471 | M9: 2232 | N9: 824 | O9: 14945 | P9: 656 | Q9: 455 | R9: 767 | S9: 5148 | T9: 1553 | U9: 2925 | V9: 89385
A10: =A9+1 -> 1925 | B10: 10500 | C10: 2263 | D10: 30332 | E10: 4073 | F10: 6724 | G10: 456 | H10: 3432 | I10: 1054 | J10: 1724 | K10: 1301 | L10: 1514 | M10: 2260 | N10: 851 | O10: 15204 | P10: 660 | Q10: 457 | R10: 785 | S10: 5229 | T10: 1571 | U10: 2953 | V10: 91044
A11: =A10+1 -> 1926 | B11: 10804 | C11: 2289 | D11: 30953 | E11: 4130 | F11: 6859 | G11: 466 | H11: 3519 | I11: 1092 | J11: 1762 | K11: 1325 | L11: 1557 | M11: 2292 | N11: 878 | O11: 15468 | P11: 665 | Q11: 459 | R11: 803 | S11: 5313 | T11: 1604 | U11: 2981 | V11: 92735
A12: =A11+1 -> 1927 | B12: 11126 | C12: 2316 | D12: 31587 | E12: 4188 | F12: 6996 | G12: 472 | H12: 3606 | I12: 1131 | J12: 1800 | K12: 1351 | L12: 1602 | M12: 2325 | N12: 893 | O12: 15738 | P12: 670 | Q12: 462 | R12: 822 | S12: 5399 | T12: 1636 | U12: 3012 | V12: 93604
A13: =A12+1 -> 1928 | B13: 11438 | C13: 2343 | D13: 32234 | E13: 4246 | F13: 7136 | G13: 479 | H13: 3507 | I13: 1172 | J13: 1846 | K13: 1385 | L13: 1660 | M13: 2357 | N13: 911 | O13: 16012 | P13: 674 | Q13: 464 | R13: 841 | S13: 5482 | T13: 1669 | U13: 3047 | V13: 95587
A14: =A13+1 -> 1929 | B14: 11746 | C14: 2370 | D14: 32894 | E14: 4305 | F14: 7279 | G14: 489 | H14: 3577 | I14: 1213 | J14: 1891 | K14: 1412 | L14: 1706 | M14: 2390 | N14: 928 | O14: 16926 | P14: 679 | Q14: 466 | R14: 860 | S14: 5567 | T14: 1701 | U14: 3082 | V14: 97721
... A107: =A106+1 -> 2022 | B107: 45407.9 | C107: 12077.2 | D107: 210306.4 | E107: 19553 | F107: 51737.9 | G107: 5081.8 | H107: 11059.8 | I107: 11230.7 | J107: 17823.9 | K107: 6280.3 | L107: 17847.9 | M107: 11503.6 | N107: 10463.9 | O107: 128613.1 | P107: 6730.7 | Q107: 4400.8 | R107: 6760.5 | S107: 33475.4 | T107: 3390.9 | U107: 28213 | V107: 144491.94

Sheet вместе-отн
A1: год | B1: Аргентина | C1: Боливия | D1: Бразилия | E1: Чили | F1: Колумбия | G1: Коста-Рика | H1: Куба | I1: Доминиканская республика | J1: Эквадор | K1: Эль-Сальвадор | L1: Гватемала | M1: Гаити | N1: Гондурас | O1: Мексика | P1: Никарагуа | Q1: Панама | R1: Парагвай | S1: Перу | T1: Уругвай | U1: Венецуэлла | V1: РСФСР
A2: 1917 | B2: =('вместе-абс'!B2 - 'вместе-абс'!B$2) / 'вместе-абс'!B$2 -> 0 | C2: =('вместе-абс'!C2 - 'вместе-абс'!C$2) / 'вместе-абс'!C$2 -> 0 | D2: =('вместе-абс'!D2 - 'вместе-абс'!D$2) / 'вместе-абс'!D$2 -> 0 | E2: =('вместе-абс'!E2 - 'вместе-абс'!E$2) / 'вместе-абс'!E$2 -> 0 | F2: =('вместе-абс'!F2 - 'вместе-абс'!F$2) / 'вместе-абс'!F$2 -> 0 | G2: =('вместе-абс'!G2 - 'вместе-абс'!G$2) / 'вместе-абс'!G$2 -> 0 | H2: =('вместе-абс'!H2 - 'вместе-абс'!H$2) / 'вместе-абс'!H$2 -> 0 | I2: =('вместе-абс'!I2 - 'вместе-абс'!I$2) / 'вместе-абс'!I$2 -> 0 | ... V2: =('вместе-абс'!V2 - 'вместе-абс'!V$2) / 'вместе-абс'!V$2 -> 0
A3: =A2+1 -> 1918 | B3: =('вместе-абс'!B3 - 'вместе-абс'!B$2) / 'вместе-абс'!B$2 -> 0.017169923 | C3: =('вместе-абс'!C3 - 'вместе-абс'!C$2) / 'вместе-абс'!C$2 -> 0.0086496877 | D3: =('вместе-абс'!D3 - 'вместе-абс'!D$2) / 'вместе-абс'!D$2 -> 0.021179854 | E3: =('вместе-абс'!E3 - 'вместе-абс'!E$2) / 'вместе-абс'!E$2 -> 0.012623491 | F3: =('вместе-абс'!F3 - 'вместе-абс'!F$2) / 'вместе-абс'!F$2 -> 0.024496938 | G3: =('вместе-абс'!G3 - 'вместе-абс'!G$2) / 'вместе-абс'!G$2 -> 0.014851485 | H3: =('вместе-абс'!H3 - 'вместе-абс'!H$2) / 'вместе-абс'!H$2 -> 0.029861617 | I3: =('вместе-абс'!I3 - 'вместе-абс'!I$2) / 'вместе-абс'!I$2 -> 0.016726404 | ... V3: =('вместе-абс'!V3 - 'вместе-абс'!V$2) / 'вместе-абс'!V$2 -> -0.010186813
A4: =A3+1 -> 1919 | B4: =('вместе-абс'!B4 - 'вместе-абс'!B$2) / 'вместе-абс'!B$2 -> 0.036589698 | C4: =('вместе-абс'!C4 - 'вместе-абс'!C$2) / 'вместе-абс'!C$2 -> 0.017779914 | D4: =('вместе-абс'!D4 - 'вместе-абс'!D$2) / 'вместе-абс'!D$2 -> 0.042864915 | E4: =('вместе-абс'!E4 - 'вместе-абс'!E$2) / 'вместе-абс'!E$2 -> 0.025521405 | F4: =('вместе-абс'!F4 - 'вместе-абс'!F$2) / 'вместе-абс'!F$2 -> 0.054943132 | G4: =('вместе-абс'!G4 - 'вместе-абс'!G$2) / 'вместе-абс'!G$2 -> 0.027227723 | H4: =('вместе-абс'!H4 - 'вместе-абс'!H$2) / 'вместе-абс'!H$2 -> 0.060451566 | I4: =('вместе-абс'!I4 - 'вместе-абс'!I$2) / 'вместе-абс'!I$2 -> 0.033452808 | ... V4: =('вместе-абс'!V4 - 'вместе-абс'!V$2) / 'вместе-абс'!V$2 -> -0.020274725
A5: =A4+1 -> 1920 | B5: =('вместе-абс'!B5 - 'вместе-абс'!B$2) / 'вместе-абс'!B$2 -> 0.062048549 | C5: =('вместе-абс'!C5 - 'вместе-абс'!C$2) / 'вместе-абс'!C$2 -> 0.026429601 | D5: =('вместе-абс'!D5 - 'вместе-абс'!D$2) / 'вместе-абс'!D$2 -> 0.06497746 | E5: =('вместе-абс'!E5 - 'вместе-абс'!E$2) / 'вместе-абс'!E$2 -> 0.038693743 | F5: =('вместе-абс'!F5 - 'вместе-абс'!F$2) / 'вместе-абс'!F$2 -> 0.06544182 | G5: =('вместе-абс'!G5 - 'вместе-абс'!G$2) / 'вместе-абс'!G$2 -> 0.042079208 | H5: =('вместе-абс'!H5 - 'вместе-абс'!H$2) / 'вместе-абс'!H$2 -> 0.091405681 | I5: =('вместе-абс'!I5 - 'вместе-абс'!I$2) / 'вместе-абс'!I$2 -> 0.050179211 | ... V5: =('вместе-абс'!V5 - 'вместе-абс'!V$2) / 'вместе-абс'!V$2 -> -0.030252747
A6: =A5+1 -> 1921 | B6: =('вместе-абс'!B6 - 'вместе-абс'!B$2) / 'вместе-абс'!B$2 -> 0.091178212 | C6: =('вместе-абс'!C6 - 'вместе-абс'!C$2) / 'вместе-абс'!C$2 -> 0.038443056 | D6: =('вместе-абс'!D6 - 'вместе-абс'!D$2) / 'вместе-абс'!D$2 -> 0.086934556 | E6: =('вместе-абс'!E6 - 'вместе-абс'!E$2) / 'вместе-абс'!E$2 -> 0.057354555 | F6: =('вместе-абс'!F6 - 'вместе-абс'!F$2) / 'вместе-абс'!F$2 -> 0.086789151 | G6: =('вместе-абс'!G6 - 'вместе-абс'!G$2) / 'вместе-абс'!G$2 -> 0.051980198 | H6: =('вместе-абс'!H6 - 'вместе-абс'!H$2) / 'вместе-абс'!H$2 -> 0.12272396 | I6: =('вместе-абс'!I6 - 'вместе-абс'!I$2) / 'вместе-абс'!I$2 -> 0.089605735 | ... V6: =('вместе-абс'!V6 - 'вместе-абс'!V$2) / 'вместе-абс'!V$2 -> -0.032054945
A7: =A6+1 -> 1922 | B7: =('вместе-абс'!B7 - 'вместе-абс'!B$2) / 'вместе-абс'!B$2 -> 0.12741267 | C7: =('вместе-абс'!C7 - 'вместе-абс'!C$2) / 'вместе-абс'!C$2 -> 0.050456511 | D7: =('вместе-абс'!D7 - 'вместе-абс'!D$2) / 'вместе-абс'!D$2 -> 0.10920255 | E7: =('вместе-абс'!E7 - 'вместе-абс'!E$2) / 'вместе-абс'!E$2 -> 0.072173436 | F7: =('вместе-абс'!F7 - 'вместе-абс'!F$2) / 'вместе-абс'!F$2 -> 0.10866142 | G7: =('вместе-абс'!G7 - 'вместе-абс'!G$2) / 'вместе-абс'!G$2 -> 0.066831683 | H7: =('вместе-абс'!H7 - 'вместе-абс'!H$2) / 'вместе-абс'!H$2 -> 0.15440641 | I7: =('вместе-абс'!I7 - 'вместе-абс'!I$2) / 'вместе-абс'!I$2 -> 0.130227 | ... V7: =('вместе-абс'!V7 - 'вместе-абс'!V$2) / 'вместе-абс'!V$2 -> -0.033857143
A8: =A7+1 -> 1923 | B8: =('вместе-абс'!B8 - 'вместе-абс'!B$2) / 'вместе-абс'!B$2 -> 0.17134399 | C8: =('вместе-абс'!C8 - 'вместе-абс'!C$2) / 'вместе-абс'!C$2 -> 0.062950505 | D8: =('вместе-абс'!D8 - 'вместе-абс'!D$2) / 'вместе-абс'!D$2 -> 0.13189803 | E8: =('вместе-абс'!E8 - 'вместе-абс'!E$2) / 'вместе-абс'!E$2 -> 0.086992316 | F8: =('вместе-абс'!F8 - 'вместе-абс'!F$2) / 'вместе-абс'!F$2 -> 0.13088364 | G8: =('вместе-абс'!G8 - 'вместе-абс'!G$2) / 'вместе-абс'!G$2 -> 0.086633663 | H8: =('вместе-абс'!H8 - 'вместе-абс'!H$2) / 'вместе-абс'!H$2 -> 0.18608886 | I8: =('вместе-абс'!I8 - 'вместе-абс'!I$2) / 'вместе-абс'!I$2 -> 0.17204301 | ... V8: =('вместе-абс'!V8 - 'вместе-абс'!V$2) / 'вместе-абс'!V$2 -> -0.035659341
A9: =A8+1 -> 1924 | B9: =('вместе-абс'!B9 - 'вместе-абс'!B$2) / 'вместе-абс'!B$2 -> 0.20970989 | C9: =('вместе-абс'!C9 - 'вместе-абс'!C$2) / 'вместе-абс'!C$2 -> 0.07496396 | D9: =('вместе-абс'!D9 - 'вместе-абс'!D$2) / 'вместе-абс'!D$2 -> 0.15509871 | E9: =('вместе-абс'!E9 - 'вместе-абс'!E$2) / 'вместе-абс'!E$2 -> 0.10236004 | F9: =('вместе-абс'!F9 - 'вместе-абс'!F$2) / 'вместе-абс'!F$2 -> 0.15345582 | G9: =('вместе-абс'!G9 - 'вместе-абс'!G$2) / 'вместе-абс'!G$2 -> 0.10643564 | H9: =('вместе-абс'!H9 - 'вместе-абс'!H$2) / 'вместе-абс'!H$2 -> 0.21813547 | I9: =('вместе-абс'!I9 - 'вместе-абс'!I$2) / 'вместе-абс'!I$2 -> 0.21505376 | ... V9: =('вместе-абс'!V9 - 'вместе-абс'!V$2) / 'вместе-абс'!V$2 -> -0.017747253
A10: =A9+1 -> 1925 | B10: =('вместе-абс'!B10 - 'вместе-абс'!B$2) / 'вместе-абс'!B$2 -> 0.24333925 | C10: =('вместе-абс'!C10 - 'вместе-абс'!C$2) / 'вместе-абс'!C$2 -> 0.087457953 | D10: =('вместе-абс'!D10 - 'вместе-абс'!D$2) / 'вместе-абс'!D$2 -> 0.17876574 | E10: =('вместе-абс'!E10 - 'вместе-абс'!E$2) / 'вместе-абс'!E$2 -> 0.11772777 | F10: =('вместе-абс'!F10 - 'вместе-абс'!F$2) / 'вместе-абс'!F$2 -> 0.17655293 | G10: =('вместе-абс'!G10 - 'вместе-абс'!G$2) / 'вместе-абс'!G$2 -> 0.12871287 | H10: =('вместе-абс'!H10 - 'вместе-абс'!H$2) / 'вместе-абс'!H$2 -> 0.24981792 | I10: =('вместе-абс'!I10 - 'вместе-абс'!I$2) / 'вместе-абс'!I$2 -> 0.25925926 | ... V10: =('вместе-абс'!V10 - 'вместе-абс'!V$2) / 'вместе-абс'!V$2 -> 0.00048351648
A11: =A10+1 -> 1926 | B11: =('вместе-абс'!B11 - 'вместе-абс'!B$2) / 'вместе-абс'!B$2 -> 0.27933689 | C11: =('вместе-абс'!C11 - 'вместе-абс'!C$2) / 'вместе-абс'!C$2 -> 0.099951946 | D11: =('вместе-абс'!D11 - 'вместе-абс'!D$2) / 'вместе-абс'!D$2 -> 0.20289911 | E11: =('вместе-абс'!E11 - 'вместе-абс'!E$2) / 'вместе-абс'!E$2 -> 0.13336992 | F11: =('вместе-абс'!F11 - 'вместе-абс'!F$2) / 'вместе-абс'!F$2 -> 0.20017498 | G11: =('вместе-абс'!G11 - 'вместе-абс'!G$2) / 'вместе-абс'!G$2 -> 0.15346535 | H11: =('вместе-абс'!H11 - 'вместе-абс'!H$2) / 'вместе-абс'!H$2 -> 0.28150036 | I11: =('вместе-абс'!I11 - 'вместе-абс'!I$2) / 'вместе-абс'!I$2 -> 0.3046595 | ... V11: =('вместе-абс'!V11 - 'вместе-абс'!V$2) / 'вместе-абс'!V$2 -> 0.019065934
A12: =A11+1 -> 1927 | B12: =('вместе-абс'!B12 - 'вместе-абс'!B$2) / 'вместе-абс'!B$2 -> 0.31746596 | C12: =('вместе-абс'!C12 - 'вместе-абс'!C$2) / 'вместе-абс'!C$2 -> 0.11292648 | D12: =('вместе-абс'!D12 - 'вместе-абс'!D$2) / 'вместе-абс'!D$2 -> 0.2275377 | E12: =('вместе-абс'!E12 - 'вместе-абс'!E$2) / 'вместе-абс'!E$2 -> 0.1492865 | F12: =('вместе-абс'!F12 - 'вместе-абс'!F$2) / 'вместе-абс'!F$2 -> 0.22414698 | G12: =('вместе-абс'!G12 - 'вместе-абс'!G$2) / 'вместе-абс'!G$2 -> 0.16831683 | H12: =('вместе-абс'!H12 - 'вместе-абс'!H$2) / 'вместе-абс'!H$2 -> 0.31318281 | I12: =('вместе-абс'!I12 - 'вместе-абс'!I$2) / 'вместе-абс'!I$2 -> 0.35125448 | ... V12: =('вместе-абс'!V12 - 'вместе-абс'!V$2) / 'вместе-абс'!V$2 -> 0.028615385
A13: =A12+1 -> 1928 | B13: =('вместе-абс'!B13 - 'вместе-абс'!B$2) / 'вместе-абс'!B$2 -> 0.35441089 | C13: =('вместе-абс'!C13 - 'вместе-абс'!C$2) / 'вместе-абс'!C$2 -> 0.12590101 | D13: =('вместе-абс'!D13 - 'вместе-абс'!D$2) / 'вместе-абс'!D$2 -> 0.25268149 | E13: =('вместе-абс'!E13 - 'вместе-абс'!E$2) / 'вместе-абс'!E$2 -> 0.16520307 | F13: =('вместе-абс'!F13 - 'вместе-абс'!F$2) / 'вместе-абс'!F$2 -> 0.24864392 | G13: =('вместе-абс'!G13 - 'вместе-абс'!G$2) / 'вместе-абс'!G$2 -> 0.18564356 | H13: =('вместе-абс'!H13 - 'вместе-абс'!H$2) / 'вместе-абс'!H$2 -> 0.27713037 | I13: =('вместе-абс'!I13 - 'вместе-абс'!I$2) / 'вместе-абс'!I$2 -> 0.40023895 | ... V13: =('вместе-абс'!V13 - 'вместе-абс'!V$2) / 'вместе-абс'!V$2 -> 0.050406593
A14: =A13+1 -> 1929 | B14: =('вместе-абс'!B14 - 'вместе-абс'!B$2) / 'вместе-абс'!B$2 -> 0.39088218 | C14: =('вместе-абс'!C14 - 'вместе-абс'!C$2) / 'вместе-абс'!C$2 -> 0.13887554 | D14: =('вместе-абс'!D14 - 'вместе-абс'!D$2) / 'вместе-абс'!D$2 -> 0.27833048 | E14: =('вместе-абс'!E14 - 'вместе-абс'!E$2) / 'вместе-абс'!E$2 -> 0.18139407 | F14: =('вместе-абс'!F14 - 'вместе-абс'!F$2) / 'вместе-абс'!F$2 -> 0.27366579 | G14: =('вместе-абс'!G14 - 'вместе-абс'!G$2) / 'вместе-абс'!G$2 -> 0.21039604 | H14: =('вместе-абс'!H14 - 'вместе-абс'!H$2) / 'вместе-абс'!H$2 -> 0.302622 | I14: =('вместе-абс'!I14 - 'вместе-абс'!I$2) / 'вместе-абс'!I$2 -> 0.44922342 | ... V14: =('вместе-абс'!V14 - 'вместе-абс'!V$2) / 'вместе-абс'!V$2 -> 0.073857143
... A107: =A106+1 -> 2022 | B107: =('вместе-абс'!B107 - 'вместе-абс'!B$2) / 'вместе-абс'!B$2 -> 4.3768976 | C107: =('вместе-абс'!C107 - 'вместе-абс'!C$2) / 'вместе-абс'!C$2 -> 4.803556 | D107: =('вместе-абс'!D107 - 'вместе-абс'!D$2) / 'вместе-абс'!D$2 -> 7.172952 | E107: =('вместе-абс'!E107 - 'вместе-абс'!E$2) / 'вместе-абс'!E$2 -> 4.3658068 | F107: =('вместе-абс'!F107 - 'вместе-абс'!F$2) / 'вместе-абс'!F$2 -> 8.0530009 | G107: =('вместе-абс'!G107 - 'вместе-абс'!G$2) / 'вместе-абс'!G$2 -> 11.578713 | H107: =('вместе-абс'!H107 - 'вместе-абс'!H$2) / 'вместе-абс'!H$2 -> 3.0276038 | I107: =('вместе-абс'!I107 - 'вместе-абс'!I$2) / 'вместе-абс'!I$2 -> 12.417802 | ... V107: =('вместе-абс'!V107 - 'вместе-абс'!V$2) / 'вместе-абс'!V$2 -> 0.58782356
